{"e": "depthUpdate", "E": 1746122586014, "s": "BTCUSDT", "b": [["96834.00000000", "7.63979000"], ["96828.66000000", "0.00560000"], ["96828.11000000", "0.02048000"], ["96827.57000000", "0.00000000"], ["96827.23000000", "0.07925000"], ["96827.06000000", "0.04000000"], ["96826.41000000", "0.00999000"], ["96825.64000000", "0.48334000"], ["96823.82000000", "0.02000000"], ["96822.85000000", "0.04800000"], ["96820.78000000", "0.00651000"], ["96819.94000000", "0.04800000"], ["96818.89000000", "0.92530000"], ["96818.88000000", "1.10000000"], ["96818.14000000", "0.00000000"], ["96818.01000000", "0.04800000"], ["96817.94000000", "0.04851000"], ["96817.46000000", "0.00000000"], ["96817.39000000", "0.00651000"], ["96814.72000000", "0.00013000"], ["96814.71000000", "0.00000000"], ["96814.67000000", "0.00000000"], ["96813.24000000", "1.67128000"], ["96812.62000000", "0.00000000"], ["96812.15000000", "1.69930000"], ["96811.69000000", "0.00000000"], ["96811.64000000", "1.00000000"], ["96810.95000000", "0.00651000"], ["96809.56000000", "0.00000000"], ["96808.78000000", "0.00000000"], ["96808.01000000", "0.00000000"], ["96807.76000000", "0.00000000"], ["96807.51000000", "0.00651000"], ["96806.82000000", "0.00000000"], ["96806.74000000", "0.00000000"], ["96804.96000000", "0.00000000"], ["96803.06000000", "0.00000000"], ["96802.83000000", "0.00651000"], ["96795.92000000", "0.00651000"], ["96794.73000000", "0.04800000"], ["96794.00000000", "0.03932000"], ["96792.03000000", "0.00651000"], ["96789.28000000", "2.00000000"], ["96787.60000000", "0.00651000"], ["96785.12000000", "0.00000000"], ["96783.55000000", "0.00651000"], ["96782.02000000", "0.00000000"], ["96781.76000000", "0.00000000"], ["96778.61000000", "0.00651000"], ["96776.98000000", "0.00723000"], ["96775.98000000", "0.00723000"], ["96774.98000000", "0.00723000"], ["96774.02000000", "0.00651000"], ["96773.98000000", "0.00723000"], ["96772.98000000", "0.00723000"], ["96771.98000000", "0.00723000"], ["96770.98000000", "0.00723000"], ["96767.65000000", "0.00651000"], ["96762.52000000", "0.00254000"], ["96758.54000000", "0.00000000"], ["96753.78000000", "0.01031000"], ["96748.24000000", "0.00000000"], ["96747.21000000", "0.04800000"], ["96744.38000000", "0.00000000"], ["96741.91000000", "0.05167000"], ["96693.79000000", "0.00000000"], ["96590.01000000", "0.00545000"], ["96580.01000000", "0.00000000"], ["96101.00000000", "0.00000000"], ["95381.50000000", "0.00008000"], ["95381.49000000", "0.00100000"], ["95284.67000000", "0.00008000"], ["95187.83000000", "0.00008000"], ["95091.00000000", "0.00008000"], ["94994.16000000", "0.00008000"], ["87150.60000000", "0.00000000"], ["87150.00000000", "0.10415000"], ["77467.20000000", "0.00050000"], ["70000.00000000", "183.65512000"], ["34860.24000000", "0.00018000"], ["33000.00000000", "2.70627000"]], "a": [["96834.01000000", "2.76870000"], ["96834.02000000", "0.00734000"], ["96834.32000000", "0.00006000"], ["96834.51000000", "0.00013000"], ["96835.69000000", "0.00006000"], ["96835.70000000", "0.00000000"], ["96835.98000000", "0.00006000"], ["96835.99000000", "0.02582000"], ["96836.00000000", "0.05056000"], ["96837.59000000", "0.00006000"], ["96837.60000000", "0.04136000"], ["96838.91000000", "0.01777000"], ["96840.00000000", "0.05062000"], ["96840.11000000", "0.00006000"], ["96840.12000000", "0.16902000"], ["96840.13000000", "0.24498000"], ["96840.93000000", "0.02439000"], ["96841.58000000", "0.00000000"], ["96841.59000000", "0.00000000"], ["96841.99000000", "0.00000000"], ["96842.00000000", "0.05050000"], ["96842.47000000", "0.02012000"], ["96843.18000000", "0.00000000"], ["96843.19000000", "0.06543000"], ["96843.44000000", "0.00000000"], ["96843.45000000", "0.16000000"], ["96844.00000000", "0.04130000"], ["96844.69000000", "0.00000000"], ["96844.70000000", "0.61507000"], ["96844.71000000", "0.39773000"], ["96844.72000000", "0.21301000"], ["96844.91000000", "0.00000000"], ["96845.19000000", "0.00000000"], ["96850.46000000", "0.00560000"], ["96850.81000000", "0.00309000"], ["96850.82000000", "0.00000000"], ["96850.84000000", "0.00000000"], ["96852.07000000", "0.00999000"], ["96852.46000000", "0.00000000"], ["96853.39000000", "0.00000000"], ["96853.58000000", "0.00010000"], ["96853.90000000", "0.02289000"], ["96855.30000000", "0.02000000"], ["96856.23000000", "0.00000000"], ["96856.24000000", "0.09600000"], ["96856.26000000", "0.09600000"], ["96856.56000000", "0.00000000"], ["96859.16000000", "0.08640000"], ["96861.11000000", "0.07680000"], ["96861.18000000", "0.06720000"], ["96865.64000000", "0.00000000"], ["96865.66000000", "1.00000000"], ["96867.22000000", "0.00000000"], ["96868.17000000", "0.00000000"], ["96869.16000000", "0.00000000"], ["96870.19000000", "0.05000000"], ["96872.06000000", "0.00000000"], ["96873.02000000", "0.00000000"], ["96874.06000000", "0.00000000"], ["96875.85000000", "0.00766000"], ["96878.05000000", "1.27625000"], ["96884.00000000", "0.00246000"], ["96884.59000000", "1.63200000"], ["96884.74000000", "0.00000000"], ["96885.78000000", "0.03062000"], ["96897.27000000", "0.00000000"], ["96897.31000000", "2.00000000"], ["96900.43000000", "0.00000000"], ["96922.18000000", "0.09600000"], ["96927.86000000", "0.00000000"], ["96928.35000000", "0.00000000"], ["96929.48000000", "0.07680000"], ["96932.07000000", "0.00000000"], ["96933.57000000", "0.00000000"], ["96934.10000000", "0.06720000"], ["96938.52000000", "0.00000000"], ["98286.53000000", "0.00100000"]]}
{"e": "depthUpdate", "E": 1746122587014, "s": "BTCUSDT", "b": [["96834.00000000", "7.09979000"], ["96833.49000000", "0.00006000"], ["96833.44000000", "0.00007000"], ["96833.34000000", "0.14225000"], ["96833.03000000", "0.00103000"], ["96830.00000000", "0.05056000"], ["96829.56000000", "0.00000000"], ["96829.55000000", "0.00000000"], ["96829.17000000", "0.00000000"], ["96828.11000000", "0.02048000"], ["96827.94000000", "0.00000000"], ["96827.23000000", "0.00000000"], ["96827.06000000", "0.04006000"], ["96826.61000000", "0.21307000"], ["96826.60000000", "0.76937000"], ["96826.59000000", "0.00000000"], ["96826.58000000", "0.21301000"], ["96826.41000000", "0.00000000"], ["96825.65000000", "0.00000000"], ["96825.37000000", "0.00999000"], ["96824.33000000", "0.00103000"], ["96822.42000000", "0.84726000"], ["96822.41000000", "0.00000000"], ["96822.34000000", "0.00000000"], ["96820.79000000", "0.61931000"], ["96820.75000000", "0.15629000"], ["96815.55000000", "0.00007000"], ["96811.64000000", "0.00000000"], ["96810.92000000", "1.00000000"], ["96810.08000000", "0.00000000"], ["96809.88000000", "0.00000000"], ["96809.36000000", "0.00104000"], ["96807.79000000", "0.00000000"], ["96807.46000000", "0.74348000"], ["96805.51000000", "0.01350000"], ["96804.40000000", "0.00560000"], ["96804.31000000", "0.00000000"], ["96803.06000000", "0.07919000"], ["96801.00000000", "0.00051000"], ["96800.67000000", "0.01032000"], ["96799.56000000", "0.02000000"], ["96799.47000000", "0.00000000"], ["96798.59000000", "0.04800000"], ["96795.68000000", "0.04800000"], ["96794.00000000", "0.00000000"], ["96793.75000000", "0.04800000"], ["96793.68000000", "0.04800000"], ["96789.29000000", "0.00000000"], ["96789.28000000", "0.00000000"], ["96788.40000000", "0.00000000"], ["96787.84000000", "2.00000000"], ["96786.16000000", "0.00000000"], ["96785.76000000", "0.00000000"], ["96784.72000000", "0.00000000"], ["96783.02000000", "0.00000000"], ["96782.83000000", "0.00000000"], ["96781.58000000", "0.00000000"], ["96777.19000000", "0.05000000"], ["96771.54000000", "0.03932000"], ["96769.98000000", "0.00723000"], ["96769.02000000", "0.03799000"], ["96768.98000000", "0.00723000"], ["96751.38000000", "0.00000000"], ["96748.24000000", "0.00000000"], ["96747.28000000", "0.00000000"], ["96744.38000000", "0.00000000"], ["96742.42000000", "0.00000000"], ["96733.32000000", "0.00000000"], ["96732.37000000", "0.00000000"], ["96628.70000000", "6.60779000"], ["96628.17000000", "0.00000000"], ["95980.21000000", "0.00008000"], ["95381.49000000", "0.00000000"], ["95368.99000000", "0.00348000"], ["95368.86000000", "0.00000000"], ["94897.33000000", "0.00008000"], ["94800.50000000", "0.00020000"], ["87150.60000000", "0.00000000"], ["87150.00000000", "0.10415000"], ["79000.00000000", "54.24601000"], ["77467.20000000", "0.00050000"], ["33000.00000000", "2.70627000"]], "a": [["96834.01000000", "4.32320000"], ["96834.02000000", "0.00174000"], ["96836.00000000", "0.05056000"], ["96837.34000000", "0.00000000"], ["96837.35000000", "0.00000000"], ["96837.60000000", "0.04136000"], ["96838.30000000", "0.02444000"], ["96839.56000000", "0.00000000"], ["96839.99000000", "0.00042000"], ["96840.13000000", "0.24498000"], ["96840.62000000", "0.07925000"], ["96840.93000000", "0.02433000"], ["96841.46000000", "0.00998000"], ["96841.60000000", "0.01734000"], ["96844.69000000", "0.21301000"], ["96845.96000000", "0.00103000"], ["96849.99000000", "0.00999000"], ["96850.46000000", "0.00869000"], ["96850.47000000", "0.00000000"], ["96850.55000000", "0.00010000"], ["96850.56000000", "0.00000000"], ["96850.81000000", "0.00000000"], ["96850.87000000", "0.02289000"], ["96850.97000000", "0.00000000"], ["96851.88000000", "0.70751000"], ["96852.07000000", "0.00000000"], ["96853.58000000", "0.00000000"], ["96853.88000000", "1.68968000"], ["96853.90000000", "0.00000000"], ["96854.91000000", "0.00000000"], ["96870.90000000", "0.10232000"], ["96875.85000000", "0.02297000"], ["96883.10000000", "0.10615000"], ["96884.00000000", "0.00235000"], ["96884.58000000", "1.53870000"], ["96885.78000000", "0.00000000"], ["96889.74000000", "0.00000000"], ["96894.09000000", "0.03493000"], ["96895.04000000", "0.03627000"], ["96909.99000000", "0.00000000"], ["96910.95000000", "0.00000000"], ["96928.35000000", "0.02000000"], ["96932.07000000", "0.08640000"], ["97058.16000000", "0.00000000"], ["97059.05000000", "6.36809000"], ["97451.85000000", "0.00080000"], ["98286.53000000", "0.00000000"], ["99261.89000000", "0.00000000"], ["99262.02000000", "0.00341000"]]}
{"e": "depthUpdate", "E": 1746122588014, "s": "BTCUSDT", "b": [["96834.00000000", "6.33084000"], ["96833.99000000", "0.00042000"], ["96833.35000000", "0.00006000"], ["96833.34000000", "0.15771000"], ["96832.58000000", "0.23190000"], ["96831.20000000", "0.00000000"], ["96830.00000000", "0.05056000"], ["96829.53000000", "0.18756000"], ["96829.49000000", "0.00000000"], ["96829.11000000", "0.00000000"], ["96827.06000000", "0.04006000"], ["96826.61000000", "0.00000000"], ["96826.60000000", "0.00000000"], ["96826.58000000", "0.00000000"], ["96826.20000000", "0.30735000"], ["96826.19000000", "0.21307000"], ["96826.18000000", "0.21301000"], ["96826.03000000", "0.00000000"], ["96825.64000000", "0.00000000"], ["96825.37000000", "0.00000000"], ["96824.80000000", "0.04130000"], ["96824.33000000", "0.00000000"], ["96824.31000000", "0.54999000"], ["96823.66000000", "0.00000000"], ["96822.63000000", "0.00421000"], ["96822.35000000", "0.00007000"], ["96820.79000000", "0.00000000"], ["96819.71000000", "0.00000000"], ["96819.37000000", "0.00000000"], ["96819.00000000", "0.00516000"], ["96818.93000000", "0.00103000"], ["96817.59000000", "0.00000000"], ["96816.47000000", "0.61935000"], ["96813.89000000", "0.00464000"], ["96813.73000000", "0.00000000"], ["96810.92000000", "0.00000000"], ["96809.81000000", "0.03999000"], ["96808.24000000", "0.00000000"], ["96804.34000000", "1.41530000"], ["96804.24000000", "1.00000000"], ["96796.03000000", "0.00000000"], ["96788.53000000", "0.04340000"], ["96787.85000000", "0.00000000"], ["96787.84000000", "0.00000000"], ["96782.48000000", "0.00000000"], ["96774.48000000", "2.00000000"], ["96769.58000000", "0.00000000"], ["96769.02000000", "0.00000000"], ["96766.08000000", "0.30993000"], ["96756.74000000", "0.03799000"], ["96708.49000000", "0.00000000"], ["96687.02000000", "0.15895000"], ["96684.46000000", "0.00000000"], ["96676.05000000", "0.00000000"], ["96665.76000000", "0.10334000"], ["96628.70000000", "0.00000000"], ["95980.21000000", "0.00000000"], ["95883.36000000", "0.00000000"], ["95786.51000000", "0.00000000"], ["95689.66000000", "0.00000000"], ["95381.49000000", "0.00100000"], ["94150.00000000", "0.10971000"], ["87150.60000000", "0.00000000"], ["87150.00000000", "0.10415000"], ["77467.20000000", "0.00050000"], ["70000.00000000", "183.65512000"], ["42000.00000000", "3.70661000"], ["33000.00000000", "2.70627000"]], "a": [["96834.01000000", "6.56064000"], ["96834.02000000", "0.00090000"], ["96834.05000000", "0.00006000"], ["96834.51000000", "0.00013000"], ["96834.80000000", "0.00012000"], ["96834.81000000", "0.05351000"], ["96834.82000000", "0.06044000"], ["96834.84000000", "0.00000000"], ["96834.85000000", "0.00000000"], ["96835.33000000", "0.00006000"], ["96835.35000000", "0.00000000"], ["96835.40000000", "0.00000000"], ["96835.69000000", "0.00000000"], ["96835.98000000", "0.00000000"], ["96835.99000000", "0.00006000"], ["96837.59000000", "0.00006000"], ["96838.30000000", "0.02444000"], ["96838.91000000", "0.00000000"], ["96839.21000000", "0.00006000"], ["96839.22000000", "0.20503000"], ["96839.26000000", "0.00000000"], ["96839.27000000", "0.12397000"], ["96839.74000000", "0.00043000"], ["96839.75000000", "0.52603000"], ["96839.99000000", "0.00000000"], ["96840.11000000", "0.00000000"], ["96840.12000000", "0.44878000"], ["96840.13000000", "0.24492000"], ["96840.21000000", "0.68129000"], ["96840.62000000", "0.07919000"], ["96841.47000000", "0.00000000"], ["96842.69000000", "0.00000000"], ["96843.87000000", "0.00000000"], ["96844.69000000", "0.00000000"], ["96844.70000000", "0.61507000"], ["96844.71000000", "0.00000000"], ["96844.95000000", "0.00008000"], ["96845.24000000", "0.00000000"], ["96845.34000000", "0.00000000"], ["96845.35000000", "0.00000000"], ["96845.91000000", "0.00010000"], ["96846.23000000", "0.02289000"], ["96847.48000000", "0.00000000"], ["96848.29000000", "0.00010000"], ["96848.30000000", "0.05163000"], ["96848.61000000", "0.02289000"], ["96848.98000000", "0.00309000"], ["96849.01000000", "0.00999000"], ["96849.17000000", "0.00000000"], ["96849.99000000", "0.00000000"], ["96850.26000000", "0.00000000"], ["96850.46000000", "0.00560000"], ["96850.55000000", "0.00000000"], ["96850.87000000", "0.00000000"], ["96851.88000000", "0.65751000"], ["96853.87000000", "2.36306000"], ["96853.89000000", "0.00000000"], ["96857.68000000", "0.61935000"], ["96857.96000000", "1.00000000"], ["96858.25000000", "0.00000000"], ["96858.26000000", "0.00000000"], ["96860.97000000", "0.00000000"], ["96861.96000000", "0.00000000"], ["96862.26000000", "0.00000000"], ["96862.28000000", "0.00000000"], ["96862.97000000", "0.47653000"], ["96864.16000000", "0.00000000"], ["96864.41000000", "0.74304000"], ["96865.66000000", "0.00000000"], ["96866.50000000", "0.00000000"], ["96867.79000000", "0.00000000"], ["96868.07000000", "0.00000000"], ["96870.19000000", "0.00000000"], ["96871.48000000", "0.00000000"], ["96881.91000000", "2.00000000"], ["96882.51000000", "0.00009000"], ["96884.00000000", "0.00235000"], ["96884.70000000", "0.00000000"], ["96890.51000000", "0.00000000"], ["96893.36000000", "0.86846000"], ["96894.31000000", "0.00000000"], ["96897.31000000", "0.00000000"], ["96898.99000000", "0.00000000"], ["96902.13000000", "0.00000000"], ["96933.59000000", "0.05396000"], ["97059.05000000", "0.00000000"], ["98286.53000000", "0.00100000"]]}
{"e": "depthUpdate", "E": 1746122589014, "s": "BTCUSDT", "b": [["96834.00000000", "4.92337000"], ["96833.99000000", "0.00102000"], ["96833.35000000", "0.00000000"], ["96833.34000000", "0.00006000"], ["96833.33000000", "0.23357000"], ["96832.59000000", "0.00000000"], ["96832.58000000", "0.00000000"], ["96832.42000000", "0.00006000"], ["96831.43000000", "0.00006000"], ["96831.42000000", "0.24922000"], ["96830.63000000", "0.00000000"], ["96830.23000000", "0.00000000"], ["96830.00000000", "0.05056000"], ["96829.54000000", "0.00000000"], ["96829.53000000", "0.18756000"], ["96829.00000000", "0.00011000"], ["96828.11000000", "0.00000000"], ["96827.10000000", "0.23630000"], ["96827.09000000", "0.02062000"], ["96827.06000000", "0.00000000"], ["96826.35000000", "0.00000000"], ["96826.34000000", "0.00000000"], ["96826.33000000", "0.00000000"], ["96826.21000000", "0.00000000"], ["96826.20000000", "0.00000000"], ["96826.19000000", "0.00000000"], ["96826.18000000", "0.00000000"], ["96826.16000000", "0.21307000"], ["96824.80000000", "0.04136000"], ["96824.32000000", "0.00566000"], ["96824.31000000", "0.54006000"], ["96823.82000000", "0.02000000"], ["96823.18000000", "0.21301000"], ["96823.17000000", "0.21301000"], ["96822.85000000", "0.04800000"], ["96819.66000000", "0.04000000"], ["96819.24000000", "0.57733000"], ["96819.23000000", "0.50218000"], ["96819.00000000", "0.00000000"], ["96818.94000000", "0.00999000"], ["96818.93000000", "0.00000000"], ["96818.89000000", "0.00000000"], ["96818.88000000", "0.00000000"], ["96818.13000000", "0.00000000"], ["96816.47000000", "0.00000000"], ["96815.48000000", "0.00516000"], ["96813.76000000", "0.00000000"], ["96813.75000000", "0.00000000"], ["96813.67000000", "0.00000000"], ["96813.48000000", "0.74343000"], ["96812.72000000", "0.00000000"], ["96810.06000000", "0.00601000"], ["96809.81000000", "0.00000000"], ["96809.44000000", "0.00000000"], ["96808.13000000", "0.00000000"], ["96807.46000000", "0.00000000"], ["96805.51000000", "0.00000000"], ["96805.34000000", "0.09923000"], ["96804.48000000", "0.03999000"], ["96804.41000000", "0.00103000"], ["96804.24000000", "0.00000000"], ["96803.33000000", "0.74351000"], ["96802.14000000", "0.61944000"], ["96801.94000000", "0.00000000"], ["96801.63000000", "1.00000000"], ["96800.67000000", "0.00000000"], ["96800.34000000", "0.00000000"], ["96800.24000000", "0.00000000"], ["96800.03000000", "0.00000000"], ["96799.03000000", "0.74354000"], ["96798.54000000", "0.00000000"], ["96798.52000000", "0.00000000"], ["96797.10000000", "0.00000000"], ["96795.72000000", "0.01549000"], ["96792.79000000", "0.00000000"], ["96791.86000000", "0.04800000"], ["96790.88000000", "0.01032000"], ["96788.40000000", "0.50793000"], ["96787.92000000", "0.00000000"], ["96785.94000000", "0.03076000"], ["96782.43000000", "0.22627000"], ["96781.85000000", "0.00206000"], ["96774.48000000", "0.00000000"], ["96771.54000000", "0.00000000"], ["96770.41000000", "0.00000000"], ["96769.98000000", "0.00723000"], ["96769.88000000", "0.00000000"], ["96769.26000000", "2.00000000"], ["96766.68000000", "0.00000000"], ["96766.48000000", "0.00000000"], ["96766.06000000", "0.00000000"], ["96763.08000000", "0.00000000"], ["96760.60000000", "0.03932000"], ["96756.74000000", "0.00000000"], ["96745.78000000", "0.03799000"], ["96698.88000000", "0.00000000"], ["96625.09000000", "6.57396000"], ["96594.33000000", "0.01062000"], ["96590.01000000", "0.00000000"], ["95592.81000000", "0.00000000"], ["95495.95000000", "0.00000000"], ["95399.10000000", "0.00000000"], ["95381.49000000", "0.00000000"], ["95302.25000000", "0.00000000"], ["94737.69000000", "0.00006000"], ["93825.00000000", "0.00662000"], ["87150.60000000", "0.00000000"], ["87150.00000000", "0.10415000"], ["79000.00000000", "54.24605000"], ["77467.20000000", "0.00050000"], ["33000.00000000", "2.70627000"], ["20002.00000000", "0.00000000"]], "a": [["96834.01000000", "7.01461000"], ["96834.02000000", "0.00006000"], ["96834.51000000", "0.00013000"], ["96834.79000000", "0.00012000"], ["96834.80000000", "0.28123000"], ["96834.81000000", "0.00000000"], ["96834.82000000", "0.06044000"], ["96835.11000000", "0.00000000"], ["96835.12000000", "0.00000000"], ["96835.45000000", "0.00050000"], ["96835.72000000", "0.00000000"], ["96835.73000000", "0.00012000"], ["96835.99000000", "0.00000000"], ["96836.12000000", "0.00100000"], ["96836.89000000", "0.00051000"], ["96837.59000000", "0.00000000"], ["96837.60000000", "0.04136000"], ["96837.68000000", "0.12397000"], ["96837.70000000", "0.00006000"], ["96837.71000000", "0.68137000"], ["96837.77000000", "0.00000000"], ["96837.78000000", "0.00000000"], ["96837.90000000", "0.02070000"], ["96837.91000000", "0.00000000"], ["96837.92000000", "0.00000000"], ["96838.12000000", "0.00000000"], ["96838.27000000", "0.01112000"], ["96838.28000000", "0.00050000"], ["96838.30000000", "0.02444000"], ["96839.13000000", "0.00996000"], ["96839.21000000", "0.00000000"], ["96839.22000000", "0.00000000"], ["96839.27000000", "0.00000000"], ["96839.72000000", "0.00000000"], ["96839.73000000", "0.43820000"], ["96839.74000000", "0.21301000"], ["96839.75000000", "0.52597000"], ["96840.00000000", "0.05056000"], ["96840.12000000", "0.00000000"], ["96840.15000000", "0.00050000"], ["96840.21000000", "0.00000000"], ["96840.90000000", "0.00051000"], ["96840.93000000", "0.00000000"], ["96841.46000000", "0.00000000"], ["96842.21000000", "0.00000000"], ["96842.53000000", "0.00000000"], ["96842.85000000", "0.00010000"], ["96843.17000000", "0.02289000"], ["96843.18000000", "0.00000000"], ["96844.14000000", "0.00999000"], ["96844.67000000", "1.38883000"], ["96844.68000000", "1.68968000"], ["96844.69000000", "0.21301000"], ["96844.70000000", "0.00000000"], ["96845.03000000", "0.00000000"], ["96845.28000000", "0.00309000"], ["96845.29000000", "0.00000000"], ["96845.35000000", "0.00000000"], ["96845.58000000", "0.00000000"], ["96845.91000000", "0.00000000"], ["96846.23000000", "0.00000000"], ["96846.54000000", "0.09600000"], ["96846.59000000", "0.00000000"], ["96846.62000000", "0.15360000"], ["96846.72000000", "0.05163000"], ["96846.86000000", "0.00000000"], ["96847.08000000", "0.00013000"], ["96847.09000000", "0.00464000"], ["96847.27000000", "0.61942000"], ["96847.61000000", "0.00000000"], ["96847.63000000", "0.00000000"], ["96847.72000000", "0.21301000"], ["96848.29000000", "0.00526000"], ["96848.30000000", "0.00000000"], ["96848.36000000", "0.00051000"], ["96848.40000000", "0.00000000"], ["96848.48000000", "0.00000000"], ["96848.84000000", "0.00000000"], ["96848.98000000", "0.00000000"], ["96849.01000000", "0.00000000"], ["96850.42000000", "0.08160000"], ["96851.40000000", "0.08640000"], ["96852.56000000", "0.00000000"], ["96852.76000000", "0.00000000"], ["96854.26000000", "0.00000000"], ["96854.36000000", "0.00000000"], ["96854.64000000", "0.00051000"], ["96854.76000000", "0.03999000"], ["96855.36000000", "0.00000000"], ["96855.65000000", "1.00000000"], ["96855.96000000", "0.00000000"], ["96856.05000000", "0.00777000"], ["96856.24000000", "0.00000000"], ["96856.36000000", "0.00000000"], ["96857.68000000", "0.00000000"], ["96857.96000000", "0.00000000"], ["96859.99000000", "0.00000000"], ["96860.19000000", "0.74307000"], ["96861.11000000", "0.17791000"], ["96861.15000000", "0.00000000"], ["96861.38000000", "0.00000000"], ["96861.46000000", "0.00000000"], ["96861.90000000", "0.00000000"], ["96862.94000000", "0.00000000"], ["96862.97000000", "0.00000000"], ["96865.21000000", "0.00000000"], ["96868.26000000", "1.65393000"], ["96871.11000000", "0.00000000"], ["96871.34000000", "0.00000000"], ["96871.51000000", "0.00000000"], ["96874.51000000", "0.00000000"], ["96874.71000000", "0.00000000"], ["96876.71000000", "0.00000000"], ["96876.95000000", "0.09961000"], ["96877.29000000", "2.00000000"], ["96877.91000000", "0.00000000"], ["96878.42000000", "0.03493000"], ["96879.34000000", "0.03627000"], ["96880.04000000", "0.00000000"], ["96881.91000000", "0.00000000"], ["96882.98000000", "0.01549000"], ["96883.00000000", "0.00011000"], ["96883.10000000", "0.00000000"], ["96884.58000000", "0.00000000"], ["96884.59000000", "0.00000000"], ["96888.18000000", "0.83376000"], ["96888.75000000", "0.00000000"], ["96889.09000000", "0.00000000"], ["96889.79000000", "0.00054000"], ["96890.63000000", "0.01032000"], ["96891.87000000", "0.00000000"], ["96893.59000000", "0.00000000"], ["96894.09000000", "0.00000000"], ["96895.04000000", "0.00000000"], ["96898.43000000", "0.00000000"], ["96929.48000000", "0.00000000"], ["96932.41000000", "0.11139000"], ["96965.47000000", "0.00000000"], ["97056.74000000", "6.61428000"], ["97451.85000000", "0.00080000"], ["97802.34000000", "0.00000000"], ["98286.53000000", "0.00000000"]]}
{"e": "depthUpdate", "E": 1746122590014, "s": "BTCUSDT", "b": [["96834.00000000", "5.55269000"], ["96833.99000000", "0.00114000"], ["96833.87000000", "0.00006000"], ["96833.85000000", "0.00012000"], ["96833.84000000", "0.23700000"], ["96833.50000000", "0.00010000"], ["96833.49000000", "0.00000000"], ["96833.33000000", "0.23351000"], ["96831.79000000", "0.00000000"], ["96831.78000000", "0.00000000"], ["96831.43000000", "0.00000000"], ["96831.42000000", "0.00000000"], ["96830.23000000", "0.02407000"], ["96829.53000000", "0.18756000"], ["96829.24000000", "0.21307000"], ["96827.10000000", "0.29240000"], ["96827.09000000", "0.00000000"], ["96826.83000000", "0.00000000"], ["96826.17000000", "0.21307000"], ["96826.16000000", "0.21307000"], ["96824.80000000", "0.04130000"], ["96824.31000000", "0.54000000"], ["96823.82000000", "0.02000000"], ["96819.24000000", "0.83904000"], ["96814.57000000", "1.10000000"], ["96813.48000000", "0.00000000"], ["96813.44000000", "0.74343000"], ["96806.62000000", "1.00000000"], ["96805.06000000", "0.00000000"], ["96804.72000000", "0.00000000"], ["96801.63000000", "0.00000000"], ["96801.32000000", "0.00000000"], ["96799.82000000", "0.00000000"], ["96799.72000000", "0.00000000"], ["96798.22000000", "0.00000000"], ["96797.24000000", "0.00000000"], ["96779.61000000", "0.72373000"], ["96779.24000000", "2.00000000"], ["96776.12000000", "0.00000000"], ["96775.44000000", "0.00000000"], ["96770.28000000", "0.00000000"], ["96770.24000000", "0.00000000"], ["96769.26000000", "0.00000000"], ["96768.64000000", "0.00000000"], ["96765.64000000", "0.00000000"], ["96765.44000000", "0.00000000"], ["96762.44000000", "0.00000000"], ["96753.78000000", "0.00000000"], ["96749.02000000", "0.01032000"], ["96737.15000000", "0.00000000"], ["96655.18000000", "0.00000000"], ["96640.34000000", "0.00020000"], ["96625.09000000", "0.00011000"], ["96624.77000000", "6.32547000"], ["96551.13000000", "0.64319000"], ["96507.41000000", "0.00000000"], ["96462.84000000", "0.00000000"], ["96419.18000000", "0.00000000"], ["95381.49000000", "0.00100000"], ["95205.40000000", "0.00000000"], ["95108.55000000", "0.00000000"], ["95011.69000000", "0.00000000"], ["94914.84000000", "0.00000000"], ["91992.30000000", "0.00010000"], ["89087.28000000", "0.00012000"], ["87150.60000000", "0.00000000"], ["87150.00000000", "0.10415000"], ["77467.20000000", "0.00050000"], ["70000.00000000", "183.65512000"], ["42000.00000000", "3.70561000"], ["33000.00000000", "2.70627000"]], "a": [["96834.01000000", "7.24762000"], ["96834.02000000", "0.00048000"], ["96834.82000000", "0.06044000"], ["96835.23000000", "0.00006000"], ["96835.24000000", "0.68139000"], ["96835.58000000", "0.02445000"], ["96836.00000000", "0.05056000"], ["96837.25000000", "0.00000000"], ["96837.26000000", "0.00000000"], ["96837.60000000", "0.04136000"], ["96837.68000000", "0.00000000"], ["96837.70000000", "0.00000000"], ["96837.71000000", "0.00000000"], ["96838.30000000", "0.02444000"], ["96839.73000000", "0.32514000"], ["96839.74000000", "0.00000000"], ["96840.74000000", "0.00560000"], ["96843.04000000", "0.00000000"], ["96843.45000000", "0.00000000"], ["96844.66000000", "0.00000000"], ["96844.67000000", "0.61268000"], ["96844.68000000", "0.00000000"], ["96844.69000000", "0.00000000"], ["96844.72000000", "0.00000000"], ["96845.58000000", "0.02000000"], ["96846.02000000", "0.21301000"], ["96846.46000000", "0.09600000"], ["96847.09000000", "0.00000000"], ["96847.27000000", "0.00000000"], ["96847.72000000", "0.00000000"], ["96849.04000000", "0.21301000"], ["96849.36000000", "0.08640000"], ["96850.46000000", "0.00000000"], ["96850.63000000", "0.00000000"], ["96851.39000000", "0.61939000"], ["96851.40000000", "0.16320000"], ["96851.47000000", "0.06720000"], ["96852.26000000", "0.00000000"], ["96853.76000000", "0.00000000"], ["96853.86000000", "0.00000000"], ["96855.30000000", "0.00000000"], ["96855.36000000", "0.00000000"], ["96855.65000000", "0.00000000"], ["96855.97000000", "0.00464000"], ["96856.09000000", "0.05000000"], ["96856.26000000", "0.00000000"], ["96857.80000000", "0.30525000"], ["96858.76000000", "0.00000000"], ["96859.16000000", "0.00000000"], ["96860.16000000", "0.00000000"], ["96860.66000000", "1.00000000"], ["96861.11000000", "0.10111000"], ["96861.18000000", "0.00000000"], ["96863.27000000", "0.00000000"], ["96864.31000000", "0.00000000"], ["96865.88000000", "0.00000000"], ["96868.13000000", "0.77998000"], ["96870.51000000", "0.00000000"], ["96873.51000000", "0.00000000"], ["96873.71000000", "0.00000000"], ["96876.71000000", "0.00000000"], ["96877.29000000", "0.00000000"], ["96883.00000000", "0.00000000"], ["96883.51000000", "0.00000000"], ["96887.31000000", "2.00000000"], ["96892.53000000", "0.00000000"], ["96894.61000000", "0.00000000"], ["96897.75000000", "0.00000000"], ["96915.07000000", "0.00000000"], ["96928.35000000", "0.00000000"], ["96929.48000000", "0.07680000"], ["96932.07000000", "0.00000000"], ["96961.28000000", "0.01715000"], ["96976.90000000", "0.00000000"], ["97053.12000000", "6.37068000"], ["97056.74000000", "0.00000000"], ["98000.00000000", "137.74008000"], ["98286.53000000", "0.00100000"], ["109881.77000000", "0.00066000"]]}
{"e": "depthUpdate", "E": 1746123309014, "s": "BTCUSDT", "b": [["96590.00000000", "4.98380000"], ["96589.75000000", "0.00022000"], ["96589.74000000", "0.04095000"], ["96589.73000000", "0.00000000"], ["96588.60000000", "0.00022000"], ["96588.59000000", "0.05174000"], ["96588.16000000", "0.00007000"], ["96588.01000000", "0.00012000"], ["96588.00000000", "0.08171000"], ["96587.34000000", "0.00000000"], ["96587.33000000", "0.00000000"], ["96586.58000000", "0.00000000"], ["96586.48000000", "0.03113000"], ["96586.36000000", "0.00806000"], ["96586.20000000", "0.01290000"], ["96586.15000000", "0.21307000"], ["96586.00000000", "0.03796000"], ["96585.06000000", "0.00000000"], ["96585.03000000", "0.00000000"], ["96585.02000000", "0.78556000"], ["96585.01000000", "0.02000000"], ["96584.86000000", "0.00000000"], ["96583.23000000", "0.26919000"], ["96582.91000000", "0.07919000"], ["96581.23000000", "0.47258000"], ["96580.24000000", "0.00000000"], ["96580.14000000", "0.00999000"], ["96579.92000000", "0.00000000"], ["96579.20000000", "0.00000000"], ["96578.56000000", "0.00011000"], ["96578.20000000", "0.00000000"], ["96574.14000000", "0.00000000"], ["96571.31000000", "0.00000000"], ["96568.39000000", "0.00000000"], ["96566.19000000", "1.85073000"], ["96563.34000000", "0.00000000"], ["96563.29000000", "0.00000000"], ["96563.09000000", "0.00000000"], ["96560.03000000", "0.03824000"], ["96557.75000000", "0.03911000"], ["96550.62000000", "0.00000000"], ["96544.99000000", "0.00000000"], ["96543.98000000", "0.01748000"], ["96538.93000000", "0.00000000"], ["96535.57000000", "0.00000000"], ["96535.28000000", "0.00178000"], ["96529.49000000", "0.00000000"], ["96523.40000000", "0.00000000"], ["96519.79000000", "0.05006000"], ["96518.91000000", "0.00000000"], ["96518.70000000", "0.03500000"], ["96518.38000000", "0.00000000"], ["96515.01000000", "0.00000000"], ["96509.75000000", "0.00357000"], ["96505.23000000", "0.05297000"], ["96502.14000000", "0.05297000"], ["96498.64000000", "0.05306000"], ["96495.94000000", "0.05297000"], ["96493.32000000", "0.10593000"], ["96489.33000000", "0.05297000"], ["96487.13000000", "0.05297000"], ["96485.83000000", "0.05297000"], ["96483.35000000", "0.05297000"], ["96480.79000000", "0.05297000"], ["96477.50000000", "0.05323000"], ["96473.71000000", "0.05297000"], ["96447.93000000", "2.69947000"], ["96267.49000000", "0.04766000"], ["96257.84000000", "0.00583000"], ["95249.99000000", "0.00000000"], ["95141.15000000", "0.00000000"], ["86931.00000000", "0.00020000"], ["79000.00000000", "54.24635000"], ["77272.00000000", "0.00050000"], ["33000.00000000", "2.70627000"]], "a": [["96590.01000000", "1.17595000"], ["96590.17000000", "0.00006000"], ["96590.18000000", "0.00006000"], ["96590.19000000", "0.00018000"], ["96590.20000000", "0.01022000"], ["96590.30000000", "0.00006000"], ["96590.49000000", "0.00013000"], ["96590.82000000", "0.00012000"], ["96590.83000000", "0.20339000"], ["96591.49000000", "0.00000000"], ["96591.69000000", "0.00202000"], ["96591.76000000", "0.00403000"], ["96592.00000000", "0.00000000"], ["96592.80000000", "0.00000000"], ["96592.88000000", "0.00000000"], ["96592.98000000", "0.00000000"], ["96593.78000000", "0.00000000"], ["96593.98000000", "0.00000000"], ["96593.99000000", "0.03560000"], ["96594.00000000", "0.03796000"], ["96594.19000000", "0.00000000"], ["96594.40000000", "0.00000000"], ["96595.12000000", "0.00000000"], ["96595.99000000", "0.00000000"], ["96596.47000000", "0.00000000"], ["96596.48000000", "0.03524000"], ["96596.65000000", "0.00000000"], ["96596.66000000", "0.00000000"], ["96596.97000000", "0.00000000"], ["96597.09000000", "0.00000000"], ["96597.99000000", "0.00000000"], ["96598.00000000", "0.03796000"], ["96598.58000000", "0.00000000"], ["96599.21000000", "0.02812000"], ["96599.64000000", "0.00012000"], ["96599.65000000", "0.56164000"], ["96599.66000000", "0.42602000"], ["96599.67000000", "0.54000000"], ["96599.99000000", "0.03900000"], ["96600.00000000", "0.03796000"], ["96600.74000000", "0.77637000"], ["96600.80000000", "0.04140000"], ["96600.94000000", "0.00091000"], ["96601.24000000", "0.00000000"], ["96601.36000000", "0.00094000"], ["96601.56000000", "0.00000000"], ["96601.73000000", "0.00000000"], ["96602.60000000", "0.01035000"], ["96602.61000000", "0.00000000"], ["96602.97000000", "0.00000000"], ["96603.05000000", "0.38433000"], ["96603.06000000", "0.68296000"], ["96603.13000000", "0.00092000"], ["96603.20000000", "0.00000000"], ["96603.83000000", "0.47477000"], ["96604.59000000", "0.00000000"], ["96604.81000000", "0.00999000"], ["96606.06000000", "0.00000000"], ["96607.81000000", "0.00000000"], ["96608.66000000", "0.06454000"], ["96609.33000000", "0.54000000"], ["96609.62000000", "0.06000000"], ["96609.77000000", "0.00000000"], ["96610.62000000", "0.00000000"], ["96610.81000000", "0.00000000"], ["96610.94000000", "0.00000000"], ["96611.39000000", "0.00000000"], ["96611.73000000", "0.00000000"], ["96611.78000000", "0.00000000"], ["96612.40000000", "0.00000000"], ["96612.72000000", "0.00000000"], ["96613.15000000", "0.00000000"], ["96613.30000000", "0.00000000"], ["96614.95000000", "0.00000000"], ["96615.26000000", "0.00000000"], ["96615.27000000", "0.00000000"], ["96615.79000000", "0.00310000"], ["96615.84000000", "0.00000000"], ["96615.85000000", "0.00000000"], ["96615.99000000", "0.00517000"], ["96616.97000000", "0.00010000"], ["96617.29000000", "0.02295000"], ["96618.00000000", "0.00000000"], ["96618.01000000", "0.00000000"], ["96618.02000000", "0.00000000"], ["96618.03000000", "0.00000000"], ["96618.04000000", "0.00000000"], ["96618.07000000", "0.00000000"], ["96618.18000000", "0.00000000"], ["96619.05000000", "0.00000000"], ["96619.06000000", "0.00000000"], ["96621.27000000", "0.00000000"], ["96622.61000000", "0.00000000"], ["96623.82000000", "0.74489000"], ["96624.47000000", "0.00000000"], ["96624.49000000", "0.00000000"], ["96624.85000000", "0.44366000"], ["96626.89000000", "1.15016000"], ["96627.65000000", "0.00000000"], ["96628.05000000", "0.00464000"], ["96628.19000000", "0.00000000"], ["96631.00000000", "0.00000000"], ["96633.10000000", "0.62079000"], ["96636.49000000", "0.74479000"], ["96639.93000000", "0.05000000"], ["96640.40000000", "0.10080000"], ["96641.34000000", "1.68758000"], ["96643.28000000", "0.08640000"], ["96645.20000000", "0.63289000"], ["96645.97000000", "0.00000000"], ["96651.25000000", "0.31055000"], ["96653.07000000", "0.00000000"], ["96661.17000000", "0.00000000"], ["96667.61000000", "0.00257000"], ["96668.62000000", "0.00257000"], ["96671.27000000", "0.03601000"], ["96672.89000000", "0.00000000"], ["96678.07000000", "0.03531000"], ["96679.17000000", "0.00000000"], ["96695.15000000", "0.00178000"], ["96698.00000000", "0.04037000"], ["96704.82000000", "0.00357000"], ["96705.64000000", "0.00000000"], ["96709.36000000", "0.00000000"], ["96719.33000000", "0.00000000"], ["96733.22000000", "0.11139000"], ["96734.23000000", "0.00000000"], ["96763.98000000", "0.00103000"], ["96766.52000000", "0.00103000"], ["96784.69000000", "0.00000000"], ["96786.32000000", "0.00000000"], ["96893.22000000", "0.20798000"], ["96902.87000000", "0.12580000"], ["96912.52000000", "0.01793000"], ["96922.17000000", "0.00250000"], ["96952.00000000", "0.00235000"], ["98038.87000000", "0.00000000"]]}
{"e": "depthUpdate", "E": 1746123310014, "s": "BTCUSDT", "b": [["96590.00000000", "3.77187000"], ["96588.45000000", "0.00051000"], ["96586.49000000", "0.00800000"], ["96586.36000000", "0.00006000"], ["96584.04000000", "0.00000000"], ["96584.01000000", "0.00043000"], ["96582.65000000", "0.38923000"], ["96581.86000000", "0.00052000"], ["96581.85000000", "0.20259000"], ["96581.24000000", "0.00021000"], ["96578.34000000", "0.02077000"], ["96577.02000000", "0.00000000"], ["96575.96000000", "0.00000000"], ["96562.70000000", "0.00521000"], ["96560.03000000", "0.00000000"], ["96557.75000000", "0.00016000"], ["96550.98000000", "0.00000000"], ["96549.11000000", "0.03824000"], ["96546.73000000", "0.03895000"], ["96518.70000000", "0.00000000"], ["96482.72000000", "0.00545000"], ["96482.05000000", "0.00000000"], ["96475.50000000", "0.05297000"], ["95624.10000000", "0.00000000"], ["95507.35000000", "0.04105000"], ["95141.15000000", "0.00100000"], ["94680.62000000", "0.00000000"], ["91774.40000000", "0.00000000"], ["88874.84000000", "0.00012000"], ["86931.00000000", "0.00020000"], ["77272.00000000", "0.00050000"], ["70000.00000000", "183.65512000"], ["42000.00000000", "3.70561000"], ["34772.40000000", "0.00036000"], ["33000.00000000", "2.70627000"], ["20002.00000000", "0.00000000"]], "a": [["96590.01000000", "1.51400000"], ["96590.06000000", "0.00006000"], ["96590.20000000", "0.01022000"], ["96590.30000000", "0.00006000"], ["96590.49000000", "0.00000000"], ["96590.81000000", "0.00012000"], ["96590.82000000", "0.09854000"], ["96590.83000000", "0.20339000"], ["96591.11000000", "0.00000000"], ["96593.99000000", "0.00000000"], ["96598.00000000", "0.03796000"], ["96599.21000000", "0.00000000"], ["96599.64000000", "0.00012000"], ["96599.65000000", "0.51848000"], ["96599.66000000", "0.42608000"], ["96599.67000000", "0.54000000"], ["96599.99000000", "0.03900000"], ["96600.00000000", "0.03796000"], ["96600.44000000", "0.00000000"], ["96600.74000000", "0.00000000"], ["96600.94000000", "0.00000000"], ["96601.25000000", "0.68298000"], ["96603.06000000", "0.00000000"], ["96603.20000000", "0.00008000"], ["96603.75000000", "0.01064000"], ["96603.83000000", "0.47477000"], ["96603.84000000", "0.00999000"], ["96604.81000000", "0.00000000"], ["96606.91000000", "0.00000000"], ["96607.23000000", "0.77994000"], ["96607.71000000", "0.00000000"], ["96610.54000000", "0.00051000"], ["96611.77000000", "1.79462000"], ["96611.78000000", "1.68968000"], ["96611.79000000", "0.00000000"], ["96612.57000000", "0.77637000"], ["96612.67000000", "0.77637000"], ["96614.85000000", "0.00000000"], ["96615.17000000", "0.00000000"], ["96615.18000000", "0.00000000"], ["96617.04000000", "0.19370000"], ["96618.98000000", "0.10350000"], ["96634.44000000", "0.00560000"], ["96639.93000000", "0.00000000"], ["96640.40000000", "0.18240000"], ["96645.05000000", "0.07680000"], ["96701.00000000", "0.00000000"], ["96704.37000000", "0.00000000"], ["96709.71000000", "0.00000000"], ["96710.90000000", "0.00000000"], ["96715.74000000", "0.00000000"], ["96731.70000000", "0.03798000"], ["97055.00000000", "0.00015000"], ["98038.87000000", "0.00100000"]]}
{"e": "depthUpdate", "E": 1746123311014, "s": "BTCUSDT", "b": [["96590.00000000", "3.23485000"], ["96589.84000000", "0.00006000"], ["96589.83000000", "0.00320000"], ["96589.75000000", "0.00000000"], ["96589.74000000", "0.00000000"], ["96589.48000000", "0.00012000"], ["96589.47000000", "0.02692000"], ["96588.64000000", "0.00022000"], ["96588.63000000", "0.00022000"], ["96588.61000000", "0.00096000"], ["96588.60000000", "0.00000000"], ["96588.59000000", "0.00000000"], ["96588.45000000", "0.00000000"], ["96588.15000000", "0.05182000"], ["96588.02000000", "0.00012000"], ["96588.01000000", "0.02480000"], ["96588.00000000", "0.08171000"], ["96586.48000000", "0.00000000"], ["96586.36000000", "0.00000000"], ["96586.35000000", "0.00000000"], ["96586.22000000", "0.00000000"], ["96586.21000000", "0.00000000"], ["96586.20000000", "0.01290000"], ["96586.15000000", "0.00000000"], ["96586.01000000", "0.00000000"], ["96586.00000000", "0.03796000"], ["96585.03000000", "0.00000000"], ["96585.02000000", "0.00008000"], ["96585.01000000", "0.02006000"], ["96584.89000000", "0.00006000"], ["96584.60000000", "0.00000000"], ["96584.59000000", "0.00012000"], ["96584.58000000", "0.21307000"], ["96584.57000000", "0.00000000"], ["96584.49000000", "0.00000000"], ["96584.46000000", "0.00000000"], ["96584.41000000", "0.03113000"], ["96584.37000000", "0.00000000"], ["96584.19000000", "0.00000000"], ["96584.06000000", "0.00000000"], ["96584.05000000", "1.04075000"], ["96584.04000000", "0.00000000"], ["96584.03000000", "0.04800000"], ["96583.86000000", "0.04800000"], ["96583.85000000", "0.04800000"], ["96583.64000000", "0.00000000"], ["96583.24000000", "0.00009000"], ["96583.23000000", "0.00000000"], ["96583.22000000", "0.00000000"], ["96583.21000000", "0.00000000"], ["96583.20000000", "0.00000000"], ["96582.91000000", "0.00000000"], ["96582.65000000", "0.00000000"], ["96582.62000000", "0.00000000"], ["96582.34000000", "0.02070000"], ["96582.33000000", "0.62084000"], ["96582.17000000", "0.00000000"], ["96581.85000000", "0.00000000"], ["96581.30000000", "0.05176000"], ["96581.23000000", "0.00000000"], ["96580.58000000", "0.00000000"], ["96580.30000000", "0.00000000"], ["96580.22000000", "0.00000000"], ["96580.20000000", "0.00000000"], ["96580.14000000", "0.00000000"], ["96580.12000000", "1.06908000"], ["96580.11000000", "1.68968000"], ["96580.10000000", "0.94343000"], ["96580.05000000", "0.00000000"], ["96579.60000000", "0.00000000"], ["96579.33000000", "0.00000000"], ["96579.17000000", "0.00999000"], ["96579.15000000", "0.00000000"], ["96578.65000000", "0.00000000"], ["96578.35000000", "0.00517000"], ["96577.98000000", "0.39255000"], ["96577.78000000", "0.00000000"], ["96577.30000000", "0.00000000"], ["96577.29000000", "0.00000000"], ["96577.28000000", "0.00000000"], ["96577.27000000", "0.00000000"], ["96576.88000000", "0.00464000"], ["96576.74000000", "0.06455000"], ["96576.72000000", "0.00050000"], ["96576.25000000", "0.21301000"], ["96576.02000000", "0.00000000"], ["96575.98000000", "0.00000000"], ["96575.71000000", "0.21301000"], ["96575.47000000", "1.44731000"], ["96575.26000000", "0.00008000"], ["96575.15000000", "0.00000000"], ["96573.81000000", "0.00000000"], ["96573.64000000", "1.65358000"], ["96573.61000000", "0.00517000"], ["96573.59000000", "0.00103000"], ["96573.34000000", "0.21301000"], ["96572.73000000", "1.68968000"], ["96572.72000000", "0.21301000"], ["96572.71000000", "0.00000000"], ["96572.66000000", "0.00000000"], ["96572.56000000", "0.00013000"], ["96572.55000000", "0.00000000"], ["96572.48000000", "0.00000000"], ["96571.50000000", "0.00000000"], ["96571.01000000", "0.00000000"], ["96570.69000000", "0.00206000"], ["96570.68000000", "0.05175000"], ["96570.43000000", "0.00000000"], ["96570.42000000", "0.21301000"], ["96569.28000000", "0.54917000"], ["96569.27000000", "0.21301000"], ["96567.92000000", "0.00000000"], ["96567.52000000", "0.21301000"], ["96566.53000000", "1.64308000"], ["96566.24000000", "0.31055000"], ["96566.20000000", "0.21301000"], ["96566.19000000", "0.00000000"], ["96566.18000000", "0.00000000"], ["96565.87000000", "0.00000000"], ["96565.40000000", "0.00000000"], ["96562.11000000", "0.00000000"], ["96561.72000000", "0.21301000"], ["96561.36000000", "0.21301000"], ["96561.29000000", "0.00000000"], ["96558.88000000", "0.77637000"], ["96558.66000000", "0.00000000"], ["96557.89000000", "0.77637000"], ["96556.37000000", "0.77637000"], ["96556.21000000", "0.42602000"], ["96555.82000000", "0.00000000"], ["96555.32000000", "0.02300000"], ["96555.06000000", "0.00000000"], ["96554.21000000", "0.57624000"], ["96553.75000000", "0.00000000"], ["96553.63000000", "0.77637000"], ["96552.72000000", "0.00000000"], ["96552.36000000", "0.48958000"], ["96550.54000000", "0.42602000"], ["96550.53000000", "0.77637000"], ["96549.11000000", "0.00000000"], ["96548.94000000", "0.78447000"], ["96547.59000000", "0.77637000"], ["96546.73000000", "0.00000000"], ["96544.99000000", "0.05000000"], ["96543.32000000", "0.00000000"], ["96541.55000000", "0.00070000"], ["96541.54000000", "0.00000000"], ["96533.91000000", "0.03824000"], ["96529.49000000", "0.08711000"], ["96529.28000000", "0.00000000"], ["96528.21000000", "0.03895000"], ["96527.60000000", "0.31055000"], ["96519.79000000", "0.00006000"], ["96517.39000000", "0.74178000"], ["96516.07000000", "0.51758000"], ["96515.01000000", "0.07919000"], ["96506.51000000", "0.00000000"], ["96501.96000000", "0.00258000"], ["96494.91000000", "0.00000000"], ["96488.59000000", "0.00008000"], ["96476.81000000", "1.69112000"], ["96454.23000000", "0.00000000"], ["96452.18000000", "0.00000000"], ["96451.62000000", "0.00227000"], ["96447.93000000", "0.00000000"], ["96446.77000000", "0.00000000"], ["96436.26000000", "0.38169000"], ["96403.61000000", "0.01276000"], ["96363.04000000", "0.00000000"], ["96355.08000000", "0.00193000"], ["96159.25000000", "0.00000000"], ["95960.00000000", "0.00363000"], ["95918.32000000", "0.00074000"], ["95507.35000000", "0.00000000"], ["95141.15000000", "0.00000000"], ["94538.49000000", "0.00000000"], ["88874.84000000", "0.00000000"], ["86931.00000000", "0.00020000"], ["79000.00000000", "54.24632000"], ["77272.00000000", "0.00050000"], ["33000.00000000", "2.70627000"]], "a": [["96590.01000000", "3.80506000"], ["96590.20000000", "0.01022000"], ["96590.30000000", "0.00006000"], ["96590.81000000", "0.00000000"], ["96590.82000000", "0.00012000"], ["96590.83000000", "0.20339000"], ["96592.22000000", "0.00000000"], ["96593.19000000", "0.00000000"], ["96594.00000000", "0.03796000"], ["96594.38000000", "0.00000000"], ["96594.40000000", "0.04146000"], ["96596.00000000", "0.03796000"], ["96596.27000000", "0.00000000"], ["96596.48000000", "0.03524000"], ["96596.72000000", "0.00000000"], ["96598.00000000", "0.03796000"], ["96598.02000000", "0.00012000"], ["96598.03000000", "0.45378000"], ["96598.04000000", "0.00000000"], ["96598.05000000", "0.00000000"], ["96598.06000000", "0.42877000"], ["96599.18000000", "0.00000000"], ["96599.21000000", "0.02820000"], ["96599.64000000", "0.00000000"], ["96599.65000000", "0.00000000"], ["96599.66000000", "0.00000000"], ["96601.25000000", "0.00000000"], ["96601.36000000", "0.00000000"], ["96601.55000000", "0.00000000"], ["96601.56000000", "0.42685000"], ["96601.57000000", "0.68297000"], ["96602.18000000", "0.07919000"], ["96602.60000000", "0.01138000"], ["96603.05000000", "0.00000000"], ["96603.13000000", "0.00000000"], ["96603.83000000", "0.00000000"], ["96607.14000000", "0.00000000"], ["96607.46000000", "0.00000000"], ["96609.02000000", "0.00000000"], ["96609.34000000", "0.00000000"], ["96609.97000000", "0.00000000"], ["96610.29000000", "0.01881000"], ["96610.30000000", "0.00000000"], ["96610.81000000", "0.00000000"], ["96610.92000000", "0.00000000"], ["96611.00000000", "0.00000000"], ["96611.12000000", "0.00000000"], ["96611.24000000", "0.00000000"], ["96611.25000000", "0.00000000"], ["96611.66000000", "0.00010000"], ["96611.78000000", "0.00000000"], ["96611.99000000", "0.00517000"], ["96612.27000000", "0.00414000"], ["96612.88000000", "0.00000000"], ["96613.20000000", "0.00000000"], ["96613.22000000", "0.00000000"], ["96613.23000000", "0.00000000"], ["96615.30000000", "0.77637000"], ["96615.99000000", "0.00000000"], ["96618.98000000", "0.10350000"], ["96619.84000000", "0.00000000"], ["96619.92000000", "0.00000000"], ["96621.97000000", "0.00000000"], ["96624.14000000", "0.00000000"], ["96625.12000000", "0.21301000"], ["96627.13000000", "0.05011000"], ["96629.15000000", "0.00000000"], ["96632.13000000", "0.00000000"], ["96633.80000000", "1.64786000"], ["96634.27000000", "0.74481000"], ["96634.30000000", "0.74481000"], ["96634.55000000", "0.10606000"], ["96636.48000000", "1.11157000"], ["96636.49000000", "0.00000000"], ["96636.93000000", "0.00000000"], ["96639.14000000", "0.02298000"], ["96641.34000000", "0.00000000"], ["96649.06000000", "0.00000000"], ["96650.03000000", "0.31055000"], ["96651.25000000", "0.00000000"], ["96654.97000000", "0.03601000"], ["96659.51000000", "0.00000000"], ["96660.78000000", "0.00000000"], ["96660.91000000", "0.00000000"], ["96662.81000000", "0.03531000"], ["96671.27000000", "0.00000000"], ["96678.07000000", "0.00000000"], ["96688.00000000", "0.00210000"], ["96789.99000000", "0.01276000"], ["96833.33000000", "0.00006000"], ["98000.00000000", "141.76759000"], ["98038.87000000", "0.00000000"], ["104875.75000000", "0.01920000"]]}
{"e": "depthUpdate", "E": 1746123312014, "s": "BTCUSDT", "b": [["96590.00000000", "4.68650000"], ["96589.86000000", "0.00006000"], ["96589.85000000", "0.00006000"], ["96589.53000000", "0.00000000"], ["96589.48000000", "0.00000000"], ["96589.47000000", "0.00000000"], ["96589.44000000", "0.00000000"], ["96589.43000000", "0.00000000"], ["96588.95000000", "0.00012000"], ["96588.94000000", "0.16966000"], ["96588.93000000", "0.00030000"], ["96588.92000000", "0.07925000"], ["96588.64000000", "0.00000000"], ["96588.63000000", "0.00000000"], ["96588.62000000", "0.00000000"], ["96588.17000000", "0.00000000"], ["96588.16000000", "0.00007000"], ["96588.15000000", "0.00000000"], ["96588.06000000", "0.00044000"], ["96588.02000000", "0.00000000"], ["96588.01000000", "0.00000000"], ["96588.00000000", "0.08171000"], ["96587.11000000", "0.00529000"], ["96587.10000000", "0.42608000"], ["96586.85000000", "0.00000000"], ["96586.84000000", "0.00000000"], ["96586.49000000", "0.00000000"], ["96586.01000000", "0.00000000"], ["96586.00000000", "0.03796000"], ["96585.01000000", "0.00000000"], ["96584.88000000", "0.00000000"], ["96584.87000000", "0.23683000"], ["96584.86000000", "0.05182000"], ["96584.69000000", "0.20265000"], ["96584.59000000", "0.00000000"], ["96584.58000000", "0.00000000"], ["96584.41000000", "0.03107000"], ["96584.30000000", "0.00000000"], ["96584.06000000", "0.00000000"], ["96584.05000000", "0.00011000"], ["96584.03000000", "0.00000000"], ["96583.86000000", "0.00000000"], ["96583.85000000", "0.00000000"], ["96583.17000000", "0.21301000"], ["96583.16000000", "0.21301000"], ["96583.00000000", "0.00000000"], ["96582.95000000", "0.00000000"], ["96582.81000000", "0.07919000"], ["96582.46000000", "0.00000000"], ["96582.34000000", "0.00000000"], ["96582.33000000", "0.00000000"], ["96581.87000000", "0.00000000"], ["96581.61000000", "0.00011000"], ["96581.30000000", "0.00000000"], ["96581.24000000", "0.00000000"], ["96581.13000000", "0.00000000"], ["96580.13000000", "0.00000000"], ["96580.12000000", "1.05071000"], ["96580.09000000", "0.00000000"], ["96579.36000000", "0.21545000"], ["96579.21000000", "0.00000000"], ["96579.17000000", "0.00000000"], ["96579.12000000", "0.00000000"], ["96579.05000000", "0.07246000"], ["96578.96000000", "0.00560000"], ["96578.71000000", "0.00000000"], ["96578.35000000", "0.00000000"], ["96578.34000000", "0.02077000"], ["96578.20000000", "0.00999000"], ["96577.98000000", "0.00000000"], ["96576.24000000", "0.47624000"], ["96575.51000000", "0.00517000"], ["96575.46000000", "0.58800000"], ["96575.16000000", "1.10000000"], ["96574.35000000", "0.02301000"], ["96574.13000000", "0.02000000"], ["96574.07000000", "0.02588000"], ["96574.02000000", "0.00000000"], ["96573.89000000", "0.00900000"], ["96573.61000000", "0.00000000"], ["96573.51000000", "0.00000000"], ["96572.91000000", "0.00517000"], ["96572.55000000", "0.04800000"], ["96572.07000000", "0.00000000"], ["96571.86000000", "0.81867000"], ["96570.69000000", "0.00206000"], ["96569.99000000", "0.00000000"], ["96568.33000000", "0.04800000"], ["96568.23000000", "0.04800000"], ["96567.85000000", "0.00000000"], ["96565.53000000", "0.00000000"], ["96564.53000000", "0.00000000"], ["96563.91000000", "0.74535000"], ["96561.65000000", "0.74537000"], ["96561.34000000", "0.00000000"], ["96557.15000000", "0.77637000"], ["96556.37000000", "0.00000000"], ["96555.58000000", "0.00000000"], ["96555.53000000", "0.00000000"], ["96555.32000000", "0.00000000"], ["96554.51000000", "0.00000000"], ["96550.54000000", "0.00000000"], ["96550.53000000", "0.00000000"], ["96549.90000000", "0.77637000"], ["96549.72000000", "0.00000000"], ["96549.20000000", "0.03824000"], ["96548.94000000", "0.78447000"], ["96547.59000000", "0.77637000"], ["96547.57000000", "0.01619000"], ["96544.41000000", "0.77637000"], ["96543.61000000", "0.03895000"], ["96533.91000000", "0.00000000"], ["96529.49000000", "0.00792000"], ["96528.21000000", "0.00000000"], ["96519.75000000", "0.00000000"], ["96518.88000000", "0.00000000"], ["96515.01000000", "0.00000000"], ["96510.17000000", "0.00006000"], ["96507.18000000", "0.02000000"], ["96506.13000000", "0.04807000"], ["96503.24000000", "0.04800000"], ["96501.36000000", "0.04800000"], ["96488.76000000", "0.00000000"], ["96452.18000000", "0.02697000"], ["96346.65000000", "0.00000000"], ["96109.45000000", "0.00000000"], ["95720.70000000", "0.00016000"], ["95141.15000000", "0.00100000"], ["94737.69000000", "0.00076000"], ["86931.00000000", "0.00020000"], ["77272.00000000", "0.00050000"], ["70000.00000000", "183.65512000"], ["33000.00000000", "2.70627000"]], "a": [["96590.01000000", "1.44011000"], ["96590.20000000", "0.01022000"], ["96590.30000000", "0.00006000"], ["96590.67000000", "0.00000000"], ["96590.81000000", "0.00000000"], ["96590.82000000", "0.00000000"], ["96590.83000000", "0.00000000"], ["96590.96000000", "0.00000000"], ["96591.85000000", "0.00007000"], ["96591.95000000", "0.00045000"], ["96592.80000000", "0.00006000"], ["96592.86000000", "0.00000000"], ["96592.87000000", "0.00000000"], ["96592.90000000", "0.00000000"], ["96593.99000000", "0.00012000"], ["96594.39000000", "0.00012000"], ["96595.99000000", "0.00012000"], ["96596.48000000", "0.03524000"], ["96596.74000000", "0.00000000"], ["96598.00000000", "0.03796000"], ["96598.02000000", "0.00000000"], ["96598.03000000", "0.00000000"], ["96598.06000000", "0.00000000"], ["96598.51000000", "0.00000000"], ["96598.57000000", "0.00000000"], ["96599.21000000", "0.00000000"], ["96599.67000000", "0.00000000"], ["96599.99000000", "0.00000000"], ["96600.00000000", "0.03802000"], ["96600.46000000", "0.00092000"], ["96600.80000000", "0.04146000"], ["96600.96000000", "0.00095000"], ["96601.04000000", "0.00091000"], ["96601.55000000", "0.00000000"], ["96601.56000000", "0.00000000"], ["96601.57000000", "0.00000000"], ["96601.77000000", "0.00000000"], ["96601.78000000", "0.00000000"], ["96602.00000000", "0.03796000"], ["96602.18000000", "0.00000000"], ["96602.87000000", "0.00999000"], ["96603.20000000", "0.00000000"], ["96603.84000000", "0.00000000"], ["96604.04000000", "0.00006000"], ["96604.05000000", "0.68296000"], ["96604.60000000", "0.00000000"], ["96604.74000000", "0.00000000"], ["96606.20000000", "0.00000000"], ["96607.23000000", "0.00000000"], ["96607.60000000", "0.00000000"], ["96607.79000000", "0.00000000"], ["96608.36000000", "0.00000000"], ["96610.29000000", "0.00000000"], ["96611.28000000", "0.00000000"], ["96611.54000000", "0.00000000"], ["96611.55000000", "0.00000000"], ["96611.66000000", "0.00000000"], ["96611.76000000", "0.00000000"], ["96611.77000000", "0.00000000"], ["96611.99000000", "0.00000000"], ["96612.00000000", "0.00200000"], ["96612.27000000", "0.00000000"], ["96612.66000000", "1.15173000"], ["96612.87000000", "0.00000000"], ["96613.44000000", "0.00000000"], ["96613.45000000", "0.00000000"], ["96613.80000000", "0.00000000"], ["96613.88000000", "0.00000000"], ["96614.07000000", "0.31055000"], ["96614.22000000", "0.00000000"], ["96614.23000000", "0.00000000"], ["96614.45000000", "0.08160000"], ["96614.76000000", "0.00000000"], ["96615.18000000", "0.00310000"], ["96615.22000000", "0.00310000"], ["96615.38000000", "0.00000000"], ["96615.60000000", "0.00000000"], ["96615.76000000", "0.00000000"], ["96615.79000000", "0.00000000"], ["96616.97000000", "0.00000000"], ["96617.03000000", "0.00000000"], ["96617.04000000", "0.00000000"], ["96617.29000000", "0.00000000"], ["96617.92000000", "0.21301000"], ["96617.93000000", "1.03847000"], ["96617.94000000", "0.00000000"], ["96617.95000000", "0.77637000"], ["96617.97000000", "0.00000000"], ["96617.99000000", "0.00000000"], ["96618.97000000", "0.00517000"], ["96618.98000000", "0.10350000"], ["96619.12000000", "0.77637000"], ["96619.16000000", "0.00000000"], ["96619.57000000", "0.00010000"], ["96620.92000000", "0.00000000"], ["96621.95000000", "0.21301000"], ["96621.96000000", "1.28637000"], ["96622.07000000", "0.00000000"], ["96622.08000000", "0.00000000"], ["96623.82000000", "0.00000000"], ["96623.84000000", "0.21301000"], ["96624.61000000", "0.00000000"], ["96626.88000000", "0.21301000"], ["96626.89000000", "0.20257000"], ["96626.90000000", "0.00000000"], ["96627.66000000", "0.00000000"], ["96628.64000000", "0.05175000"], ["96630.92000000", "0.21301000"], ["96631.19000000", "0.00000000"], ["96631.20000000", "1.57069000"], ["96632.68000000", "0.21301000"], ["96632.93000000", "0.00000000"], ["96633.09000000", "1.68968000"], ["96633.80000000", "0.00000000"], ["96634.30000000", "0.00000000"], ["96634.35000000", "0.00000000"], ["96634.55000000", "0.00000000"], ["96636.72000000", "0.21301000"], ["96638.48000000", "0.21301000"], ["96639.14000000", "0.00000000"], ["96639.46000000", "0.74477000"], ["96642.52000000", "0.21301000"], ["96643.32000000", "0.00000000"], ["96643.84000000", "0.00000000"], ["96646.67000000", "0.00000000"], ["96647.50000000", "0.00000000"], ["96649.80000000", "0.02299000"], ["96652.72000000", "0.00000000"], ["96653.30000000", "0.00000000"], ["96654.93000000", "0.01630000"], ["96659.51000000", "0.00000000"], ["96660.78000000", "0.86336000"], ["96661.49000000", "0.10606000"], ["96662.81000000", "0.00000000"], ["96664.91000000", "0.02947000"], ["96675.37000000", "0.03531000"], ["98038.87000000", "0.00100000"]]}
{"e": "depthUpdate", "E": 1746123313014, "s": "BTCUSDT", "b": [["96590.00000000", "4.02894000"], ["96588.95000000", "0.00030000"], ["96588.94000000", "0.04949000"], ["96588.93000000", "0.00012000"], ["96588.01000000", "0.00012000"], ["96588.00000000", "0.08171000"], ["96587.11000000", "0.00000000"], ["96587.10000000", "0.00000000"], ["96586.37000000", "0.05055000"], ["96584.88000000", "0.00012000"], ["96584.87000000", "0.35883000"], ["96584.69000000", "0.20265000"], ["96583.18000000", "0.00000000"], ["96582.44000000", "0.44851000"], ["96580.13000000", "0.00517000"], ["96576.24000000", "0.00000000"], ["96575.32000000", "0.04800000"], ["96575.31000000", "0.04800000"], ["96575.16000000", "0.00000000"], ["96574.85000000", "0.04800000"], ["96571.87000000", "0.83000000"], ["96569.28000000", "0.00000000"], ["96566.76000000", "0.77637000"], ["96565.23000000", "0.00000000"], ["96562.22000000", "0.10279000"], ["96559.15000000", "0.00000000"], ["96557.67000000", "0.00000000"], ["96557.33000000", "0.74540000"], ["96549.90000000", "0.00000000"], ["96548.09000000", "0.10065000"], ["96547.60000000", "1.05309000"], ["96547.23000000", "0.05000000"], ["96546.45000000", "0.00000000"], ["96544.99000000", "0.00000000"], ["96510.78000000", "0.04800000"], ["96506.13000000", "0.00007000"], ["96503.24000000", "0.00000000"], ["96500.29000000", "0.00000000"], ["96489.82000000", "0.00000000"], ["96483.05000000", "0.00545000"], ["96482.72000000", "0.00000000"], ["96454.16000000", "2.69947000"], ["95624.11000000", "0.00016000"], ["95527.52000000", "0.00008000"], ["95430.93000000", "0.00008000"], ["95334.34000000", "0.00008000"], ["95141.15000000", "0.00000000"], ["86931.00000000", "0.00043000"], ["77272.00000000", "0.00050000"], ["33000.00000000", "2.70627000"]], "a": [["96590.01000000", "2.97280000"], ["96590.20000000", "0.01022000"], ["96590.30000000", "0.00006000"], ["96590.45000000", "0.00007000"], ["96591.26000000", "0.00000000"], ["96591.43000000", "0.00012000"], ["96591.44000000", "0.10885000"], ["96591.45000000", "0.19605000"], ["96591.83000000", "0.00000000"], ["96592.27000000", "0.00000000"], ["96593.99000000", "0.00000000"], ["96594.39000000", "0.00000000"], ["96595.99000000", "0.00000000"], ["96596.48000000", "0.03524000"], ["96597.22000000", "0.20264000"], ["96597.99000000", "0.30886000"], ["96598.00000000", "0.03790000"], ["96598.93000000", "0.00274000"], ["96599.67000000", "0.54000000"], ["96599.87000000", "0.21301000"], ["96600.00000000", "0.03796000"], ["96600.46000000", "0.00000000"], ["96600.64000000", "0.21301000"], ["96600.80000000", "0.04140000"], ["96600.96000000", "0.00000000"], ["96601.04000000", "0.00000000"], ["96601.70000000", "0.00013000"], ["96601.71000000", "0.02721000"], ["96601.72000000", "0.00000000"], ["96601.78000000", "0.67513000"], ["96601.79000000", "0.68297000"], ["96602.00000000", "0.03790000"], ["96603.06000000", "0.21301000"], ["96603.20000000", "0.00008000"], ["96603.99000000", "0.21301000"], ["96604.04000000", "0.00000000"], ["96604.05000000", "0.00000000"], ["96605.64000000", "0.50584000"], ["96606.07000000", "0.21301000"], ["96609.05000000", "0.51741000"], ["96609.06000000", "0.83567000"], ["96609.07000000", "0.21301000"], ["96609.32000000", "0.00000000"], ["96611.99000000", "1.68968000"], ["96612.00000000", "0.21501000"], ["96612.05000000", "0.21301000"], ["96612.65000000", "1.49722000"], ["96612.66000000", "0.00000000"], ["96612.87000000", "0.00008000"], ["96613.78000000", "0.00010000"], ["96614.09000000", "0.00828000"], ["96614.10000000", "0.01467000"], ["96614.99000000", "0.42602000"], ["96615.17000000", "0.00517000"], ["96615.73000000", "0.00000000"], ["96616.04000000", "0.00000000"], ["96616.05000000", "0.00000000"], ["96616.22000000", "0.17320000"], ["96617.04000000", "0.00000000"], ["96617.14000000", "0.10112000"], ["96617.90000000", "1.68968000"], ["96617.91000000", "0.21301000"], ["96617.92000000", "0.00000000"], ["96617.96000000", "0.00000000"], ["96618.24000000", "0.08160000"], ["96618.28000000", "0.00000000"], ["96618.97000000", "0.00000000"], ["96619.80000000", "0.00414000"], ["96619.95000000", "0.00000000"], ["96620.95000000", "0.01881000"], ["96621.35000000", "0.51741000"], ["96626.89000000", "0.66915000"], ["96627.13000000", "0.00011000"], ["96627.25000000", "1.68968000"], ["96634.19000000", "0.15999000"], ["96634.57000000", "1.63045000"], ["96635.52000000", "0.77637000"], ["96636.72000000", "0.00000000"], ["96636.73000000", "0.05000000"], ["96638.48000000", "0.00000000"], ["96639.93000000", "0.00000000"], ["96642.52000000", "0.00000000"], ["96645.57000000", "0.74472000"], ["96649.65000000", "0.00000000"], ["96700.00000000", "0.64256000"], ["98038.87000000", "0.00000000"]]}
{"e": "depthUpdate", "E": 1746124956015, "s": "BTCUSDT", "b": [["96666.41000000", "12.58211000"], ["96666.00000000", "0.03819000"], ["96665.75000000", "0.00006000"], ["96665.41000000", "0.00566000"], ["96665.22000000", "0.00006000"], ["96665.08000000", "0.00000000"], ["96661.22000000", "0.00000000"], ["96659.97000000", "0.00999000"], ["96659.68000000", "0.00006000"], ["96655.32000000", "0.00000000"], ["96650.95000000", "0.00013000"], ["96649.47000000", "0.00477000"], ["96647.31000000", "0.60789000"], ["96645.41000000", "0.00000000"], ["96644.35000000", "0.00000000"], ["96644.34000000", "0.00000000"], ["96642.86000000", "0.00000000"], ["96642.10000000", "1.79884000"], ["96632.70000000", "1.24025000"], ["96632.01000000", "0.00000000"], ["96631.33000000", "0.21301000"], ["96626.82000000", "0.00206000"], ["96621.63000000", "0.05000000"], ["96614.02000000", "0.00100000"], ["96614.01000000", "0.00100000"], ["96592.01000000", "0.00258000"], ["96585.49000000", "0.00000000"], ["96583.81000000", "0.02000000"], ["96580.03000000", "0.04800000"], ["96540.44000000", "0.00006000"], ["96528.76000000", "2.69752000"], ["96450.09000000", "0.00188000"], ["96443.50000000", "0.00016000"], ["91833.09000000", "0.00010000"], ["86999.77000000", "0.00000000"], ["86999.00000000", "0.01065000"], ["77333.13000000", "0.00050000"], ["70000.00000000", "183.65395000"], ["42000.00000000", "3.70661000"], ["33000.00000000", "2.70627000"]], "a": [["96666.42000000", "0.82820000"], ["96666.91000000", "0.00006000"], ["96667.16000000", "0.00000000"], ["96667.19000000", "0.00013000"], ["96669.29000000", "0.10522000"], ["96669.30000000", "0.00000000"], ["96673.89000000", "0.00006000"], ["96673.90000000", "0.45467000"], ["96674.04000000", "0.21307000"], ["96674.24000000", "0.02720000"], ["96677.99000000", "0.00013000"], ["96678.73000000", "0.00013000"], ["96683.58000000", "0.00999000"], ["96684.98000000", "0.00000000"], ["96686.26000000", "0.00000000"], ["96686.38000000", "0.00310000"], ["96686.39000000", "0.00000000"], ["96690.09000000", "0.00000000"], ["96694.35000000", "0.62038000"], ["96695.33000000", "1.10000000"], ["96698.88000000", "0.00000000"], ["96701.61000000", "1.57329000"], ["96703.75000000", "1.60631000"], ["96703.98000000", "0.00000000"], ["96704.00000000", "0.00211000"], ["96709.83000000", "0.00000000"], ["96720.20000000", "0.00000000"], ["96762.99000000", "0.02000000"], ["96763.96000000", "0.00000000"], ["96766.85000000", "0.09600000"], ["96798.56000000", "0.04997000"], ["96871.56000000", "0.00000000"], ["97411.44000000", "0.05175000"]]}
{"e": "depthUpdate", "E": 1746124957014, "s": "BTCUSDT", "b": [["96666.41000000", "12.58099000"], ["96665.75000000", "0.00006000"], ["96665.44000000", "0.00109000"], ["96665.41000000", "0.00566000"], ["96665.22000000", "0.00000000"], ["96663.65000000", "0.86950000"], ["96659.97000000", "0.00000000"], ["96658.73000000", "0.00999000"], ["96655.25000000", "0.00000000"], ["96637.41000000", "0.41368000"], ["96635.41000000", "0.04800000"], ["96632.51000000", "0.04800000"], ["96631.33000000", "0.21301000"], ["96621.64000000", "0.36394000"], ["96580.03000000", "0.00000000"], ["96434.96000000", "0.00548000"], ["96431.54000000", "0.00000000"], ["95699.74000000", "0.00000000"], ["95454.36000000", "0.00144000"], ["94737.69000000", "0.00006000"], ["88933.10000000", "0.00000000"], ["86999.77000000", "0.00000000"], ["86999.00000000", "0.01065000"], ["77333.13000000", "0.00050000"], ["33000.00000000", "2.70627000"]], "a": [["96666.42000000", "1.01050000"], ["96666.45000000", "0.00020000"], ["96666.55000000", "0.00013000"], ["96666.59000000", "0.00905000"], ["96666.85000000", "0.00000000"], ["96666.91000000", "0.00006000"], ["96667.19000000", "0.00000000"], ["96667.62000000", "0.00018000"], ["96668.27000000", "0.00007000"], ["96678.48000000", "0.00013000"], ["96678.49000000", "0.68243000"], ["96678.73000000", "0.00000000"], ["96679.00000000", "0.00103000"], ["96680.41000000", "0.00000000"], ["96682.48000000", "0.00999000"], ["96683.58000000", "0.00000000"], ["96686.37000000", "0.00310000"], ["96686.38000000", "0.00000000"], ["96693.11000000", "0.03999000"], ["96697.05000000", "0.77566000"], ["96711.82000000", "0.42385000"]]}
{"e": "depthUpdate", "E": 1746124958014, "s": "BTCUSDT", "b": [["96666.41000000", "6.43260000"], ["96666.40000000", "0.00066000"], ["96666.39000000", "0.00006000"], ["96666.02000000", "0.00018000"], ["96666.01000000", "0.05373000"], ["96666.00000000", "0.03819000"], ["96665.41000000", "0.00560000"], ["96665.35000000", "0.00012000"], ["96665.34000000", "0.02445000"], ["96665.17000000", "0.00000000"], ["96664.81000000", "0.00012000"], ["96664.01000000", "0.00000000"], ["96664.00000000", "0.03802000"], ["96663.68000000", "0.00000000"], ["96663.67000000", "0.00000000"], ["96663.66000000", "0.05012000"], ["96663.65000000", "0.00202000"], ["96662.00000000", "0.03796000"], ["96661.91000000", "0.00000000"], ["96661.80000000", "0.00006000"], ["96661.79000000", "0.21307000"], ["96661.66000000", "0.00000000"], ["96661.19000000", "0.00000000"], ["96660.78000000", "0.00000000"], ["96660.41000000", "0.32286000"], ["96660.36000000", "0.00000000"], ["96660.10000000", "0.00372000"], ["96660.00000000", "0.03796000"], ["96659.94000000", "0.64478000"], ["96659.12000000", "0.00000000"], ["96658.88000000", "0.21301000"], ["96658.73000000", "0.00000000"], ["96657.59000000", "0.00000000"], ["96656.69000000", "0.19224000"], ["96656.67000000", "0.00000000"], ["96656.36000000", "0.00000000"], ["96656.01000000", "0.00000000"], ["96654.60000000", "0.00000000"], ["96654.59000000", "0.00000000"], ["96653.61000000", "0.31026000"], ["96653.38000000", "0.00000000"], ["96652.82000000", "0.00000000"], ["96652.81000000", "0.43841000"], ["96652.70000000", "0.21301000"], ["96652.09000000", "0.46837000"], ["96650.69000000", "0.00999000"], ["96650.67000000", "0.00000000"], ["96650.48000000", "0.00000000"], ["96650.20000000", "0.00517000"], ["96650.01000000", "0.00000000"], ["96650.00000000", "0.00000000"], ["96648.86000000", "0.00000000"], ["96648.42000000", "0.00000000"], ["96647.60000000", "0.00000000"], ["96647.31000000", "1.01559000"], ["96646.56000000", "0.00000000"], ["96646.52000000", "0.52410000"], ["96645.73000000", "0.00000000"], ["96644.50000000", "0.00000000"], ["96643.72000000", "0.00000000"], ["96643.63000000", "0.00000000"], ["96643.17000000", "0.00000000"], ["96643.02000000", "0.00000000"], ["96642.60000000", "0.62045000"], ["96642.17000000", "0.00000000"], ["96641.90000000", "0.06441000"], ["96641.49000000", "0.00000000"], ["96641.14000000", "0.00560000"], ["96639.95000000", "0.00000000"], ["96638.87000000", "0.00000000"], ["96638.39000000", "0.00000000"], ["96638.35000000", "0.00000000"], ["96637.90000000", "0.74478000"], ["96636.99000000", "0.09981000"], ["96636.93000000", "0.03999000"], ["96636.55000000", "0.00000000"], ["96636.09000000", "0.00839000"], ["96635.87000000", "0.00000000"], ["96635.14000000", "0.00000000"], ["96634.85000000", "1.00000000"], ["96633.55000000", "0.00000000"], ["96633.23000000", "0.00000000"], ["96632.70000000", "0.28923000"], ["96632.54000000", "0.00767000"], ["96631.49000000", "0.01534000"], ["96631.33000000", "0.00000000"], ["96631.31000000", "0.00000000"], ["96631.26000000", "0.00839000"], ["96626.81000000", "0.00000000"], ["96625.05000000", "0.00000000"], ["96623.62000000", "0.00000000"], ["96621.64000000", "0.36394000"], ["96621.63000000", "0.00000000"], ["96620.85000000", "0.00000000"], ["96619.93000000", "0.00000000"], ["96617.93000000", "0.00000000"], ["96614.32000000", "0.00000000"], ["96613.49000000", "0.00000000"], ["96611.33000000", "0.00000000"], ["96610.94000000", "0.00000000"], ["96610.29000000", "0.00000000"], ["96610.07000000", "0.00000000"], ["96606.69000000", "2.00000000"], ["96599.06000000", "0.00000000"], ["96599.01000000", "0.03785000"], ["96598.95000000", "0.51710000"], ["96598.19000000", "0.41368000"], ["96588.63000000", "0.00000000"], ["96584.81000000", "0.03693000"], ["96582.92000000", "0.00000000"], ["96581.87000000", "0.24952000"], ["96580.04000000", "0.10492000"], ["96579.26000000", "0.20988000"], ["96578.84000000", "0.09094000"], ["96578.06000000", "0.08731000"], ["96577.51000000", "0.00000000"], ["96575.76000000", "0.00000000"], ["96548.26000000", "0.16536000"], ["96528.76000000", "0.00000000"], ["96525.55000000", "0.00000000"], ["96343.76000000", "0.33876000"], ["96334.10000000", "0.03177000"], ["86999.77000000", "0.00000000"], ["86999.00000000", "0.01065000"], ["77333.13000000", "0.00050000"], ["70000.00000000", "183.65395000"], ["42000.00000000", "3.70561000"], ["33000.00000000", "2.70627000"]], "a": [["96666.42000000", "5.14456000"], ["96666.43000000", "0.00255000"], ["96666.58000000", "0.00018000"], ["96667.63000000", "0.04563000"], ["96668.67000000", "0.00050000"], ["96668.68000000", "0.00000000"], ["96668.69000000", "0.00000000"], ["96669.28000000", "0.00000000"], ["96669.29000000", "0.00000000"], ["96669.36000000", "0.00012000"], ["96669.37000000", "0.07925000"], ["96670.36000000", "0.00000000"], ["96670.37000000", "0.00000000"], ["96670.55000000", "0.00000000"], ["96670.96000000", "0.00000000"], ["96671.08000000", "0.00012000"], ["96671.09000000", "0.10735000"], ["96671.10000000", "0.21307000"], ["96671.19000000", "0.00000000"], ["96671.20000000", "0.04146000"], ["96672.00000000", "0.03796000"], ["96672.22000000", "0.68254000"], ["96672.30000000", "0.00000000"], ["96672.75000000", "0.06447000"], ["96672.79000000", "0.00000000"], ["96672.80000000", "0.00000000"], ["96672.89000000", "0.04036000"], ["96673.06000000", "0.01880000"], ["96673.07000000", "0.00414000"], ["96673.78000000", "0.00000000"], ["96673.89000000", "0.00000000"], ["96673.90000000", "0.95274000"], ["96674.00000000", "0.03790000"], ["96674.04000000", "0.21301000"], ["96674.24000000", "0.00000000"], ["96674.54000000", "1.68968000"], ["96674.90000000", "0.00000000"], ["96674.92000000", "0.00000000"], ["96675.29000000", "0.48920000"], ["96676.19000000", "0.00000000"], ["96676.56000000", "0.00000000"], ["96677.29000000", "0.07919000"], ["96677.34000000", "0.00000000"], ["96678.49000000", "0.00000000"], ["96679.76000000", "0.00000000"], ["96680.24000000", "0.00000000"], ["96680.76000000", "0.21301000"], ["96681.10000000", "0.00000000"], ["96681.49000000", "0.00000000"], ["96682.48000000", "0.00000000"], ["96683.62000000", "0.62459000"], ["96685.05000000", "0.00516000"], ["96685.16000000", "0.00000000"], ["96686.05000000", "0.00310000"], ["96686.08000000", "0.00310000"], ["96686.09000000", "0.00000000"], ["96686.11000000", "0.00000000"], ["96686.12000000", "0.00000000"], ["96686.15000000", "0.00000000"], ["96686.37000000", "0.00000000"], ["96688.78000000", "0.10181000"], ["96688.91000000", "1.00000000"], ["96689.05000000", "0.00000000"], ["96690.61000000", "0.00000000"], ["96692.41000000", "0.00000000"], ["96692.89000000", "0.00011000"], ["96693.11000000", "0.00000000"], ["96693.20000000", "1.75630000"], ["96694.01000000", "0.00000000"], ["96694.35000000", "0.00000000"], ["96694.59000000", "0.74435000"], ["96695.59000000", "0.00000000"], ["96695.89000000", "0.00000000"], ["96696.19000000", "0.00000000"], ["96697.19000000", "0.07919000"], ["96697.65000000", "0.00000000"], ["96698.92000000", "0.74431000"], ["96699.48000000", "0.05000000"], ["96699.75000000", "0.00000000"], ["96703.45000000", "0.00000000"], ["96704.01000000", "0.00000000"], ["96705.08000000", "0.00000000"], ["96705.33000000", "0.10416000"], ["96705.57000000", "0.00000000"], ["96711.53000000", "0.03641000"], ["96711.82000000", "0.42385000"], ["96712.74000000", "0.00000000"], ["96713.04000000", "0.00000000"], ["96714.80000000", "2.00000000"], ["96717.05000000", "0.00000000"], ["96717.29000000", "0.00000000"], ["96718.40000000", "0.00000000"], ["96719.23000000", "0.03734000"], ["96719.36000000", "0.00000000"], ["96721.60000000", "0.10250000"], ["96725.36000000", "0.04996000"], ["96725.96000000", "0.00000000"], ["96726.00000000", "0.86373000"], ["96727.96000000", "0.00000000"], ["96728.88000000", "0.00000000"], ["96731.23000000", "0.00000000"], ["96733.08000000", "0.00000000"], ["96738.79000000", "0.00000000"], ["96740.48000000", "0.00000000"], ["96741.60000000", "0.00000000"], ["96741.90000000", "0.42837000"], ["96743.74000000", "0.00000000"], ["96744.72000000", "0.00000000"], ["96946.54000000", "0.00000000"], ["97372.80000000", "0.05175000"], ["97411.44000000", "0.00000000"], ["97873.35000000", "0.05118000"]]}
{"e": "depthUpdate", "E": 1746124959014, "s": "BTCUSDT", "b": [["96666.41000000", "5.91837000"], ["96666.40000000", "0.00078000"], ["96665.44000000", "0.00006000"], ["96664.80000000", "0.04152000"], ["96664.61000000", "0.00000000"], ["96664.49000000", "0.00000000"], ["96663.66000000", "0.05012000"], ["96662.90000000", "0.02300000"], ["96662.50000000", "0.00006000"], ["96662.49000000", "0.22249000"], ["96662.48000000", "0.21307000"], ["96662.42000000", "0.00000000"], ["96662.07000000", "0.19948000"], ["96662.00000000", "0.03790000"], ["96661.80000000", "0.00000000"], ["96661.79000000", "0.00000000"], ["96661.50000000", "0.00103000"], ["96660.42000000", "0.00032000"], ["96660.41000000", "0.00000000"], ["96660.00000000", "0.03796000"], ["96659.94000000", "0.06478000"], ["96659.33000000", "0.00000000"], ["96658.16000000", "0.02116000"], ["96657.46000000", "0.12000000"], ["96656.95000000", "0.74982000"], ["96656.94000000", "0.53158000"], ["96656.75000000", "0.00000000"], ["96656.74000000", "0.54517000"], ["96656.69000000", "0.00000000"], ["96655.34000000", "0.00000000"], ["96654.30000000", "0.04000000"], ["96653.08000000", "0.00000000"], ["96652.81000000", "0.40719000"], ["96652.09000000", "0.00000000"], ["96650.74000000", "0.00000000"], ["96650.69000000", "0.00000000"], ["96649.08000000", "0.00999000"], ["96647.31000000", "0.60789000"], ["96646.38000000", "0.28742000"], ["96642.60000000", "0.00000000"], ["96642.59000000", "2.04669000"], ["96642.58000000", "0.00000000"], ["96642.23000000", "1.68968000"], ["96641.15000000", "1.00000000"], ["96639.85000000", "0.00000000"], ["96639.59000000", "0.00000000"], ["96638.15000000", "0.00000000"], ["96638.02000000", "0.77566000"], ["96637.91000000", "0.62048000"], ["96636.09000000", "0.00014000"], ["96634.85000000", "0.00000000"], ["96631.26000000", "0.00014000"], ["96626.82000000", "0.00000000"], ["96626.81000000", "0.21301000"], ["96622.50000000", "0.00206000"], ["96616.94000000", "0.05000000"], ["96615.89000000", "2.00000000"], ["96613.68000000", "0.57936000"], ["96613.29000000", "0.00000000"], ["96612.77000000", "0.00000000"], ["96609.89000000", "0.00000000"], ["96609.63000000", "0.00000000"], ["96606.69000000", "0.00000000"], ["96603.29000000", "0.00000000"], ["86999.77000000", "0.00000000"], ["86999.00000000", "0.01065000"], ["77333.13000000", "0.00050000"], ["34799.91000000", "0.00072000"], ["33000.00000000", "2.70627000"], ["20002.00000000", "0.00000000"]], "a": [["96666.42000000", "5.34942000"], ["96666.43000000", "0.00231000"], ["96666.55000000", "0.00013000"], ["96666.57000000", "0.00006000"], ["96666.58000000", "0.00012000"], ["96666.59000000", "0.00006000"], ["96667.62000000", "0.00012000"], ["96667.63000000", "0.04563000"], ["96667.78000000", "0.00000000"], ["96667.79000000", "0.00000000"], ["96668.77000000", "0.00000000"], ["96668.78000000", "0.00006000"], ["96668.96000000", "0.00000000"], ["96669.37000000", "0.07925000"], ["96670.64000000", "0.00000000"], ["96671.08000000", "0.00012000"], ["96671.09000000", "0.10735000"], ["96671.20000000", "0.04146000"], ["96671.35000000", "0.02300000"], ["96672.00000000", "0.03796000"], ["96672.22000000", "0.00000000"], ["96672.63000000", "0.00485000"], ["96672.75000000", "0.06447000"], ["96672.89000000", "0.04036000"], ["96673.06000000", "0.00000000"], ["96673.07000000", "0.00000000"], ["96673.10000000", "0.00103000"], ["96673.16000000", "0.00999000"], ["96673.89000000", "0.00006000"], ["96674.14000000", "0.68246000"], ["96677.33000000", "0.00095000"], ["96678.23000000", "0.00410000"], ["96679.00000000", "0.00000000"], ["96679.07000000", "0.04000000"], ["96680.76000000", "0.21301000"], ["96682.47000000", "0.00000000"], ["96683.04000000", "0.00000000"], ["96683.38000000", "0.00310000"], ["96683.42000000", "0.00000000"], ["96683.62000000", "0.00000000"], ["96683.63000000", "0.00000000"], ["96683.70000000", "0.00000000"], ["96683.79000000", "0.03999000"], ["96684.33000000", "0.00000000"], ["96685.01000000", "0.00000000"], ["96685.54000000", "0.00000000"], ["96685.95000000", "0.00000000"], ["96686.05000000", "0.00000000"], ["96686.08000000", "0.00000000"], ["96686.72000000", "0.62043000"], ["96686.87000000", "0.09562000"], ["96688.91000000", "0.00000000"], ["96689.27000000", "0.00000000"], ["96692.21000000", "0.00000000"], ["96693.91000000", "0.00000000"], ["96695.21000000", "0.00000000"], ["96695.33000000", "0.00000000"], ["96695.42000000", "0.09776000"], ["96695.73000000", "0.00000000"], ["96696.25000000", "1.00000000"], ["96697.81000000", "0.00000000"], ["96698.88000000", "0.00772000"], ["96711.40000000", "0.00000000"], ["96711.82000000", "0.18070000"], ["96714.80000000", "0.00000000"], ["96718.00000000", "0.00000000"], ["96721.40000000", "0.00000000"], ["96724.00000000", "0.00200000"], ["96725.04000000", "0.00000000"], ["96726.00000000", "1.45571000"], ["96726.08000000", "2.00000000"], ["96729.20000000", "0.00000000"]]}
{"e": "depthUpdate", "E": 1746124960014, "s": "BTCUSDT", "b": [["96666.41000000", "5.90755000"], ["96654.15000000", "0.31997000"], ["96646.38000000", "0.00000000"], ["96632.70000000", "0.59708000"], ["96616.87000000", "0.00000000"], ["96598.96000000", "0.44871000"], ["96597.80000000", "0.00000000"], ["96320.47000000", "0.00000000"], ["95796.41000000", "0.00016000"], ["95699.75000000", "0.00008000"], ["94759.63000000", "0.00000000"], ["94726.64000000", "0.00007000"], ["89054.68000000", "0.00000000"], ["86999.77000000", "0.00000000"], ["86999.00000000", "0.01065000"], ["85344.07000000", "0.00000000"], ["81633.46000000", "0.00000000"], ["77922.85000000", "0.00000000"], ["77333.13000000", "0.00050000"], ["74212.24000000", "0.00000000"], ["70501.63000000", "0.00000000"], ["70000.00000000", "183.65395000"], ["66791.01000000", "0.00000000"], ["63080.40000000", "0.00000000"], ["59369.79000000", "0.00000000"], ["34799.91000000", "0.00090000"], ["33000.00000000", "2.70627000"]], "a": [["96666.42000000", "5.24331000"], ["96669.37000000", "0.07925000"], ["96670.17000000", "0.02806000"], ["96672.89000000", "0.04030000"], ["96673.16000000", "0.00000000"], ["96674.31000000", "0.00999000"], ["96693.20000000", "1.28816000"], ["96695.13000000", "1.00000000"], ["96696.25000000", "0.00000000"], ["96697.73000000", "0.00000000"], ["96706.98000000", "0.00000000"], ["96723.84000000", "2.00000000"], ["96726.08000000", "0.00000000"], ["96729.04000000", "0.00000000"]]}
{"e": "depthUpdate", "E": 1746124961014, "s": "BTCUSDT", "b": [["96666.41000000", "5.90590000"], ["96660.11000000", "0.00107000"], ["96654.15000000", "0.00007000"], ["96650.10000000", "0.00999000"], ["96649.08000000", "0.00000000"], ["96641.15000000", "0.00000000"], ["96641.07000000", "1.00000000"], ["96640.55000000", "0.00000000"], ["96639.51000000", "0.00000000"], ["96638.99000000", "0.00000000"], ["96637.94000000", "0.00000000"], ["96636.60000000", "0.00006000"], ["96618.99000000", "0.00000000"], ["96616.62000000", "0.00103000"], ["96615.89000000", "0.00000000"], ["96615.73000000", "2.00000000"], ["96614.69000000", "0.00000000"], ["96612.61000000", "0.00000000"], ["96611.57000000", "0.00000000"], ["96609.47000000", "0.00000000"], ["96602.65000000", "0.03500000"], ["96594.39000000", "0.00000000"], ["96524.02000000", "0.01778000"], ["96508.40000000", "0.00000000"], ["96435.74000000", "0.00548000"], ["96434.96000000", "0.00000000"], ["95699.75000000", "0.00016000"], ["95603.08000000", "0.00008000"], ["95522.12000000", "0.00000000"], ["95506.41000000", "0.00008000"], ["95426.01000000", "0.04105000"], ["95409.75000000", "0.00008000"], ["95313.08000000", "0.00008000"], ["86999.77000000", "0.00000000"], ["86999.00000000", "0.01065000"], ["77333.13000000", "0.00050000"], ["60000.00000000", "80.85283000"], ["33000.00000000", "2.70627000"]], "a": [["96666.42000000", "5.24373000"], ["96666.43000000", "0.00249000"], ["96671.09000000", "0.28617000"], ["96672.00000000", "0.03796000"], ["96672.12000000", "0.00000000"], ["96672.13000000", "0.68254000"], ["96672.75000000", "0.06441000"], ["96673.89000000", "0.00000000"], ["96674.14000000", "0.00000000"], ["96680.76000000", "0.21301000"], ["96683.37000000", "0.00310000"], ["96683.38000000", "0.00000000"], ["96695.13000000", "1.00000000"], ["96697.21000000", "0.00000000"], ["96713.29000000", "0.00103000"], ["96722.44000000", "1.08178000"], ["96723.84000000", "2.00000000"], ["96726.00000000", "0.86373000"], ["96728.00000000", "0.00200000"], ["96769.21000000", "0.05396000"], ["96794.43000000", "0.04997000"], ["97099.00000000", "0.00412000"]]}
{"e": "depthUpdate", "E": 1746124962014, "s": "BTCUSDT", "b": [["96650.27000000", "0.00000000"], ["96642.10000000", "0.14443000"], ["96638.16000000", "3.32143000"], ["96638.15000000", "1.69091000"], ["96638.04000000", "0.00000000"], ["96614.02000000", "0.00000000"], ["96614.01000000", "0.00000000"], ["96602.65000000", "0.00000000"], ["96602.55000000", "0.00000000"], ["96602.53000000", "0.00000000"], ["96602.40000000", "0.00000000"], ["96602.07000000", "0.00000000"], ["96601.95000000", "0.03500000"], ["96571.34000000", "0.01617000"], ["96522.38000000", "2.69734000"], ["95506.41000000", "0.00068000"], ["95426.01000000", "0.00000000"], ["95216.41000000", "0.00008000"], ["95119.75000000", "0.00008000"], ["95023.08000000", "0.00008000"], ["94926.41000000", "0.00008000"], ["88933.10000000", "0.00012000"], ["86999.77000000", "0.00000000"], ["86999.00000000", "0.01065000"], ["77333.13000000", "0.00050000"], ["70000.00000000", "183.65395000"], ["60000.00000000", "80.85273000"], ["34799.91000000", "0.00126000"], ["33000.00000000", "2.70627000"]], "a": [["96666.42000000", "5.44547000"], ["96674.31000000", "0.00000000"], ["96675.31000000", "0.00999000"], ["96677.33000000", "0.00000000"], ["96695.13000000", "0.00000000"], ["96695.17000000", "1.00000000"], ["96697.25000000", "0.00000000"], ["96700.23000000", "1.61203000"], ["96703.75000000", "0.00000000"], ["96720.65000000", "0.01617000"], ["96723.84000000", "0.00000000"], ["96723.92000000", "2.00000000"], ["96728.08000000", "0.00000000"], ["97633.07000000", "0.00000000"]]}
{"e": "depthUpdate", "E": 1746124963014, "s": "BTCUSDT", "b": [["96666.41000000", "2.93664000"], ["96664.56000000", "0.00007000"], ["96662.49000000", "0.22249000"], ["96662.48000000", "0.00000000"], ["96662.07000000", "0.19954000"], ["96660.11000000", "0.00117000"], ["96659.94000000", "0.00000000"], ["96655.28000000", "0.00417000"], ["96654.15000000", "0.28945000"], ["96652.81000000", "0.20173000"], ["96651.11000000", "0.01010000"], ["96650.10000000", "0.00000000"], ["96648.87000000", "0.00000000"], ["96642.59000000", "1.40221000"], ["96641.07000000", "0.00000000"], ["96637.75000000", "0.00000000"], ["96637.55000000", "0.00000000"], ["96636.99000000", "0.00000000"], ["96636.09000000", "0.00000000"], ["96635.85000000", "1.00000000"], ["96634.64000000", "0.74481000"], ["96633.15000000", "0.10144000"], ["96631.26000000", "0.00000000"], ["96626.81000000", "0.21301000"], ["96618.99000000", "0.00000000"], ["96616.94000000", "0.00000000"], ["96615.73000000", "0.00000000"], ["96610.95000000", "0.05000000"], ["96609.09000000", "1.05047000"], ["96608.69000000", "0.00000000"], ["96605.29000000", "2.00000000"], ["96571.34000000", "0.00000000"], ["94829.75000000", "0.00008000"], ["94733.08000000", "0.00008000"], ["94636.42000000", "0.00008000"], ["88933.10000000", "0.00000000"], ["86999.77000000", "0.00000000"], ["86999.00000000", "0.01065000"], ["77333.13000000", "0.00050000"], ["33000.00000000", "2.70627000"]], "a": [["96666.42000000", "5.07731000"], ["96666.43000000", "0.00243000"], ["96669.37000000", "0.07925000"], ["96669.56000000", "0.02300000"], ["96669.98000000", "0.00012000"], ["96669.99000000", "0.30815000"], ["96670.00000000", "0.68255000"], ["96670.17000000", "0.02806000"], ["96671.08000000", "0.00000000"], ["96671.09000000", "0.00000000"], ["96672.00000000", "0.03790000"], ["96672.13000000", "0.00000000"], ["96678.23000000", "0.00000000"], ["96680.76000000", "0.21301000"], ["96682.89000000", "0.00310000"], ["96682.90000000", "0.00310000"], ["96683.09000000", "0.00310000"], ["96683.13000000", "0.00310000"], ["96683.37000000", "0.00000000"], ["96684.94000000", "0.10151000"], ["96688.78000000", "0.00000000"], ["96689.87000000", "1.00000000"], ["96691.57000000", "0.00000000"], ["96691.77000000", "0.00000000"], ["96695.17000000", "0.00000000"], ["96713.32000000", "2.00000000"], ["96716.72000000", "0.00000000"], ["96717.12000000", "0.00000000"], ["96720.61000000", "0.01551000"], ["96720.65000000", "0.00000000"], ["96722.44000000", "0.68285000"], ["96723.92000000", "0.00000000"], ["96725.44000000", "0.01034000"], ["96725.51000000", "0.00000000"], ["96730.35000000", "0.00000000"], ["96762.04000000", "0.01617000"], ["96786.35000000", "0.00000000"], ["96797.82000000", "0.15924000"], ["96817.49000000", "0.00000000"], ["96818.66000000", "0.00000000"], ["96820.37000000", "0.00000000"], ["96821.76000000", "0.00000000"], ["96860.00000000", "0.00331000"], ["115635.75000000", "0.00000000"], ["121399.05000000", "0.00000000"]]}
{"e": "depthUpdate", "E": 1746124964014, "s": "BTCUSDT", "b": [["96666.41000000", "2.96775000"], ["96666.40000000", "0.00090000"], ["96666.02000000", "0.00006000"], ["96666.01000000", "0.00024000"], ["96665.34000000", "0.02445000"], ["96664.98000000", "0.00012000"], ["96664.97000000", "0.12123000"], ["96664.96000000", "0.24832000"], ["96664.81000000", "0.00000000"], ["96663.66000000", "0.05006000"], ["96662.90000000", "0.02300000"], ["96662.50000000", "0.00000000"], ["96662.49000000", "0.00000000"], ["96662.08000000", "0.26313000"], ["96662.07000000", "0.19948000"], ["96662.00000000", "0.03790000"], ["96661.98000000", "0.21301000"], ["96658.77000000", "0.03105000"], ["96656.96000000", "0.51741000"], ["96656.95000000", "0.68311000"], ["96655.28000000", "0.00000000"], ["96654.15000000", "0.00007000"], ["96648.32000000", "0.00000000"], ["96640.92000000", "0.00000000"], ["96640.75000000", "0.00000000"], ["96640.62000000", "0.00000000"], ["96639.02000000", "1.00000000"], ["96638.95000000", "0.00000000"], ["96637.55000000", "0.00000000"], ["96637.25000000", "0.00000000"], ["96635.95000000", "0.00000000"], ["96635.85000000", "0.00000000"], ["96635.55000000", "0.00000000"], ["96633.15000000", "0.00000000"], ["96632.19000000", "0.00828000"], ["96630.13000000", "0.10163000"], ["96627.36000000", "0.00828000"], ["96618.99000000", "0.86894000"], ["96615.43000000", "0.00000000"], ["96615.09000000", "0.00000000"], ["96614.83000000", "0.00000000"], ["96611.63000000", "2.00000000"], ["96611.49000000", "0.00000000"], ["96610.95000000", "0.00000000"], ["96608.69000000", "0.00000000"], ["96608.09000000", "0.00000000"], ["96605.49000000", "0.00000000"], ["96605.29000000", "0.00000000"], ["96604.69000000", "0.00000000"], ["96400.01000000", "0.00103000"], ["94737.69000000", "0.00076000"], ["86999.77000000", "0.00000000"], ["86999.00000000", "0.01065000"], ["81333.00000000", "0.13380000"], ["77333.13000000", "0.00050000"], ["70000.00000000", "183.65395000"], ["33000.00000000", "2.70627000"]], "a": [["96666.42000000", "4.96341000"], ["96666.43000000", "0.00261000"], ["96669.37000000", "0.07925000"], ["96669.56000000", "0.00000000"], ["96669.65000000", "0.02300000"], ["96670.00000000", "0.68255000"], ["96670.17000000", "0.00000000"], ["96671.20000000", "0.04146000"], ["96671.35000000", "0.00000000"], ["96672.00000000", "0.03796000"], ["96672.75000000", "0.06447000"], ["96672.89000000", "0.04030000"], ["96680.76000000", "0.21301000"], ["96682.20000000", "0.10294000"], ["96682.76000000", "0.00310000"], ["96682.86000000", "0.00000000"], ["96682.89000000", "0.00000000"], ["96682.90000000", "0.00000000"], ["96683.09000000", "0.00000000"], ["96683.13000000", "0.00000000"], ["96684.94000000", "0.00000000"], ["96689.57000000", "0.00000000"], ["96689.87000000", "0.00000000"], ["96689.97000000", "0.00000000"], ["96690.39000000", "0.74438000"], ["96691.27000000", "0.00000000"], ["96691.57000000", "0.00000000"], ["96692.97000000", "0.00000000"], ["96693.04000000", "0.00000000"], ["96694.57000000", "0.00000000"], ["96694.64000000", "0.00011000"], ["96694.67000000", "0.00000000"], ["96694.94000000", "0.00000000"], ["96695.69000000", "0.00000000"], ["96696.21000000", "0.00000000"], ["96696.80000000", "0.04140000"], ["96697.77000000", "0.00000000"], ["96698.37000000", "1.00000000"], ["96700.68000000", "0.05197000"], ["96701.30000000", "0.10394000"], ["96707.09000000", "0.00000000"], ["96709.58000000", "0.04997000"], ["96711.42000000", "0.04997000"], ["96711.82000000", "0.18070000"], ["96712.72000000", "0.00000000"], ["96713.32000000", "0.00000000"], ["96713.52000000", "0.00000000"], ["96715.64000000", "0.04997000"], ["96716.12000000", "0.00000000"], ["96716.72000000", "0.00000000"], ["96719.52000000", "0.00000000"], ["96719.66000000", "0.00000000"], ["96722.72000000", "0.00000000"], ["96722.86000000", "0.00000000"], ["96722.92000000", "0.00000000"], ["96723.46000000", "0.00000000"], ["96724.96000000", "0.00000000"], ["96726.00000000", "0.86373000"], ["96727.18000000", "0.00000000"], ["96729.12000000", "0.00000000"], ["96730.32000000", "2.00000000"], ["96762.04000000", "0.00000000"], ["96774.89000000", "0.04997000"], ["96802.90000000", "1.33332000"], ["96809.72000000", "0.00000000"], ["96810.64000000", "0.00000000"], ["96814.21000000", "0.00000000"]]}
{"e": "depthUpdate", "E": 1746124965014, "s": "BTCUSDT", "b": [["96666.41000000", "3.22755000"], ["96662.08000000", "0.27058000"], ["96656.98000000", "0.97278000"], ["96656.97000000", "0.00000000"], ["96656.95000000", "0.00000000"], ["96654.15000000", "0.29538000"], ["96641.22000000", "1.00000000"], ["96639.02000000", "0.00000000"], ["96616.03000000", "2.00000000"], ["96613.68000000", "0.57936000"], ["96611.63000000", "0.00000000"], ["86999.77000000", "0.00000000"], ["86999.00000000", "0.01065000"], ["77333.13000000", "0.00050000"], ["33000.00000000", "2.70627000"], ["20002.00000000", "0.00000000"]], "a": [["96666.42000000", "4.87327000"], ["96666.43000000", "0.00267000"], ["96669.37000000", "0.07925000"], ["96669.65000000", "0.00000000"], ["96669.82000000", "0.02300000"], ["96672.89000000", "0.04030000"], ["96677.48000000", "0.00417000"], ["96680.76000000", "0.21301000"], ["96682.20000000", "0.00000000"], ["96682.58000000", "0.00310000"], ["96682.62000000", "0.00000000"], ["96682.76000000", "0.00000000"], ["96684.57000000", "0.09977000"], ["96693.94000000", "0.00000000"], ["96694.14000000", "0.00000000"], ["96695.76000000", "0.00000000"], ["96696.28000000", "1.00000000"], ["96697.84000000", "0.00000000"], ["96698.37000000", "0.00000000"], ["96721.45000000", "0.00000000"], ["96721.46000000", "0.00000000"], ["96721.86000000", "0.00000000"], ["96722.44000000", "0.00000000"], ["96725.10000000", "0.00000000"], ["96726.14000000", "2.00000000"], ["96729.26000000", "0.00000000"], ["96730.32000000", "0.00000000"]]}
{"e": "depthUpdate", "E": 1746124966014, "s": "BTCUSDT", "b": [["96666.41000000", "3.29340000"], ["96662.08000000", "0.26089000"], ["96642.09000000", "0.00000000"], ["96641.31000000", "1.00000000"], ["96641.22000000", "0.00000000"], ["96639.75000000", "0.00000000"], ["96638.73000000", "1.68161000"], ["96638.15000000", "0.00000000"], ["96618.99000000", "0.86894000"], ["96616.94000000", "0.05000000"], ["96616.21000000", "2.00000000"], ["96616.03000000", "0.00000000"], ["96613.09000000", "0.00000000"], ["96584.93000000", "0.01617000"], ["96522.38000000", "0.00000000"], ["96519.19000000", "2.69734000"], ["95810.65000000", "0.00000000"], ["95713.97000000", "0.00000000"], ["91833.09000000", "0.00000000"], ["86999.77000000", "0.00022000"], ["86999.00000000", "0.01115000"], ["77333.13000000", "0.00050000"], ["70000.00000000", "183.65395000"], ["42000.00000000", "3.70661000"], ["33000.00000000", "2.70627000"]], "a": [["96666.42000000", "4.87323000"], ["96666.43000000", "0.00285000"], ["96666.91000000", "0.00006000"], ["96667.31000000", "0.00012000"], ["96667.32000000", "0.00000000"], ["96667.34000000", "0.00012000"], ["96667.35000000", "0.06447000"], ["96667.63000000", "0.04557000"], ["96668.78000000", "0.00000000"], ["96669.37000000", "0.07925000"], ["96669.82000000", "0.00000000"], ["96669.99000000", "0.30803000"], ["96671.20000000", "0.04146000"], ["96671.85000000", "0.02300000"], ["96672.00000000", "0.03796000"], ["96672.75000000", "0.00000000"], ["96672.89000000", "0.04030000"], ["96675.31000000", "0.00000000"], ["96676.30000000", "0.01005000"], ["96697.22000000", "1.67149000"], ["96700.23000000", "0.00000000"], ["96726.00000000", "1.45261000"], ["96876.59000000", "0.02000000"]]}
{"e": "depthUpdate", "E": 1746124967014, "s": "BTCUSDT", "b": [["96666.41000000", "3.26638000"], ["96661.50000000", "0.00000000"], ["96659.94000000", "0.00006000"], ["96656.20000000", "0.00103000"], ["96654.15000000", "0.00007000"], ["96652.08000000", "0.00999000"], ["96651.11000000", "0.00011000"], ["96642.59000000", "1.90653000"], ["96626.81000000", "0.21301000"], ["96614.49000000", "0.00100000"], ["96614.48000000", "0.00100000"], ["96584.93000000", "0.00000000"], ["96444.01000000", "0.00548000"], ["96435.74000000", "0.00000000"], ["95617.29000000", "0.00000000"], ["95520.61000000", "0.00000000"], ["95423.93000000", "0.00000000"], ["95327.25000000", "0.00000000"], ["86999.77000000", "0.00000000"], ["86999.00000000", "0.01065000"], ["77333.13000000", "0.00050000"], ["34799.91000000", "0.00144000"], ["33000.00000000", "2.70627000"]], "a": [["96666.42000000", "4.69368000"], ["96666.91000000", "0.00006000"], ["96667.31000000", "0.00000000"], ["96667.80000000", "0.00103000"], ["96669.99000000", "0.30809000"], ["96673.10000000", "0.00000000"], ["96674.46000000", "0.18334000"], ["96680.76000000", "0.21301000"], ["96680.78000000", "0.03573000"], ["96723.06000000", "0.55060000"], ["96805.11000000", "0.01722000"], ["96811.36000000", "0.00000000"], ["97633.07000000", "0.00000000"]]}
{"e": "depthUpdate", "E": 1746124968014, "s": "BTCUSDT", "b": [["96666.41000000", "4.50636000"], ["96664.97000000", "0.12122000"], ["96662.08000000", "0.19822000"], ["96654.14000000", "0.35353000"], ["96647.08000000", "0.62042000"], ["96637.91000000", "0.00000000"], ["96618.99000000", "1.31992000"], ["96614.49000000", "0.00000000"], ["96614.48000000", "0.00000000"], ["96614.47000000", "0.00000000"], ["96614.39000000", "0.00100000"], ["96614.38000000", "0.00100000"], ["96522.38000000", "2.69734000"], ["96519.19000000", "0.00000000"], ["95230.57000000", "0.00000000"], ["95216.41000000", "0.00108000"], ["95133.89000000", "0.00000000"], ["95037.21000000", "0.00000000"], ["94940.53000000", "0.00014000"], ["94843.85000000", "0.00000000"], ["88933.10000000", "0.00000000"], ["86999.77000000", "0.00000000"], ["86999.00000000", "0.01065000"], ["77333.13000000", "0.00050000"], ["70000.00000000", "183.65395000"], ["42000.00000000", "3.70561000"], ["34799.91000000", "0.00162000"], ["33000.00000000", "2.70627000"]], "a": [["96666.42000000", "4.89850000"], ["96667.63000000", "0.04557000"], ["96667.67000000", "0.00012000"], ["96667.68000000", "0.02725000"], ["96669.99000000", "0.30803000"], ["96672.00000000", "0.03790000"], ["96677.19000000", "0.00097000"], ["97142.00000000", "0.06061000"]]}
{"e": "depthUpdate", "E": 1746124969014, "s": "BTCUSDT", "b": [["96666.41000000", "7.27587000"], ["96666.40000000", "0.00006000"], ["96666.39000000", "0.00006000"], ["96666.20000000", "0.00018000"], ["96666.19000000", "0.04012000"], ["96666.01000000", "0.00018000"], ["96666.00000000", "0.03819000"], ["96665.75000000", "0.00000000"], ["96665.44000000", "0.00000000"], ["96665.35000000", "0.00000000"], ["96665.34000000", "0.00000000"], ["96665.21000000", "0.00012000"], ["96665.20000000", "0.24448000"], ["96665.19000000", "0.43365000"], ["96664.98000000", "0.00000000"], ["96664.97000000", "0.00006000"], ["96664.96000000", "0.24838000"], ["96663.66000000", "0.05006000"], ["96663.01000000", "0.05178000"], ["96662.90000000", "0.00000000"], ["96662.08000000", "0.37392000"], ["96662.07000000", "0.00000000"], ["96662.00000000", "0.03790000"], ["96660.88000000", "0.00007000"], ["96660.70000000", "0.00103000"], ["96658.89000000", "0.62034000"], ["96657.11000000", "0.07240000"], ["96656.98000000", "1.34913000"], ["96656.94000000", "0.00000000"], ["96656.22000000", "0.05374000"], ["96656.20000000", "0.00000000"], ["96656.01000000", "0.00517000"], ["96654.69000000", "1.68968000"], ["96654.68000000", "0.74465000"], ["96654.30000000", "0.00000000"], ["96654.15000000", "0.38015000"], ["96654.14000000", "0.00000000"], ["96653.10000000", "1.00000000"], ["96652.81000000", "1.17390000"], ["96652.08000000", "0.00000000"], ["96650.90000000", "0.00000000"], ["96650.53000000", "0.74469000"], ["96650.20000000", "0.00000000"], ["96648.80000000", "0.00000000"], ["96648.71000000", "1.68968000"], ["96648.70000000", "0.00000000"], ["96648.60000000", "0.00000000"], ["96647.73000000", "0.07919000"], ["96647.08000000", "0.00000000"], ["96646.90000000", "0.00000000"], ["96646.52000000", "0.00700000"], ["96645.80000000", "0.00000000"], ["96645.70000000", "0.00000000"], ["96644.10000000", "0.00000000"], ["96642.93000000", "0.03785000"], ["96642.90000000", "0.00000000"], ["96641.40000000", "0.00000000"], ["96641.31000000", "0.00000000"], ["96640.88000000", "0.00000000"], ["96640.36000000", "0.00000000"], ["96640.27000000", "0.82967000"], ["96639.79000000", "2.00000000"], ["96639.32000000", "0.00000000"], ["96639.02000000", "0.00000000"], ["96638.39000000", "0.01551000"], ["96637.90000000", "0.00000000"], ["96637.41000000", "1.03145000"], ["96636.76000000", "0.03693000"], ["96635.39000000", "0.00000000"], ["96634.64000000", "0.00000000"], ["96634.36000000", "0.21301000"], ["96633.05000000", "0.00206000"], ["96632.70000000", "0.00000000"], ["96632.19000000", "0.00000000"], ["96631.19000000", "0.00000000"], ["96631.00000000", "0.21301000"], ["96630.99000000", "0.00000000"], ["96630.79000000", "0.00000000"], ["96630.13000000", "0.00000000"], ["96627.39000000", "0.00000000"], ["96627.36000000", "0.00000000"], ["96626.00000000", "0.00025000"], ["96625.19000000", "0.00000000"], ["96624.99000000", "0.00000000"], ["96622.50000000", "0.00000000"], ["96621.79000000", "0.00000000"], ["96621.64000000", "0.00000000"], ["96619.42000000", "0.00000000"], ["96619.39000000", "0.00000000"], ["96618.99000000", "0.86894000"], ["96617.16000000", "0.00000000"], ["96616.39000000", "0.04800000"], ["96616.21000000", "0.00000000"], ["96615.35000000", "0.04000000"], ["96614.40000000", "0.00000000"], ["96614.39000000", "0.00000000"], ["96614.38000000", "0.00000000"], ["96614.31000000", "0.00000000"], ["96614.29000000", "0.00000000"], ["96614.28000000", "0.00000000"], ["96612.23000000", "0.00000000"], ["96601.95000000", "0.00000000"], ["96601.82000000", "0.00000000"], ["96601.67000000", "0.03500000"], ["96599.01000000", "0.00000000"], ["96598.96000000", "0.29358000"], ["96598.95000000", "0.00000000"], ["96598.19000000", "0.00000000"], ["96584.81000000", "0.00000000"], ["96583.06000000", "0.11139000"], ["96570.03000000", "0.64306000"], ["96559.57000000", "0.00000000"], ["96548.26000000", "0.05397000"], ["96506.95000000", "0.15924000"], ["96497.50000000", "0.00000000"], ["96457.80000000", "0.00000000"], ["95216.41000000", "0.00008000"], ["94747.16000000", "0.00000000"], ["94650.48000000", "0.00000000"], ["86999.77000000", "0.00000000"], ["86999.00000000", "0.01065000"], ["77333.13000000", "0.00050000"], ["33000.00000000", "2.70627000"], ["20002.00000000", "0.00000000"]], "a": [["96666.42000000", "0.12698000"], ["96666.43000000", "0.00309000"], ["96666.55000000", "0.00006000"], ["96666.58000000", "0.00006000"], ["96666.59000000", "0.00006000"], ["96666.91000000", "0.00000000"], ["96667.16000000", "0.00012000"], ["96667.34000000", "0.00036000"], ["96667.35000000", "0.00000000"], ["96667.62000000", "0.00000000"], ["96667.63000000", "0.00000000"], ["96667.67000000", "0.00000000"], ["96667.68000000", "0.00000000"], ["96667.80000000", "0.00000000"], ["96668.13000000", "0.00006000"], ["96668.67000000", "0.00000000"], ["96669.36000000", "0.00000000"], ["96669.37000000", "0.00000000"], ["96669.48000000", "0.00000000"], ["96669.77000000", "0.00012000"], ["96669.98000000", "0.00000000"], ["96669.99000000", "0.00000000"], ["96670.00000000", "0.00000000"], ["96670.35000000", "0.00000000"], ["96671.02000000", "0.00006000"], ["96671.09000000", "0.00000000"], ["96671.10000000", "0.00000000"], ["96671.20000000", "0.00000000"], ["96671.44000000", "0.00000000"], ["96671.85000000", "0.00000000"], ["96671.98000000", "0.00000000"], ["96671.99000000", "0.00021000"], ["96672.00000000", "0.03796000"], ["96672.30000000", "0.00103000"], ["96672.57000000", "0.00000000"], ["96672.63000000", "0.00504000"], ["96672.64000000", "0.06447000"], ["96672.88000000", "0.00023000"], ["96672.89000000", "0.04036000"], ["96673.68000000", "0.00000000"], ["96673.69000000", "0.00000000"], ["96673.88000000", "0.00000000"], ["96673.89000000", "0.00000000"], ["96673.90000000", "0.00000000"], ["96674.00000000", "0.03796000"], ["96674.04000000", "0.00000000"], ["96674.16000000", "0.00000000"], ["96674.46000000", "0.00000000"], ["96674.54000000", "0.00000000"], ["96675.29000000", "0.00000000"], ["96675.79000000", "0.00000000"], ["96675.88000000", "0.01040000"], ["96675.94000000", "0.00000000"], ["96675.97000000", "0.00000000"], ["96676.00000000", "0.03996000"], ["96676.09000000", "0.00000000"], ["96676.30000000", "0.00006000"], ["96676.33000000", "0.00000000"], ["96676.34000000", "0.00049000"], ["96676.40000000", "0.01720000"], ["96677.05000000", "0.00006000"], ["96677.06000000", "0.51747000"], ["96677.10000000", "0.21307000"], ["96677.19000000", "0.00000000"], ["96677.29000000", "0.00090000"], ["96677.60000000", "0.00742000"], ["96677.64000000", "0.00094000"], ["96677.66000000", "0.00091000"], ["96677.84000000", "0.00013000"], ["96677.85000000", "0.00000000"], ["96677.99000000", "0.00000000"], ["96678.04000000", "0.00000000"], ["96678.91000000", "0.00000000"], ["96679.07000000", "0.00000000"], ["96679.29000000", "0.00000000"], ["96679.60000000", "0.00000000"], ["96679.82000000", "0.00403000"], ["96680.34000000", "0.00000000"], ["96680.71000000", "0.00000000"], ["96680.76000000", "0.00000000"], ["96680.77000000", "0.21301000"], ["96681.01000000", "0.00000000"], ["96681.30000000", "0.18334000"], ["96682.11000000", "0.00000000"], ["96682.32000000", "0.00335000"], ["96682.72000000", "0.00000000"], ["96683.30000000", "0.00000000"], ["96683.66000000", "0.00000000"], ["96683.79000000", "0.00000000"], ["96683.81000000", "0.00000000"], ["96683.83000000", "0.00000000"], ["96683.98000000", "0.00403000"], ["96684.27000000", "0.00000000"], ["96684.57000000", "0.00000000"], ["96685.05000000", "0.00000000"], ["96685.40000000", "0.00000000"], ["96686.72000000", "0.00000000"], ["96686.81000000", "0.00000000"], ["96686.86000000", "0.00000000"], ["96686.87000000", "0.00000000"], ["96686.99000000", "0.00000000"], ["96687.00000000", "0.56943000"], ["96688.39000000", "0.50099000"], ["96688.67000000", "0.04000000"], ["96689.20000000", "0.00000000"], ["96689.33000000", "0.00403000"], ["96689.38000000", "0.00000000"], ["96689.55000000", "0.02000000"], ["96690.05000000", "0.00000000"], ["96690.07000000", "0.21301000"], ["96690.08000000", "0.00000000"], ["96690.39000000", "0.00000000"], ["96691.87000000", "0.00000000"], ["96692.72000000", "0.00403000"], ["96693.18000000", "0.00517000"], ["96694.59000000", "0.00000000"], ["96695.42000000", "0.07680000"], ["96696.28000000", "0.00000000"], ["96696.43000000", "0.00000000"], ["96698.04000000", "0.00000000"], ["96698.08000000", "0.00403000"], ["96698.92000000", "0.00000000"], ["96699.06000000", "0.00000000"], ["96699.48000000", "0.00000000"], ["96699.64000000", "0.00000000"], ["96699.99000000", "0.00000000"], ["96700.68000000", "0.00000000"], ["96700.84000000", "0.00000000"], ["96701.30000000", "0.00000000"], ["96702.54000000", "0.00000000"], ["96702.64000000", "0.00000000"], ["96703.10000000", "0.00000000"], ["96703.96000000", "0.00403000"], ["96704.14000000", "0.00000000"], ["96704.52000000", "0.62031000"], ["96704.98000000", "0.00000000"], ["96705.33000000", "0.00000000"], ["96705.64000000", "0.00000000"], ["96705.98000000", "0.00000000"], ["96708.11000000", "0.00403000"], ["96709.34000000", "0.74423000"], ["96709.94000000", "1.00000000"], ["96711.10000000", "0.00000000"], ["96711.53000000", "0.00000000"], ["96711.62000000", "0.10760000"], ["96711.78000000", "0.00403000"], ["96712.15000000", "0.00766000"], ["96713.29000000", "0.74523000"], ["96714.23000000", "0.00000000"], ["96716.05000000", "0.74418000"], ["96716.32000000", "0.01533000"], ["96717.74000000", "0.00403000"], ["96719.23000000", "0.00000000"], ["96719.57000000", "0.08900000"], ["96720.61000000", "0.00000000"], ["96721.71000000", "0.00403000"], ["96722.14000000", "0.00000000"], ["96723.08000000", "0.00000000"], ["96725.44000000", "0.00000000"], ["96726.00000000", "0.86373000"], ["96726.10000000", "0.00403000"], ["96726.14000000", "0.00000000"], ["96729.66000000", "0.00000000"], ["96730.22000000", "0.00000000"], ["96730.35000000", "0.00325000"], ["96731.04000000", "0.00403000"], ["96732.85000000", "0.00000000"], ["96732.86000000", "0.00000000"], ["96733.05000000", "0.00000000"], ["96734.01000000", "0.00000000"], ["96735.26000000", "0.00000000"], ["96735.83000000", "0.00403000"], ["96738.66000000", "0.00000000"], ["96738.86000000", "0.00000000"], ["96739.70000000", "0.03641000"], ["96741.64000000", "0.00403000"], ["96741.86000000", "0.00000000"], ["96744.86000000", "0.00000000"], ["96745.73000000", "0.64189000"], ["96746.85000000", "0.00403000"], ["96746.86000000", "0.03734000"], ["96751.61000000", "0.00403000"], ["96753.46000000", "2.00000000"], ["96756.23000000", "0.00403000"], ["96760.50000000", "0.00403000"], ["96765.21000000", "0.00403000"], ["96770.54000000", "0.00403000"], ["96776.67000000", "0.00403000"], ["96780.14000000", "0.00403000"], ["96785.22000000", "0.00403000"], ["96785.34000000", "0.05197000"], ["96785.37000000", "0.05197000"], ["96786.23000000", "0.05197000"], ["96788.82000000", "0.00403000"], ["96794.76000000", "0.00403000"], ["96799.17000000", "0.00409000"], ["96802.90000000", "0.00000000"], ["96804.12000000", "0.00403000"], ["96805.11000000", "0.00000000"], ["96808.54000000", "0.00403000"], ["96813.74000000", "0.00403000"], ["96818.11000000", "0.00403000"], ["96824.96000000", "0.00411000"], ["96829.46000000", "0.00403000"], ["96833.66000000", "0.00403000"], ["96837.40000000", "0.00403000"], ["96843.42000000", "0.00403000"], ["96848.15000000", "0.00403000"], ["96853.34000000", "0.00403000"], ["96858.33000000", "0.00403000"], ["96861.86000000", "0.00403000"], ["96867.33000000", "0.00403000"], ["96946.54000000", "0.54000000"], ["97372.80000000", "0.00000000"], ["97411.44000000", "0.05175000"]]}
{"e": "depthUpdate", "E": 1746124970014, "s": "BTCUSDT", "b": [["96666.41000000", "7.20951000"], ["96666.19000000", "0.04018000"], ["96666.00000000", "0.03825000"], ["96665.20000000", "0.24454000"], ["96665.19000000", "0.43371000"], ["96664.49000000", "0.00051000"], ["96664.00000000", "0.03796000"], ["96663.97000000", "0.05178000"], ["96663.66000000", "0.05006000"], ["96663.01000000", "0.00000000"], ["96662.08000000", "0.37392000"], ["96661.91000000", "0.00050000"], ["96657.90000000", "0.00999000"], ["96655.27000000", "0.00310000"], ["96655.23000000", "0.00000000"], ["96655.04000000", "0.05172000"], ["96655.02000000", "0.00000000"], ["96653.37000000", "1.04800000"], ["96653.10000000", "0.00000000"], ["96646.40000000", "1.60230000"], ["96644.73000000", "0.02586000"], ["96644.65000000", "0.00000000"], ["96644.08000000", "0.03999000"], ["96642.99000000", "0.00000000"], ["96641.42000000", "0.77566000"], ["96640.33000000", "2.00000000"], ["96639.79000000", "0.00000000"], ["96638.73000000", "0.00000000"], ["96637.61000000", "0.00517000"], ["96636.93000000", "0.00000000"], ["96634.36000000", "0.00000000"], ["96633.55000000", "0.01034000"], ["96631.33000000", "0.67511000"], ["96622.89000000", "0.00000000"], ["96622.10000000", "0.05000000"], ["96619.57000000", "0.00000000"], ["96616.94000000", "0.00000000"], ["96616.43000000", "0.00000000"], ["96614.20000000", "0.00000000"], ["96614.19000000", "0.00000000"], ["96598.96000000", "0.00000000"], ["96573.63000000", "0.00178000"], ["96572.49000000", "0.00000000"], ["96562.69000000", "0.00357000"], ["96561.43000000", "0.00000000"], ["96365.80000000", "0.00000000"], ["96234.11000000", "0.00207000"], ["94737.69000000", "0.00006000"], ["86999.77000000", "0.00000000"], ["86999.00000000", "0.01065000"], ["77333.13000000", "0.00050000"], ["70000.00000000", "183.65395000"], ["34799.91000000", "0.00180000"], ["33000.00000000", "2.70627000"]], "a": [["96666.42000000", "0.08508000"], ["96666.43000000", "0.00327000"], ["96670.69000000", "0.00007000"], ["96671.25000000", "0.00000000"], ["96671.26000000", "0.00000000"], ["96671.31000000", "0.00000000"], ["96672.89000000", "0.04036000"], ["96673.35000000", "0.00000000"], ["96673.66000000", "0.00006000"], ["96673.67000000", "0.05250000"], ["96673.98000000", "0.21307000"], ["96675.88000000", "0.01040000"], ["96675.98000000", "0.00000000"], ["96675.99000000", "0.23655000"], ["96676.00000000", "0.03996000"], ["96676.14000000", "0.02718000"], ["96676.40000000", "0.01714000"], ["96677.05000000", "0.00000000"], ["96677.06000000", "0.51741000"], ["96677.10000000", "0.21301000"], ["96680.76000000", "0.18967000"], ["96681.69000000", "0.00999000"], ["96682.46000000", "0.01880000"], ["96682.71000000", "0.00000000"], ["96683.70000000", "0.68239000"], ["96683.81000000", "0.00000000"], ["96684.91000000", "0.00000000"], ["96685.76000000", "0.00000000"], ["96686.72000000", "0.21301000"], ["96686.96000000", "0.00000000"], ["96693.34000000", "0.03999000"], ["96694.42000000", "0.17953000"], ["96697.22000000", "0.00000000"], ["96705.25000000", "0.74426000"], ["96706.32000000", "1.62182000"], ["96711.82000000", "0.43455000"], ["96712.15000000", "0.00000000"], ["96713.74000000", "0.02000000"], ["96716.32000000", "0.00000000"], ["96716.34000000", "0.05000000"], ["96718.60000000", "0.09120000"], ["96720.50000000", "0.00766000"], ["96722.06000000", "0.01533000"], ["96723.68000000", "0.00011000"], ["96732.57000000", "0.00000000"], ["96743.73000000", "0.02832000"], ["96749.75000000", "1.36784000"], ["96762.99000000", "0.00000000"], ["96767.58000000", "0.00000000"], ["96767.82000000", "0.00000000"], ["96768.45000000", "0.00178000"], ["96777.98000000", "0.00000000"], ["96778.28000000", "0.00357000"], ["96812.47000000", "1.33332000"], ["96953.80000000", "0.00000000"], ["97314.78000000", "0.00207000"], ["97447.97000000", "0.00000000"]]}
{"e": "depthUpdate", "E": 1746124971014, "s": "BTCUSDT", "b": [["96666.41000000", "7.22177000"], ["96666.00000000", "0.03825000"], ["96665.44000000", "0.00103000"], ["96661.19000000", "0.01082000"], ["96660.78000000", "0.01133000"], ["96660.70000000", "0.00000000"], ["96657.90000000", "0.00000000"], ["96657.35000000", "0.01733000"], ["96656.92000000", "0.00999000"], ["96653.37000000", "1.04800000"], ["96651.41000000", "0.00000000"], ["96651.31000000", "0.00000000"], ["96651.02000000", "0.00013000"], ["96651.01000000", "0.00000000"], ["96650.95000000", "0.00000000"], ["96650.61000000", "0.00000000"], ["96647.31000000", "0.99415000"], ["96646.55000000", "0.74472000"], ["96643.29000000", "0.00000000"], ["96642.93000000", "0.00000000"], ["96640.33000000", "2.00000000"], ["96636.76000000", "0.00000000"], ["96636.41000000", "0.00000000"], ["96636.21000000", "0.00000000"], ["96635.61000000", "0.00000000"], ["96634.81000000", "0.00000000"], ["96628.79000000", "0.03785000"], ["96626.69000000", "0.00000000"], ["96623.03000000", "0.03693000"], ["96622.50000000", "0.18104000"], ["96620.17000000", "0.00000000"], ["96614.30000000", "0.00000000"], ["96614.29000000", "0.00000000"], ["96200.01000000", "0.00155000"], ["95429.86000000", "0.04105000"], ["95216.41000000", "0.00108000"], ["86999.77000000", "0.00000000"], ["86999.00000000", "0.01065000"], ["77333.13000000", "0.00050000"], ["60000.00000000", "80.85283000"], ["33000.00000000", "2.70627000"]], "a": [["96666.42000000", "0.07703000"], ["96666.43000000", "0.00351000"], ["96667.16000000", "0.00012000"], ["96667.34000000", "0.00000000"], ["96667.39000000", "0.00000000"], ["96668.13000000", "0.00000000"], ["96668.37000000", "0.00000000"], ["96668.45000000", "0.00000000"], ["96668.51000000", "0.00000000"], ["96669.43000000", "0.00000000"], ["96669.44000000", "0.00000000"], ["96669.77000000", "0.00012000"], ["96670.69000000", "0.00000000"], ["96671.02000000", "0.00006000"], ["96671.16000000", "0.00000000"], ["96671.17000000", "0.00000000"], ["96671.37000000", "0.00000000"], ["96671.38000000", "0.00000000"], ["96671.98000000", "0.00012000"], ["96671.99000000", "0.01202000"], ["96672.30000000", "0.00000000"], ["96672.88000000", "0.00017000"], ["96672.89000000", "0.04036000"], ["96673.66000000", "0.00000000"], ["96673.67000000", "0.00000000"], ["96673.97000000", "0.00000000"], ["96675.98000000", "0.00000000"], ["96675.99000000", "0.37706000"], ["96676.00000000", "0.03996000"], ["96676.09000000", "0.56719000"], ["96676.14000000", "0.00000000"], ["96677.33000000", "0.02758000"], ["96678.60000000", "0.00103000"], ["96680.51000000", "0.01880000"], ["96680.74000000", "0.69957000"], ["96680.75000000", "1.68968000"], ["96680.76000000", "0.00000000"], ["96680.94000000", "0.00000000"], ["96681.18000000", "0.68241000"], ["96682.46000000", "0.00000000"], ["96683.69000000", "0.21301000"], ["96683.70000000", "0.00000000"], ["96698.88000000", "0.00000000"], ["96701.35000000", "0.74429000"], ["96704.55000000", "0.00000000"], ["96704.95000000", "0.00008000"], ["96705.25000000", "0.74426000"], ["96705.35000000", "0.00000000"], ["96707.35000000", "0.00011000"], ["96708.05000000", "0.00000000"], ["96708.15000000", "0.00000000"], ["96708.25000000", "0.00000000"], ["96709.75000000", "1.00000000"], ["96709.94000000", "0.00000000"], ["96716.05000000", "0.00000000"], ["96716.34000000", "0.00000000"], ["96717.49000000", "0.05000000"], ["96725.51000000", "0.01551000"], ["96733.05000000", "0.29793000"], ["96742.68000000", "0.00000000"], ["96743.48000000", "0.00000000"], ["96744.08000000", "0.00000000"], ["96744.28000000", "0.00000000"], ["96748.28000000", "0.00000000"], ["96749.68000000", "0.00000000"], ["96749.75000000", "0.89116000"], ["96749.88000000", "0.00000000"], ["96750.08000000", "0.00000000"], ["96753.08000000", "2.00000000"], ["96753.46000000", "0.00000000"], ["96876.59000000", "0.00000000"], ["98116.42000000", "0.00100000"], ["159000.00000000", "0.99863000"]]}
{"e": "depthUpdate", "E": 1746124972014, "s": "BTCUSDT", "b": [["96666.41000000", "7.42504000"], ["96659.52000000", "0.16000000"], ["96658.16000000", "0.00116000"], ["96657.46000000", "0.00000000"], ["96656.92000000", "0.00000000"], ["96655.86000000", "0.00999000"], ["96655.52000000", "0.00310000"], ["96655.48000000", "0.00310000"], ["96655.29000000", "0.00310000"], ["96655.27000000", "0.00000000"], ["96653.37000000", "0.04800000"], ["96651.88000000", "0.00000000"], ["96651.78000000", "1.00000000"], ["96649.96000000", "0.00000000"], ["96643.49000000", "0.00767000"], ["96642.44000000", "0.10114000"], ["96641.40000000", "0.01534000"], ["96640.33000000", "0.00000000"], ["96639.61000000", "0.00000000"], ["96637.41000000", "0.93078000"], ["96637.35000000", "0.00000000"], ["96637.15000000", "2.00000000"], ["96634.36000000", "0.00000000"], ["96633.52000000", "0.00000000"], ["96633.51000000", "0.00000000"], ["96632.54000000", "0.00000000"], ["96631.49000000", "0.00000000"], ["96631.33000000", "0.00000000"], ["96614.20000000", "0.00000000"], ["96614.19000000", "0.00000000"], ["96600.95000000", "0.01617000"], ["96597.80000000", "0.16869000"], ["95699.74000000", "0.00000000"], ["95429.86000000", "0.00000000"], ["95216.41000000", "0.00108000"], ["86999.77000000", "0.00000000"], ["86999.00000000", "0.01065000"], ["77333.13000000", "0.00050000"], ["70000.00000000", "183.65395000"], ["60000.00000000", "80.85273000"], ["34799.91000000", "0.00198000"], ["33000.00000000", "2.70627000"]], "a": [["96666.42000000", "0.07607000"], ["96666.43000000", "0.00357000"], ["96669.15000000", "0.00000000"], ["96669.83000000", "0.00000000"], ["96670.22000000", "0.00000000"], ["96671.00000000", "0.00000000"], ["96671.85000000", "0.00000000"], ["96671.98000000", "0.00000000"], ["96671.99000000", "0.00000000"], ["96672.00000000", "0.00000000"], ["96672.63000000", "0.00485000"], ["96672.64000000", "0.00000000"], ["96672.88000000", "0.00023000"], ["96672.89000000", "0.04036000"], ["96672.99000000", "0.00000000"], ["96673.97000000", "0.00000000"], ["96673.98000000", "0.00000000"], ["96673.99000000", "0.00021000"], ["96674.00000000", "0.03796000"], ["96674.01000000", "0.00000000"], ["96675.98000000", "0.00019000"], ["96675.99000000", "0.08630000"], ["96676.00000000", "0.03996000"], ["96676.09000000", "0.02725000"], ["96676.40000000", "0.01720000"], ["96676.72000000", "0.00006000"], ["96676.73000000", "0.21307000"], ["96677.06000000", "0.00000000"], ["96677.10000000", "0.00000000"], ["96677.33000000", "0.00000000"], ["96677.62000000", "0.06447000"], ["96678.00000000", "0.03790000"], ["96680.27000000", "0.02714000"], ["96680.51000000", "0.00000000"], ["96680.69000000", "0.00000000"], ["96680.72000000", "0.69657000"], ["96680.73000000", "1.68968000"], ["96680.74000000", "0.00000000"], ["96680.75000000", "0.00000000"], ["96680.91000000", "0.68241000"], ["96681.18000000", "0.00000000"], ["96681.69000000", "0.00000000"], ["96682.33000000", "0.00000000"], ["96682.39000000", "0.00999000"], ["96682.82000000", "0.00000000"], ["96683.20000000", "0.00414000"], ["96683.23000000", "0.01466000"], ["96683.25000000", "0.00000000"], ["96683.65000000", "0.02055000"], ["96683.69000000", "0.00000000"], ["96686.72000000", "0.00000000"], ["96687.39000000", "0.21301000"], ["96690.07000000", "0.00000000"], ["96701.04000000", "0.00790000"], ["96701.31000000", "0.00000000"], ["96701.35000000", "0.00000000"], ["96702.49000000", "0.00000000"], ["96705.82000000", "1.00000000"], ["96708.62000000", "0.69525000"], ["96709.59000000", "0.00000000"], ["96709.75000000", "0.00000000"], ["96710.32000000", "0.00000000"], ["96711.21000000", "0.00000000"], ["96711.22000000", "0.00000000"], ["96711.82000000", "0.00000000"], ["96715.85000000", "0.74418000"], ["96720.50000000", "0.00000000"], ["96721.54000000", "0.00766000"], ["96726.62000000", "0.01617000"], ["96745.22000000", "2.00000000"], ["96749.75000000", "0.89116000"], ["96750.82000000", "0.00000000"], ["96753.08000000", "0.00000000"], ["96754.22000000", "0.00000000"], ["96756.02000000", "0.00000000"], ["98116.42000000", "0.00000000"], ["102863.91000000", "0.25574000"], ["103393.82000000", "0.25568000"], ["103926.47000000", "0.25574000"], ["104461.85000000", "0.25547000"], ["105000.00000000", "130.85796000"]]}
{"e": "depthUpdate", "E": 1746124973014, "s": "BTCUSDT", "b": [["96673.38000000", "11.09210000"], ["96673.37000000", "0.00006000"], ["96673.36000000", "0.00006000"], ["96673.35000000", "0.00012000"], ["96673.32000000", "0.00006000"], ["96673.10000000", "0.00018000"], ["96673.09000000", "0.66755000"], ["96673.08000000", "0.00018000"], ["96673.07000000", "0.68259000"], ["96673.00000000", "0.00007000"], ["96672.96000000", "0.00000000"], ["96672.89000000", "0.00000000"], ["96672.88000000", "0.00000000"], ["96672.62000000", "0.00000000"], ["96671.99000000", "0.00000000"], ["96671.84000000", "0.00006000"], ["96671.75000000", "0.00000000"], ["96671.74000000", "0.00000000"], ["96671.46000000", "0.00051000"], ["96671.44000000", "0.00044000"], ["96671.20000000", "0.04152000"], ["96671.15000000", "0.00000000"], ["96670.16000000", "0.00006000"], ["96670.05000000", "0.44696000"], ["96670.00000000", "0.03802000"], ["96669.98000000", "0.00000000"], ["96669.81000000", "0.00000000"], ["96669.77000000", "0.00000000"], ["96669.76000000", "0.00000000"], ["96669.64000000", "0.00000000"], ["96669.55000000", "0.00000000"], ["96669.39000000", "0.21307000"], ["96669.36000000", "0.00000000"], ["96668.88000000", "0.00000000"], ["96668.68000000", "0.00000000"], ["96668.55000000", "0.00517000"], ["96668.16000000", "0.01153000"], ["96668.00000000", "0.03796000"], ["96667.98000000", "0.00000000"], ["96667.75000000", "0.00000000"], ["96667.62000000", "0.00000000"], ["96667.15000000", "0.00000000"], ["96666.58000000", "0.00000000"], ["96666.57000000", "0.00000000"], ["96666.56000000", "0.00000000"], ["96666.54000000", "0.00000000"], ["96666.44000000", "0.00000000"], ["96666.43000000", "0.67614000"], ["96666.42000000", "0.21301000"], ["96666.41000000", "2.26486000"], ["96666.40000000", "0.00000000"], ["96666.39000000", "0.00000000"], ["96666.20000000", "0.00000000"], ["96666.19000000", "0.04000000"], ["96666.02000000", "0.00000000"], ["96666.01000000", "0.00000000"], ["96666.00000000", "0.03790000"], ["96665.62000000", "0.00011000"], ["96665.21000000", "0.00000000"], ["96665.20000000", "0.00000000"], ["96665.19000000", "0.00000000"], ["96664.97000000", "0.00000000"], ["96664.96000000", "0.00000000"], ["96664.80000000", "0.04140000"], ["96664.49000000", "0.00000000"], ["96664.47000000", "0.00000000"], ["96664.32000000", "0.00000000"], ["96664.00000000", "0.03790000"], ["96663.97000000", "0.05172000"], ["96663.84000000", "0.00006000"], ["96663.71000000", "0.00527000"], ["96663.66000000", "0.05516000"], ["96663.65000000", "0.00000000"], ["96662.08000000", "0.61685000"], ["96661.93000000", "0.00008000"], ["96661.91000000", "0.00000000"], ["96661.31000000", "0.00011000"], ["96661.19000000", "0.00000000"], ["96660.78000000", "0.00000000"], ["96660.62000000", "0.74461000"], ["96660.42000000", "0.00000000"], ["96660.11000000", "0.00084000"], ["96659.96000000", "0.00000000"], ["96658.01000000", "0.00013000"], ["96657.62000000", "0.00999000"], ["96657.35000000", "0.00000000"], ["96657.08000000", "1.00000000"], ["96656.74000000", "0.54000000"], ["96656.36000000", "0.00013000"], ["96656.28000000", "0.00310000"], ["96656.22000000", "0.05172000"], ["96656.18000000", "0.00000000"], ["96656.01000000", "0.00000000"], ["96655.86000000", "0.00000000"], ["96655.53000000", "0.00006000"], ["96655.52000000", "0.00000000"], ["96655.48000000", "0.00000000"], ["96655.38000000", "0.00000000"], ["96655.29000000", "0.00000000"], ["96655.10000000", "1.10000000"], ["96654.15000000", "0.00007000"], ["96654.05000000", "0.00051000"], ["96654.04000000", "0.02524000"], ["96653.37000000", "0.04800000"], ["96652.16000000", "0.00000000"], ["96651.78000000", "0.00000000"], ["96651.02000000", "0.00000000"], ["96649.96000000", "0.00000000"], ["96649.47000000", "0.00464000"], ["96647.07000000", "0.00000000"], ["96644.39000000", "0.00051000"], ["96642.22000000", "0.00000000"], ["96640.78000000", "2.00000000"], ["96640.77000000", "0.01034000"], ["96640.54000000", "1.03989000"], ["96640.33000000", "0.00000000"], ["96638.59000000", "0.00356000"], ["96638.16000000", "0.00000000"], ["96637.58000000", "0.00000000"], ["96637.41000000", "0.00000000"], ["96637.38000000", "0.00000000"], ["96637.15000000", "0.00000000"], ["96637.09000000", "0.00584000"], ["96634.36000000", "0.21301000"], ["96633.54000000", "0.00000000"], ["96633.51000000", "0.00000000"], ["96631.11000000", "0.00000000"], ["96631.00000000", "0.00000000"], ["96630.81000000", "0.00000000"], ["96630.11000000", "0.21301000"], ["96630.10000000", "0.00000000"], ["96623.58000000", "0.00103000"], ["96623.14000000", "0.00000000"], ["96621.76000000", "0.00000000"], ["96616.62000000", "0.00000000"], ["96614.10000000", "0.00100000"], ["96614.09000000", "0.00100000"], ["96610.88000000", "0.00000000"], ["96601.77000000", "0.51710000"], ["96600.95000000", "0.00000000"], ["96600.40000000", "0.41368000"], ["96553.69000000", "0.00182000"], ["96544.01000000", "0.00000000"], ["96540.44000000", "0.00000000"], ["96531.94000000", "2.69734000"], ["96526.50000000", "0.00000000"], ["96526.00000000", "0.00000000"], ["96522.38000000", "0.00000000"], ["96418.46000000", "0.00620000"], ["96416.67000000", "0.00000000"], ["96382.37000000", "0.00000000"], ["96343.76000000", "0.00000000"], ["96343.74000000", "0.00000000"], ["96341.08000000", "0.03786000"], ["96334.10000000", "0.00000000"], ["95216.41000000", "0.00008000"], ["88933.10000000", "0.00012000"], ["87006.00000000", "0.00000000"], ["87005.00000000", "0.00163000"], ["86999.77000000", "0.00000000"], ["86999.00000000", "0.01045000"], ["77338.71000000", "0.00050000"], ["77333.13000000", "0.00000000"], ["34802.42000000", "0.00018000"], ["34799.91000000", "0.00216000"], ["33000.00000000", "2.70627000"]], "a": [["96666.42000000", "0.00000000"], ["96666.43000000", "0.00000000"], ["96666.45000000", "0.00000000"], ["96666.55000000", "0.00000000"], ["96666.57000000", "0.00000000"], ["96666.58000000", "0.00000000"], ["96666.59000000", "0.00000000"], ["96667.16000000", "0.00000000"], ["96667.99000000", "0.00000000"], ["96668.08000000", "0.00000000"], ["96668.11000000", "0.00000000"], ["96668.27000000", "0.00000000"], ["96668.36000000", "0.00000000"], ["96669.09000000", "0.00000000"], ["96669.77000000", "0.00000000"], ["96669.78000000", "0.00000000"], ["96670.83000000", "0.00000000"], ["96671.02000000", "0.00000000"], ["96671.15000000", "0.00000000"], ["96671.16000000", "0.00000000"], ["96671.50000000", "0.00000000"], ["96671.74000000", "0.00000000"], ["96671.75000000", "0.00000000"], ["96671.76000000", "0.00000000"], ["96672.14000000", "0.00000000"], ["96672.16000000", "0.00000000"], ["96672.63000000", "0.00000000"], ["96672.88000000", "0.00000000"], ["96672.89000000", "0.00000000"], ["96673.01000000", "0.00000000"], ["96673.08000000", "0.00000000"], ["96673.36000000", "0.00000000"], ["96673.38000000", "0.00000000"], ["96673.39000000", "2.10902000"], ["96673.40000000", "0.21787000"], ["96673.42000000", "0.00040000"], ["96673.91000000", "0.00006000"], ["96673.99000000", "0.00000000"], ["96674.00000000", "0.03808000"], ["96674.26000000", "0.04704000"], ["96674.61000000", "0.00306000"], ["96675.33000000", "0.00051000"], ["96675.84000000", "0.00006000"], ["96675.88000000", "0.01040000"], ["96675.98000000", "0.00000000"], ["96675.99000000", "0.08135000"], ["96676.00000000", "0.04002000"], ["96676.08000000", "0.00000000"], ["96676.09000000", "0.00000000"], ["96676.30000000", "0.00006000"], ["96676.34000000", "0.00000000"], ["96676.40000000", "0.01726000"], ["96676.72000000", "0.00000000"], ["96676.73000000", "0.21313000"], ["96677.29000000", "0.00000000"], ["96677.62000000", "0.06453000"], ["96677.66000000", "0.00000000"], ["96677.84000000", "0.00000000"], ["96678.00000000", "0.03790000"], ["96678.22000000", "0.00517000"], ["96678.48000000", "0.00000000"], ["96679.28000000", "0.00000000"], ["96679.59000000", "0.00807000"], ["96680.00000000", "0.02275000"], ["96680.23000000", "0.03515000"], ["96680.27000000", "0.02714000"], ["96680.71000000", "0.00000000"], ["96680.78000000", "0.03539000"], ["96680.91000000", "0.00000000"], ["96680.92000000", "0.00000000"], ["96681.30000000", "0.18334000"], ["96681.33000000", "0.02620000"], ["96682.06000000", "0.00724000"], ["96682.12000000", "0.85154000"], ["96682.58000000", "0.00000000"], ["96683.06000000", "0.01291000"], ["96684.09000000", "0.00000000"], ["96684.10000000", "0.00000000"], ["96684.27000000", "0.00000000"], ["96686.32000000", "0.00000000"], ["96686.64000000", "0.01033000"], ["96687.65000000", "0.00310000"], ["96687.89000000", "0.00567000"], ["96689.11000000", "0.00010000"], ["96691.47000000", "0.00000000"], ["96692.72000000", "0.00454000"], ["96693.18000000", "0.00000000"], ["96694.23000000", "0.10098000"], ["96695.41000000", "0.00000000"], ["96695.99000000", "0.00516000"], ["96699.12000000", "0.77566000"], ["96701.04000000", "0.00000000"], ["96702.39000000", "0.10393000"], ["96702.49000000", "0.00000000"], ["96702.79000000", "0.77566000"], ["96705.18000000", "0.74427000"], ["96705.25000000", "0.00000000"], ["96705.47000000", "0.19103000"], ["96705.82000000", "0.00000000"], ["96707.32000000", "0.00000000"], ["96708.12000000", "0.00000000"], ["96708.52000000", "0.00000000"], ["96708.62000000", "0.69525000"], ["96709.42000000", "0.00000000"], ["96710.12000000", "0.00000000"], ["96710.22000000", "0.00000000"], ["96711.02000000", "1.00000000"], ["96720.32000000", "0.00000000"], ["96726.62000000", "0.00000000"], ["96745.21000000", "0.00000000"], ["96745.22000000", "0.00000000"], ["96745.45000000", "0.00000000"], ["96745.52000000", "0.00000000"], ["96748.22000000", "0.00000000"], ["96748.65000000", "2.00000000"], ["96749.82000000", "0.00000000"], ["96750.62000000", "0.00000000"], ["96750.82000000", "0.00000000"], ["96753.82000000", "0.00000000"], ["96754.02000000", "0.00000000"], ["96754.59000000", "0.01080000"], ["96757.12000000", "0.00000000"], ["96760.14000000", "0.00000000"], ["96766.36000000", "0.00257000"], ["96767.41000000", "0.00257000"], ["96770.05000000", "0.01617000"], ["96798.08000000", "0.04997000"], ["96799.01000000", "0.00006000"], ["96855.30000000", "0.00000000"], ["96863.40000000", "0.00103000"], ["96938.07000000", "0.33545000"], ["96971.14000000", "0.00000000"], ["96976.71000000", "0.01733000"], ["98116.42000000", "0.00100000"], ["100771.29000000", "0.25588000"], ["101290.42000000", "0.25547000"], ["101812.22000000", "0.25595000"], ["102302.92000000", "0.00013000"], ["102336.72000000", "0.25569000"], ["102616.26000000", "0.00013000"], ["102929.60000000", "0.00013000"], ["103242.94000000", "0.00013000"], ["103556.28000000", "0.00013000"], ["103869.63000000", "0.00034000"]]}
{"e": "depthUpdate", "E": 1746124974014, "s": "BTCUSDT", "b": [["96673.38000000", "9.24161000"], ["96673.37000000", "0.00006000"], ["96673.09000000", "0.44362000"], ["96670.00000000", "0.03813000"], ["96660.57000000", "0.41446000"], ["96657.08000000", "0.00000000"], ["96656.88000000", "0.00000000"], ["96656.78000000", "0.00000000"], ["96656.53000000", "1.00000000"], ["96655.18000000", "0.00000000"], ["96655.10000000", "0.00000000"], ["96654.93000000", "0.00000000"], ["96652.03000000", "0.00000000"], ["96649.96000000", "0.00000000"], ["96649.81000000", "0.00000000"], ["96649.29000000", "0.00000000"], ["96647.73000000", "0.07919000"], ["96644.38000000", "0.00010000"], ["96644.37000000", "0.00300000"], ["96640.78000000", "0.00000000"], ["96640.38000000", "0.00000000"], ["96640.18000000", "0.00000000"], ["96639.68000000", "2.00000000"], ["96638.03000000", "2.07300000"], ["96636.98000000", "0.00000000"], ["96636.48000000", "0.00000000"], ["96631.10000000", "0.00000000"], ["96630.68000000", "0.00000000"], ["96626.54000000", "0.00000000"], ["96626.24000000", "0.00000000"], ["96625.20000000", "0.00000000"], ["96622.08000000", "0.00000000"], ["96616.60000000", "0.00000000"], ["96615.38000000", "0.00010000"], ["96602.10000000", "0.00000000"], ["96586.50000000", "0.00000000"], ["96586.37000000", "0.00010000"], ["96573.11000000", "0.00000000"], ["96557.37000000", "0.00010000"], ["96544.11000000", "0.00000000"], ["96528.37000000", "0.00010000"], ["96515.11000000", "0.00000000"], ["95223.27000000", "0.00133000"], ["95200.00000000", "9.44838000"], ["94205.79000000", "0.00993000"], ["94149.59000000", "0.00000000"], ["88933.10000000", "0.00000000"], ["87006.04000000", "0.00000000"], ["87006.00000000", "0.00000000"], ["87005.00000000", "0.00163000"], ["77338.71000000", "0.00050000"], ["70000.00000000", "183.65395000"], ["34802.42000000", "0.00072000"], ["33000.00000000", "2.70627000"]], "a": [["96673.39000000", "1.62462000"], ["96673.40000000", "0.00498000"], ["96673.42000000", "0.00040000"], ["96673.89000000", "0.00018000"], ["96673.90000000", "0.04222000"], ["96673.91000000", "0.00006000"], ["96673.99000000", "0.00018000"], ["96674.00000000", "0.03808000"], ["96674.24000000", "0.00012000"], ["96674.25000000", "0.09962000"], ["96674.26000000", "0.00000000"], ["96674.61000000", "0.00000000"], ["96675.33000000", "0.00045000"], ["96675.88000000", "0.01040000"], ["96675.89000000", "0.00000000"], ["96675.90000000", "0.00000000"], ["96675.99000000", "0.00000000"], ["96676.72000000", "0.00012000"], ["96676.73000000", "0.21307000"], ["96677.62000000", "0.06447000"], ["96678.00000000", "0.03796000"], ["96680.00000000", "0.02275000"], ["96680.23000000", "0.03515000"], ["96680.27000000", "0.00000000"], ["96680.71000000", "0.00012000"], ["96681.10000000", "0.68241000"], ["96681.44000000", "0.00000000"], ["96683.20000000", "0.00000000"], ["96683.23000000", "0.00000000"], ["96683.65000000", "0.00000000"], ["96684.00000000", "0.06220000"], ["96685.05000000", "0.00013000"], ["96685.62000000", "0.00013000"], ["96687.00000000", "0.54000000"], ["96687.39000000", "0.00000000"], ["96689.11000000", "0.00000000"], ["96702.39000000", "0.10403000"], ["96705.47000000", "0.15999000"], ["96705.56000000", "0.03105000"], ["96706.07000000", "0.00000000"], ["96707.67000000", "0.00000000"], ["96708.87000000", "0.00000000"], ["96709.12000000", "0.00000000"], ["96710.47000000", "1.00000000"], ["96710.72000000", "0.00000000"], ["96711.02000000", "0.00000000"], ["96713.28000000", "0.64680000"], ["96716.90000000", "0.00300000"], ["96718.11000000", "0.00000000"], ["96731.39000000", "0.00010000"], ["96738.75000000", "0.00000000"], ["96741.95000000", "0.00000000"], ["96744.35000000", "0.00000000"], ["96744.85000000", "0.00000000"], ["96745.52000000", "0.00000000"], ["96747.10000000", "0.00000000"], ["96747.55000000", "2.02868000"], ["96748.05000000", "0.00000000"], ["96748.65000000", "0.00000000"], ["96760.40000000", "0.00010000"], ["96767.17000000", "0.00010000"], ["96770.05000000", "0.00000000"], ["96776.10000000", "0.00000000"], ["96789.40000000", "0.00010000"], ["96805.10000000", "0.00000000"], ["96810.72000000", "0.00011000"], ["96818.40000000", "0.00010000"], ["98116.42000000", "0.00000000"], ["98721.23000000", "0.26304000"], ["99229.80000000", "0.25548000"], ["99740.99000000", "0.25698000"], ["100254.82000000", "0.25609000"], ["101049.56000000", "0.00013000"], ["101362.90000000", "0.00013000"], ["101676.24000000", "0.00013000"], ["101989.58000000", "0.00013000"]]}
{"e": "depthUpdate", "E": 1746124975014, "s": "BTCUSDT", "b": [["96673.38000000", "8.63620000"], ["96673.37000000", "0.00018000"], ["96673.09000000", "0.24548000"], ["96671.46000000", "0.00000000"], ["96671.20000000", "0.04146000"], ["96670.05000000", "0.00006000"], ["96670.00000000", "0.03807000"], ["96669.39000000", "0.00000000"], ["96666.42000000", "0.21307000"], ["96666.41000000", "2.26502000"], ["96663.66000000", "0.05000000"], ["96662.50000000", "0.00010000"], ["96660.63000000", "0.00000000"], ["96660.62000000", "0.00000000"], ["96660.12000000", "0.00516000"], ["96656.98000000", "0.97278000"], ["96656.54000000", "0.00013000"], ["96656.53000000", "0.00000000"], ["96656.36000000", "0.00000000"], ["96655.33000000", "0.00000000"], ["96654.69000000", "0.00000000"], ["96652.53000000", "0.00000000"], ["96652.43000000", "0.00000000"], ["96650.33000000", "0.00000000"], ["96649.29000000", "1.00000000"], ["96648.77000000", "0.00000000"], ["96647.20000000", "0.00000000"], ["96644.33000000", "0.74473000"], ["96639.68000000", "0.00000000"], ["96637.28000000", "0.00000000"], ["96634.36000000", "0.21301000"], ["96631.68000000", "0.00000000"], ["96631.48000000", "0.00000000"], ["96631.33000000", "0.56879000"], ["96627.28000000", "0.00000000"], ["96625.20000000", "2.00000000"], ["96624.16000000", "0.00000000"], ["96623.03000000", "0.00000000"], ["96621.02000000", "0.00000000"], ["96612.00000000", "0.03913000"], ["96600.01000000", "0.00257000"], ["96598.05000000", "0.00256000"], ["96592.32000000", "0.00000000"], ["96592.01000000", "0.00000000"], ["96502.95000000", "0.00103000"], ["96501.49000000", "0.00103000"], ["96488.40000000", "0.00000000"], ["96488.01000000", "0.00000000"], ["96456.87000000", "0.00237000"], ["96450.09000000", "0.00000000"], ["96444.63000000", "0.00548000"], ["96444.01000000", "0.00000000"], ["96217.21000000", "0.25560000"], ["95223.27000000", "0.00133000"], ["87006.04000000", "0.00000000"], ["87006.00000000", "0.00000000"], ["87005.00000000", "0.00163000"], ["77338.71000000", "0.00050000"], ["34802.42000000", "0.00090000"], ["33000.00000000", "2.70627000"], ["20002.00000000", "0.00000000"]], "a": [["96673.39000000", "3.89922000"], ["96673.40000000", "0.00498000"], ["96675.24000000", "0.00007000"], ["96676.40000000", "0.01726000"], ["96676.46000000", "0.02626000"], ["96677.48000000", "0.00000000"], ["96677.64000000", "0.00000000"], ["96678.00000000", "0.03790000"], ["96681.28000000", "0.02824000"], ["96681.33000000", "0.00000000"], ["96681.76000000", "0.01880000"], ["96687.39000000", "0.21301000"], ["96691.28000000", "0.00516000"], ["96695.99000000", "0.00000000"], ["96704.27000000", "1.00000000"], ["96706.37000000", "0.00000000"], ["96706.47000000", "0.00000000"], ["96709.27000000", "0.00000000"], ["96710.14000000", "0.05000000"], ["96710.47000000", "0.00000000"], ["96717.49000000", "0.00000000"], ["96733.05000000", "0.86069000"], ["96735.15000000", "2.00000000"], ["96739.35000000", "0.00000000"], ["96739.55000000", "0.00000000"], ["96745.15000000", "0.00000000"], ["96747.55000000", "0.02868000"], ["96812.47000000", "0.00000000"], ["96815.65000000", "1.33332000"], ["96858.38000000", "0.00000000"], ["96864.63000000", "0.00103000"], ["97211.11000000", "0.25554000"], ["97711.90000000", "0.25575000"], ["98123.50000000", "0.00100000"], ["98215.27000000", "0.25548000"], ["98500.00000000", "68.33257000"], ["99796.20000000", "0.00013000"], ["100109.54000000", "0.00013000"], ["100422.88000000", "0.00013000"], ["100736.22000000", "0.00013000"]]}
{"e": "depthUpdate", "E": 1746124976014, "s": "BTCUSDT", "b": [["96673.38000000", "9.17632000"], ["96673.37000000", "0.00018000"], ["96671.20000000", "0.04152000"], ["96670.05000000", "0.00000000"], ["96670.01000000", "0.02097000"], ["96670.00000000", "0.03813000"], ["96669.40000000", "0.21313000"], ["96668.16000000", "0.00000000"], ["96668.00000000", "0.03802000"], ["96666.41000000", "2.26496000"], ["96662.75000000", "0.44795000"], ["96660.11000000", "0.00010000"], ["96658.75000000", "0.74462000"], ["96655.83000000", "0.00000000"], ["96654.23000000", "0.00000000"], ["96652.86000000", "0.00000000"], ["96651.63000000", "0.00000000"], ["96651.16000000", "1.00000000"], ["96649.29000000", "0.00000000"], ["96646.40000000", "0.00000000"], ["96645.09000000", "1.67574000"], ["96644.33000000", "0.00000000"], ["96638.28000000", "0.00000000"], ["96635.08000000", "0.00000000"], ["96632.34000000", "0.00000000"], ["96629.88000000", "0.00000000"], ["96628.94000000", "2.00000000"], ["96625.20000000", "0.00000000"], ["96622.50000000", "0.25496000"], ["96622.03000000", "0.32759000"], ["96614.46000000", "0.00000000"], ["96602.96000000", "0.00000000"], ["96565.01000000", "0.00000000"], ["96546.42000000", "0.00000000"], ["96509.95000000", "0.00000000"], ["96487.68000000", "0.00000000"], ["96000.01000000", "0.00749000"], ["95803.32000000", "0.00016000"], ["95724.08000000", "0.25597000"], ["95706.65000000", "0.00008000"], ["95233.48000000", "0.25549000"], ["95223.27000000", "0.00033000"], ["94745.39000000", "0.25703000"], ["94259.80000000", "0.25570000"], ["87006.04000000", "0.00000000"], ["87006.00000000", "0.00000000"], ["77338.71000000", "0.00050000"], ["70000.00000000", "183.65395000"], ["42000.00000000", "3.70661000"], ["34802.42000000", "0.00126000"], ["33000.00000000", "2.70627000"]], "a": [["96673.39000000", "2.81922000"], ["96673.40000000", "0.00504000"], ["96673.42000000", "0.00040000"], ["96673.88000000", "0.00018000"], ["96673.89000000", "0.05291000"], ["96674.00000000", "0.03802000"], ["96674.24000000", "0.00000000"], ["96674.25000000", "0.00000000"], ["96675.99000000", "0.00012000"], ["96676.40000000", "0.01726000"], ["96676.46000000", "0.02626000"], ["96676.72000000", "0.00000000"], ["96676.73000000", "0.00000000"], ["96677.47000000", "0.00006000"], ["96677.48000000", "0.21307000"], ["96677.62000000", "0.06447000"], ["96678.00000000", "0.03790000"], ["96680.71000000", "0.00006000"], ["96683.65000000", "0.00000000"], ["96687.39000000", "0.00000000"], ["96691.28000000", "0.00000000"], ["96692.71000000", "0.00516000"], ["96701.61000000", "2.44449000"], ["96704.27000000", "0.00000000"], ["96705.10000000", "1.00000000"], ["96705.56000000", "0.00000000"], ["96705.83000000", "0.00000000"], ["96706.13000000", "1.63195000"], ["96706.32000000", "0.00000000"], ["96706.80000000", "0.00000000"], ["96707.70000000", "0.00000000"], ["96708.17000000", "0.00000000"], ["96709.77000000", "0.00000000"], ["96733.05000000", "0.29793000"], ["96735.15000000", "0.00000000"], ["96736.81000000", "2.00000000"], ["96738.27000000", "0.00000000"], ["96740.21000000", "0.00000000"], ["96742.95000000", "0.00000000"], ["96745.52000000", "0.00000000"], ["96746.15000000", "0.00000000"], ["96746.36000000", "0.00000000"], ["96793.76000000", "0.42010000"], ["96795.51000000", "0.00000000"], ["96823.68000000", "0.00000000"], ["97400.00000000", "10.52726000"], ["98123.50000000", "0.00000000"], ["98542.83000000", "0.00013000"], ["98856.17000000", "0.00013000"], ["99169.51000000", "0.00013000"], ["99482.85000000", "0.00062000"]]}
{"e": "depthUpdate", "E": 1746124977014, "s": "BTCUSDT", "b": [["96673.38000000", "8.63687000"], ["96673.37000000", "0.00024000"], ["96669.35000000", "0.00103000"], ["96668.00000000", "0.03796000"], ["96666.66000000", "0.06294000"], ["96666.42000000", "0.21301000"], ["96665.44000000", "0.00000000"], ["96662.76000000", "0.00516000"], ["96660.12000000", "0.00000000"], ["96658.60000000", "0.00999000"], ["96657.62000000", "0.00000000"], ["96619.04000000", "0.00000000"], ["96531.94000000", "2.69714000"], ["95706.65000000", "0.00016000"], ["95609.97000000", "0.00008000"], ["95513.30000000", "0.00008000"], ["95416.63000000", "0.00008000"], ["95223.27000000", "0.00133000"], ["94737.69000000", "0.00076000"], ["93776.70000000", "0.25576000"], ["93296.08000000", "0.25549000"], ["92817.92000000", "0.25589000"], ["92342.21000000", "0.25571000"], ["87006.04000000", "0.00000000"], ["87006.00000000", "0.00000000"], ["87005.00000000", "0.00163000"], ["77338.71000000", "0.00050000"], ["34802.42000000", "0.00144000"], ["33000.00000000", "2.70627000"]], "a": [["96673.39000000", "2.81934000"], ["96677.48000000", "0.21307000"], ["96677.62000000", "0.00000000"], ["96678.00000000", "0.03796000"], ["96686.99000000", "0.00000000"], ["96690.27000000", "0.21301000"], ["96692.71000000", "0.00000000"], ["96694.22000000", "0.00516000"], ["96701.83000000", "0.00760000"], ["96705.56000000", "0.03105000"], ["96745.52000000", "1.02896000"], ["97289.47000000", "0.00013000"], ["97602.81000000", "0.00013000"], ["97640.11000000", "0.00000000"], ["97916.15000000", "0.00013000"], ["98123.50000000", "0.00100000"], ["98229.49000000", "0.00054000"], ["149000.00000000", "10.46530000"]]}
{"e": "depthUpdate", "E": 1746124978014, "s": "BTCUSDT", "b": [["96673.38000000", "6.34312000"], ["96673.37000000", "0.00018000"], ["96673.10000000", "0.00006000"], ["96673.09000000", "0.00012000"], ["96673.08000000", "0.00018000"], ["96673.07000000", "0.68259000"], ["96672.39000000", "0.00414000"], ["96671.52000000", "0.01472000"], ["96671.20000000", "0.04146000"], ["96670.01000000", "0.00038000"], ["96670.00000000", "0.03807000"], ["96669.41000000", "0.00000000"], ["96669.40000000", "0.00000000"], ["96668.55000000", "0.02595000"], ["96666.43000000", "0.46949000"], ["96666.42000000", "0.00000000"], ["96666.41000000", "0.21424000"], ["96666.19000000", "0.04000000"], ["96666.00000000", "0.03790000"], ["96663.86000000", "0.21301000"], ["96663.71000000", "0.00565000"], ["96662.79000000", "0.00006000"], ["96662.76000000", "0.26631000"], ["96662.08000000", "0.00000000"], ["96662.01000000", "0.00423000"], ["96661.98000000", "0.00000000"], ["96660.58000000", "0.00000000"], ["96660.57000000", "0.00000000"], ["96660.35000000", "0.21301000"], ["96658.90000000", "0.00516000"], ["96658.89000000", "0.00000000"], ["96658.88000000", "0.00000000"], ["96658.75000000", "0.00000000"], ["96657.19000000", "0.21301000"], ["96656.98000000", "0.63824000"], ["96656.96000000", "0.00000000"], ["96656.56000000", "0.00000000"], ["96656.29000000", "0.00310000"], ["96656.28000000", "0.00000000"], ["96655.94000000", "0.00000000"], ["96654.96000000", "0.00000000"], ["96654.93000000", "0.31026000"], ["96654.76000000", "0.00000000"], ["96654.69000000", "0.00000000"], ["96654.68000000", "0.00000000"], ["96654.25000000", "0.21301000"], ["96654.05000000", "0.00051000"], ["96653.76000000", "0.00000000"], ["96653.61000000", "0.00000000"], ["96652.81000000", "0.76690000"], ["96652.70000000", "0.00000000"], ["96651.56000000", "0.00000000"], ["96651.27000000", "0.62039000"], ["96651.26000000", "0.21301000"], ["96651.25000000", "0.00000000"], ["96651.16000000", "0.00000000"], ["96649.95000000", "1.00000000"], ["96649.15000000", "0.00000000"], ["96648.71000000", "0.00000000"], ["96648.41000000", "0.51710000"], ["96648.39000000", "0.00000000"], ["96647.87000000", "0.00000000"], ["96647.32000000", "1.68968000"], ["96647.01000000", "0.41368000"], ["96646.82000000", "0.00000000"], ["96645.26000000", "0.00000000"], ["96645.09000000", "0.00000000"], ["96644.22000000", "0.00000000"], ["96644.08000000", "0.10439000"], ["96643.81000000", "0.74474000"], ["96643.69000000", "0.00000000"], ["96643.49000000", "0.00000000"], ["96642.59000000", "1.40221000"], ["96642.23000000", "0.00000000"], ["96642.13000000", "0.00000000"], ["96641.90000000", "0.00000000"], ["96641.61000000", "0.00000000"], ["96641.40000000", "0.00000000"], ["96641.08000000", "0.00000000"], ["96640.65000000", "1.68968000"], ["96640.56000000", "0.00000000"], ["96640.04000000", "0.00000000"], ["96639.74000000", "0.00000000"], ["96639.21000000", "0.00206000"], ["96639.00000000", "0.00000000"], ["96638.46000000", "0.21301000"], ["96637.95000000", "0.00000000"], ["96637.43000000", "0.00000000"], ["96637.23000000", "0.00000000"], ["96636.54000000", "0.00000000"], ["96635.86000000", "0.00000000"], ["96634.72000000", "0.00000000"], ["96634.36000000", "0.00000000"], ["96634.30000000", "0.00000000"], ["96634.14000000", "0.00000000"], ["96633.25000000", "0.00000000"], ["96633.05000000", "0.00000000"], ["96631.33000000", "0.56879000"], ["96630.11000000", "0.00000000"], ["96629.12000000", "0.00000000"], ["96628.94000000", "0.00000000"], ["96628.79000000", "0.00000000"], ["96626.81000000", "0.21301000"], ["96626.52000000", "2.00000000"], ["96623.40000000", "0.00000000"], ["96622.63000000", "0.00000000"], ["96622.50000000", "0.18104000"], ["96622.49000000", "0.00000000"], ["96622.36000000", "0.00000000"], ["96622.20000000", "0.21301000"], ["96622.10000000", "0.05000000"], ["96620.26000000", "0.00000000"], ["96619.44000000", "0.00000000"], ["96619.25000000", "0.21301000"], ["96617.14000000", "0.00000000"], ["96616.37000000", "0.02301000"], ["96616.35000000", "0.00000000"], ["96616.28000000", "0.21301000"], ["96615.06000000", "0.00000000"], ["96614.39000000", "0.03785000"], ["96614.00000000", "0.00000000"], ["96610.88000000", "0.00000000"], ["96609.84000000", "0.00000000"], ["96608.78000000", "0.00000000"], ["96607.74000000", "0.00000000"], ["96606.70000000", "0.00000000"], ["96604.62000000", "0.00000000"], ["96602.52000000", "0.00000000"], ["96601.48000000", "0.00000000"], ["96598.34000000", "0.00000000"], ["96596.56000000", "0.21301000"], ["96595.22000000", "0.00000000"], ["96594.06000000", "0.61001000"], ["96593.12000000", "0.00000000"], ["96349.45000000", "0.00013000"], ["96036.11000000", "0.00013000"], ["95722.77000000", "0.00013000"], ["95319.95000000", "0.00008000"], ["95223.28000000", "0.00014000"], ["95223.27000000", "0.00133000"], ["95126.61000000", "0.00224000"], ["95029.93000000", "0.00008000"], ["94933.26000000", "0.00008000"], ["91868.94000000", "0.25569000"], ["91839.71000000", "0.00010000"], ["91398.10000000", "0.25571000"], ["90929.67000000", "0.25569000"], ["90463.64000000", "0.25550000"], ["87006.04000000", "0.00000000"], ["87006.00000000", "0.00000000"], ["87005.00000000", "0.00163000"], ["77338.71000000", "0.00050000"], ["70000.00000000", "183.65395000"], ["42000.00000000", "3.70561000"], ["34802.42000000", "0.00162000"], ["33000.00000000", "2.70627000"]], "a": [["96673.39000000", "5.00324000"], ["96673.89000000", "0.05727000"], ["96674.00000000", "0.03802000"], ["96674.20000000", "0.01472000"], ["96675.99000000", "0.00000000"], ["96676.19000000", "0.00414000"], ["96676.46000000", "0.02626000"], ["96676.64000000", "0.00000000"], ["96677.47000000", "0.00012000"], ["96677.48000000", "0.21307000"], ["96677.49000000", "0.00006000"], ["96677.50000000", "0.40328000"], ["96677.60000000", "0.04882000"], ["96678.00000000", "0.03790000"], ["96678.08000000", "0.06440000"], ["96678.73000000", "0.00000000"], ["96678.80000000", "0.00000000"], ["96678.92000000", "0.00007000"], ["96679.22000000", "0.68243000"], ["96679.48000000", "0.00062000"], ["96679.59000000", "0.00000000"], ["96680.71000000", "0.00000000"], ["96681.06000000", "0.00000000"], ["96681.10000000", "0.00000000"], ["96681.76000000", "0.00000000"], ["96682.06000000", "0.00000000"], ["96682.12000000", "0.45434000"], ["96682.98000000", "0.00000000"], ["96683.31000000", "0.00000000"], ["96684.18000000", "0.00000000"], ["96684.29000000", "0.00000000"], ["96684.43000000", "0.00000000"], ["96684.57000000", "0.02025000"], ["96684.97000000", "0.00013000"], ["96684.98000000", "0.00492000"], ["96685.05000000", "0.00000000"], ["96686.72000000", "0.21301000"], ["96686.97000000", "1.16574000"], ["96688.39000000", "0.00000000"], ["96689.99000000", "0.00501000"], ["96690.96000000", "0.00516000"], ["96690.97000000", "0.00000000"], ["96691.89000000", "0.00000000"], ["96694.22000000", "0.00000000"], ["96694.35000000", "0.00000000"], ["96695.27000000", "0.62037000"], ["96698.32000000", "0.77566000"], ["96699.20000000", "0.77566000"], ["96699.69000000", "0.08900000"], ["96701.09000000", "0.00000000"], ["96701.18000000", "0.02299000"], ["96703.89000000", "1.00000000"], ["96704.52000000", "0.00000000"], ["96705.10000000", "0.00000000"], ["96705.18000000", "0.00000000"], ["96705.19000000", "0.00000000"], ["96705.39000000", "0.00000000"], ["96707.70000000", "0.00000000"], ["96707.99000000", "0.00000000"], ["96708.90000000", "0.00560000"], ["96710.50000000", "0.00000000"], ["96710.58000000", "0.77566000"], ["96713.28000000", "0.42355000"], ["96715.85000000", "0.00000000"], ["96716.40000000", "0.74418000"], ["96719.57000000", "0.00000000"], ["96721.02000000", "0.00000000"], ["96721.54000000", "0.00000000"], ["96722.06000000", "0.00000000"], ["96724.17000000", "0.03641000"], ["96730.91000000", "0.03734000"], ["96734.39000000", "2.00000000"], ["96734.65000000", "0.00927000"], ["96736.81000000", "0.00000000"], ["96736.99000000", "0.00000000"], ["96737.39000000", "0.00000000"], ["96737.85000000", "0.00707000"], ["96739.70000000", "0.00000000"], ["96741.90000000", "0.42837000"], ["96742.01000000", "0.00000000"], ["96742.59000000", "0.00000000"], ["96744.41000000", "0.00000000"], ["96746.86000000", "0.00000000"], ["96747.61000000", "0.00000000"], ["96747.77000000", "0.00560000"], ["96786.49000000", "0.28999000"], ["96825.00000000", "0.00718000"], ["96850.82000000", "0.00560000"], ["96868.56000000", "0.00636000"], ["98123.50000000", "0.00000000"]]}
{"e": "depthUpdate", "E": 1746124979014, "s": "BTCUSDT", "b": [["96673.38000000", "6.35768000"], ["96673.37000000", "0.00030000"], ["96673.09000000", "0.00024000"], ["96673.08000000", "0.25432000"], ["96671.99000000", "0.00006000"], ["96670.00000000", "0.03796000"], ["96668.00000000", "0.03796000"], ["96666.86000000", "0.21307000"], ["96666.43000000", "0.20932000"], ["96666.41000000", "0.21469000"], ["96663.97000000", "0.00000000"], ["96657.43000000", "0.48430000"], ["96653.89000000", "0.51741000"], ["96644.69000000", "1.63227000"], ["96639.21000000", "0.00000000"], ["96635.49000000", "0.74480000"], ["96635.42000000", "0.00206000"], ["96634.36000000", "0.21301000"], ["96629.95000000", "0.21301000"], ["96614.65000000", "0.17881000"], ["96596.56000000", "0.00000000"], ["96575.99000000", "0.71555000"], ["96537.32000000", "1.07376000"], ["96498.65000000", "1.43225000"], ["96444.63000000", "0.00000000"], ["96444.01000000", "0.00548000"], ["95223.27000000", "0.00033000"], ["94836.59000000", "0.00008000"], ["94739.91000000", "0.00008000"], ["94643.24000000", "0.00008000"], ["90000.00000000", "79.52129000"], ["88933.10000000", "0.00000000"], ["87006.04000000", "0.00000000"], ["87006.00000000", "0.00000000"], ["87005.00000000", "0.00163000"], ["77338.71000000", "0.00050000"], ["34802.42000000", "0.00180000"], ["33000.00000000", "2.70627000"]], "a": [["96673.39000000", "3.99989000"], ["96673.40000000", "0.00522000"], ["96674.00000000", "0.03802000"], ["96674.20000000", "0.00000000"], ["96675.99000000", "0.00006000"], ["96676.00000000", "0.04002000"], ["96676.19000000", "0.00000000"], ["96676.34000000", "0.00000000"], ["96677.47000000", "0.00006000"], ["96677.49000000", "0.00000000"], ["96677.50000000", "0.40334000"], ["96678.38000000", "0.01466000"], ["96678.60000000", "0.00000000"], ["96681.55000000", "0.00103000"], ["96682.39000000", "0.00000000"], ["96683.06000000", "0.00567000"], ["96683.40000000", "0.00999000"], ["96684.06000000", "0.00000000"], ["96685.06000000", "0.00000000"], ["96686.06000000", "0.00000000"], ["96687.06000000", "0.00000000"], ["96688.06000000", "0.00000000"], ["96691.55000000", "0.10151000"], ["96694.23000000", "0.00000000"], ["96705.55000000", "0.00925000"], ["96715.25000000", "0.00916000"], ["96716.13000000", "0.17862000"], ["96721.40000000", "0.74414000"], ["96724.57000000", "0.00532000"], ["96730.32000000", "0.00916000"], ["96733.05000000", "0.86347000"], ["96754.79000000", "0.35710000"], ["96759.48000000", "0.00523000"], ["96772.03000000", "0.00916000"], ["96793.46000000", "0.53545000"], ["96797.78000000", "0.00925000"], ["96801.96000000", "0.00557000"], ["96811.46000000", "0.00890000"], ["96831.11000000", "0.00521000"], ["96832.12000000", "1.42741000"], ["96859.89000000", "0.00916000"], ["96874.96000000", "0.00523000"], ["98123.50000000", "0.00100000"]]}
{"e": "depthUpdate", "E": 1746124980014, "s": "BTCUSDT", "b": [["96673.00000000", "0.00018000"], ["96670.00000000", "0.03796000"], ["96669.87000000", "0.21307000"], ["96668.74000000", "0.00000000"], ["96668.73000000", "0.00000000"], ["96666.86000000", "0.21307000"], ["96666.66000000", "0.06288000"], ["96656.22000000", "0.00000000"], ["96647.33000000", "0.00000000"], ["96647.31000000", "0.00000000"], ["96645.12000000", "1.67319000"], ["96644.69000000", "0.00000000"], ["96642.44000000", "0.00000000"], ["96638.46000000", "0.00000000"], ["96637.66000000", "0.10005000"], ["96580.01000000", "0.77634000"], ["96531.94000000", "0.00000000"], ["96528.76000000", "2.69714000"], ["95223.27000000", "0.00133000"], ["87006.04000000", "0.00000000"], ["87006.00000000", "0.00000000"], ["77338.71000000", "0.00050000"], ["70000.00000000", "183.65395000"], ["34802.42000000", "0.00198000"], ["33000.00000000", "2.70627000"], ["20002.00000000", "0.00000000"]], "a": [["96673.39000000", "4.20950000"], ["96679.59000000", "0.07919000"], ["96687.55000000", "0.00310000"], ["96687.65000000", "0.00000000"], ["96689.06000000", "0.00000000"], ["96690.06000000", "0.00000000"], ["96694.71000000", "0.00877000"], ["96700.57000000", "0.00890000"], ["96701.61000000", "0.00000000"], ["96701.83000000", "0.00000000"], ["96705.84000000", "1.62435000"], ["96706.13000000", "0.00000000"], ["96710.59000000", "0.00916000"], ["96721.39000000", "0.84990000"], ["96723.06000000", "0.00000000"], ["96752.79000000", "0.00497000"], ["96763.81000000", "0.00890000"], ["96767.71000000", "0.00890000"], ["96777.50000000", "0.05693000"], ["96782.81000000", "0.00916000"], ["96807.85000000", "0.00890000"], ["96808.24000000", "0.01722000"], ["96844.52000000", "0.00952000"], ["96853.94000000", "0.00497000"], ["96865.23000000", "0.00572000"], ["98123.50000000", "0.00000000"], ["99000.00000000", "86.32643000"]]}
{"e": "depthUpdate", "E": 1746124981014, "s": "BTCUSDT", "b": [["96673.38000000", "6.35757000"], ["96662.01000000", "0.00000000"], ["96660.88000000", "0.00000000"], ["96658.90000000", "0.00000000"], ["96657.45000000", "1.35782000"], ["96657.44000000", "1.69484000"], ["96656.98000000", "0.00000000"], ["96649.95000000", "0.00000000"], ["96649.75000000", "1.00000000"], ["96648.19000000", "0.00000000"], ["96647.33000000", "1.95250000"], ["96643.47000000", "0.00008000"], ["96636.60000000", "0.00000000"], ["96626.52000000", "0.00000000"], ["96626.12000000", "2.00000000"], ["96623.00000000", "0.00000000"], ["95442.71000000", "0.04105000"], ["95223.27000000", "0.00133000"], ["87006.04000000", "0.00000000"], ["87006.00000000", "0.00000000"], ["87005.00000000", "0.00163000"], ["77338.71000000", "0.00050000"], ["60000.00000000", "80.85283000"], ["34802.42000000", "0.00216000"], ["33000.00000000", "2.70627000"]], "a": [["96673.39000000", "3.28864000"], ["96677.48000000", "0.21307000"], ["96677.50000000", "0.00000000"], ["96677.60000000", "0.00742000"], ["96678.00000000", "0.03796000"], ["96686.72000000", "0.00000000"], ["96687.51000000", "0.00310000"], ["96687.54000000", "0.00000000"], ["96687.55000000", "0.00000000"], ["96695.27000000", "0.00000000"], ["96698.31000000", "0.62035000"], ["96701.61000000", "2.24159000"], ["96703.69000000", "1.00000000"], ["96703.89000000", "0.00000000"], ["96706.82000000", "0.00000000"], ["96720.44000000", "0.00992000"], ["96724.17000000", "0.00000000"], ["96733.05000000", "0.86347000"], ["96733.99000000", "2.00000000"], ["96734.39000000", "0.00000000"], ["96735.34000000", "0.03641000"], ["96740.25000000", "0.00000000"], ["96744.48000000", "0.00398000"], ["96792.99000000", "0.00841000"], ["96816.39000000", "0.00405000"], ["96820.46000000", "0.00433000"], ["96834.86000000", "0.00976000"], ["96841.52000000", "0.00992000"], ["98123.50000000", "0.00100000"]]}
{"e": "depthUpdate", "E": 1746124982014, "s": "BTCUSDT", "b": [["96673.38000000", "6.33133000"], ["96662.79000000", "0.02024000"], ["96649.75000000", "0.00000000"], ["96647.46000000", "1.00000000"], ["96647.33000000", "1.45055000"], ["96645.13000000", "1.61439000"], ["96645.12000000", "0.00000000"], ["96644.38000000", "0.10136000"], ["96637.66000000", "0.00000000"], ["96626.12000000", "0.00000000"], ["96621.54000000", "2.00000000"], ["96564.03000000", "0.01617000"], ["96444.63000000", "0.00548000"], ["96444.01000000", "0.00000000"], ["96435.73000000", "0.00000000"], ["96415.27000000", "0.02974000"], ["95790.00000000", "0.00086000"], ["95706.64000000", "0.00000000"], ["95442.71000000", "0.00000000"], ["95223.27000000", "0.00033000"], ["87006.04000000", "0.00000000"], ["87006.00000000", "0.00000000"], ["87005.00000000", "0.00163000"], ["77338.71000000", "0.00050000"], ["70000.00000000", "183.65395000"], ["60000.00000000", "80.85273000"], ["34802.42000000", "0.00234000"], ["33000.00000000", "2.70627000"]], "a": [["96673.39000000", "4.36688000"], ["96686.63000000", "0.39071000"], ["96686.96000000", "0.00000000"], ["96691.55000000", "0.00000000"], ["96696.17000000", "0.10000000"], ["96701.83000000", "0.00774000"], ["96705.78000000", "1.62632000"], ["96705.84000000", "0.00000000"], ["96728.63000000", "0.01617000"], ["97124.30000000", "0.02952000"], ["97142.55000000", "0.00025000"], ["98123.50000000", "0.00000000"]]}
{"e": "depthUpdate", "E": 1746124983014, "s": "BTCUSDT", "b": [["96673.38000000", "6.31644000"], ["96673.09000000", "0.00024000"], ["96673.08000000", "0.24807000"], ["96673.00000000", "0.00007000"], ["96670.00000000", "0.03796000"], ["96669.87000000", "0.00000000"], ["96668.55000000", "0.00517000"], ["96666.66000000", "0.06294000"], ["96666.43000000", "0.20938000"], ["96666.41000000", "0.21469000"], ["96662.57000000", "0.00417000"], ["96657.45000000", "0.64994000"], ["96657.44000000", "0.00516000"], ["96657.43000000", "0.00000000"], ["96649.54000000", "1.00000000"], ["96647.98000000", "0.00000000"], ["96647.46000000", "0.00000000"], ["96645.37000000", "0.00000000"], ["96645.13000000", "0.00000000"], ["96643.83000000", "1.61936000"], ["96635.42000000", "0.00000000"], ["96634.36000000", "0.21301000"], ["96632.52000000", "0.00206000"], ["96625.70000000", "2.00000000"], ["96622.58000000", "0.00000000"], ["96621.54000000", "0.00000000"], ["96618.99000000", "0.86894000"], ["96617.36000000", "0.00000000"], ["96616.37000000", "0.00000000"], ["96611.15000000", "0.00000000"], ["96608.54000000", "0.00774000"], ["96604.37000000", "0.01534000"], ["96582.98000000", "0.00000000"], ["96564.03000000", "0.00000000"], ["96525.98000000", "0.01617000"], ["96517.68000000", "0.15924000"], ["96506.95000000", "0.00000000"], ["95693.34000000", "0.00000000"], ["95596.68000000", "0.00000000"], ["95500.02000000", "0.00000000"], ["95403.36000000", "0.00000000"], ["95223.27000000", "0.00133000"], ["94737.69000000", "0.00006000"], ["87006.04000000", "0.00000000"], ["87006.00000000", "0.00000000"], ["87005.00000000", "0.00163000"], ["77338.71000000", "0.00050000"], ["34802.42000000", "0.00252000"], ["33000.00000000", "2.70627000"]], "a": [["96673.39000000", "4.36490000"], ["96677.48000000", "0.21307000"], ["96677.60000000", "0.04888000"], ["96678.00000000", "0.03790000"], ["96679.21000000", "1.10558000"], ["96680.72000000", "0.00000000"], ["96680.78000000", "0.03518000"], ["96680.98000000", "0.51794000"], ["96686.63000000", "0.00000000"], ["96686.96000000", "0.21301000"], ["96690.22000000", "0.02299000"], ["96701.18000000", "0.00000000"], ["96728.63000000", "0.00000000"], ["96763.04000000", "0.01617000"], ["96812.47000000", "1.33332000"], ["96815.65000000", "0.00000000"], ["98123.50000000", "0.00100000"]]}
{"e": "depthUpdate", "E": 1746124984014, "s": "BTCUSDT", "b": [["96673.38000000", "0.06617000"], ["96673.37000000", "0.00142000"], ["96673.35000000", "0.00006000"], ["96673.32000000", "0.00006000"], ["96673.10000000", "0.00000000"], ["96673.09000000", "0.00000000"], ["96673.08000000", "0.00000000"], ["96673.07000000", "0.00000000"], ["96673.00000000", "0.00000000"], ["96672.96000000", "0.00006000"], ["96672.39000000", "0.00000000"], ["96671.99000000", "0.00000000"], ["96671.84000000", "0.00000000"], ["96671.53000000", "0.00013000"], ["96671.52000000", "0.00000000"], ["96671.44000000", "0.00050000"], ["96671.20000000", "0.00000000"], ["96671.03000000", "0.00006000"], ["96670.16000000", "0.00000000"], ["96670.01000000", "0.00032000"], ["96670.00000000", "0.00000000"], ["96669.98000000", "0.00000000"], ["96669.10000000", "0.00006000"], ["96668.83000000", "0.00000000"], ["96668.55000000", "0.00517000"], ["96668.33000000", "0.00000000"], ["96668.26000000", "0.00000000"], ["96668.01000000", "0.00000000"], ["96668.00000000", "0.00000000"], ["96667.57000000", "0.00000000"], ["96666.89000000", "0.00012000"], ["96666.88000000", "0.23827000"], ["96666.86000000", "0.00000000"], ["96666.67000000", "0.00016000"], ["96666.66000000", "0.06300000"], ["96666.60000000", "0.00000000"], ["96666.59000000", "0.00000000"], ["96666.50000000", "0.00000000"], ["96666.49000000", "0.00000000"], ["96666.43000000", "0.00000000"], ["96666.42000000", "0.00000000"], ["96666.41000000", "0.04657000"], ["96666.24000000", "0.68264000"], ["96666.19000000", "0.00000000"], ["96666.01000000", "0.00000000"], ["96666.00000000", "0.03796000"], ["96665.52000000", "0.00414000"], ["96665.41000000", "0.00000000"], ["96664.86000000", "0.01472000"], ["96664.81000000", "0.00000000"], ["96664.80000000", "0.04146000"], ["96664.27000000", "0.00000000"], ["96664.00000000", "0.03796000"], ["96663.86000000", "0.00000000"], ["96663.66000000", "0.00000000"], ["96663.57000000", "0.00000000"], ["96663.56000000", "0.00000000"], ["96662.94000000", "0.00094000"], ["96662.79000000", "0.00006000"], ["96662.76000000", "0.00000000"], ["96662.75000000", "0.00000000"], ["96662.00000000", "0.03796000"], ["96661.93000000", "0.00000000"], ["96661.88000000", "0.00090000"], ["96661.56000000", "0.00000000"], ["96661.26000000", "0.00090000"], ["96661.16000000", "0.00000000"], ["96660.64000000", "0.00090000"], ["96660.46000000", "0.00000000"], ["96660.35000000", "0.00000000"], ["96660.12000000", "0.21301000"], ["96660.00000000", "0.03796000"], ["96659.60000000", "0.00000000"], ["96659.52000000", "0.00000000"], ["96659.07000000", "0.00000000"], ["96658.77000000", "0.03105000"], ["96658.60000000", "0.00000000"], ["96658.36000000", "0.02000000"], ["96658.26000000", "0.00011000"], ["96658.16000000", "0.12116000"], ["96657.45000000", "0.63766000"], ["96657.44000000", "0.00000000"], ["96657.11000000", "0.00000000"], ["96656.70000000", "0.00000000"], ["96656.49000000", "0.19948000"], ["96655.43000000", "0.00000000"], ["96655.42000000", "0.00000000"], ["96655.04000000", "0.00000000"], ["96654.87000000", "0.04000000"], ["96654.75000000", "0.00000000"], ["96654.13000000", "0.00000000"], ["96653.62000000", "0.00000000"], ["96653.38000000", "0.00000000"], ["96652.81000000", "0.35680000"], ["96651.91000000", "0.48704000"], ["96651.27000000", "0.00000000"], ["96650.62000000", "0.16000000"], ["96650.53000000", "0.00000000"], ["96649.65000000", "0.00000000"], ["96649.54000000", "0.00000000"], ["96649.47000000", "0.00000000"], ["96648.29000000", "0.00000000"], ["96647.77000000", "0.00000000"], ["96647.73000000", "0.00000000"], ["96647.46000000", "0.00000000"], ["96647.33000000", "0.62710000"], ["96647.32000000", "0.00000000"], ["96646.55000000", "0.00000000"], ["96646.20000000", "0.00000000"], ["96645.61000000", "0.00517000"], ["96644.73000000", "0.00000000"], ["96644.64000000", "0.00000000"], ["96644.39000000", "0.00051000"], ["96644.38000000", "0.00010000"], ["96644.08000000", "0.00000000"], ["96643.83000000", "0.00000000"], ["96643.81000000", "0.00000000"], ["96642.93000000", "0.00000000"], ["96641.76000000", "0.00464000"], ["96640.78000000", "0.00000000"], ["96640.64000000", "0.00000000"], ["96640.50000000", "1.67683000"], ["96640.43000000", "1.00000000"], ["96640.27000000", "0.00000000"], ["96640.10000000", "0.10273000"], ["96639.99000000", "0.74477000"], ["96639.93000000", "0.00000000"], ["96638.93000000", "0.00000000"], ["96638.39000000", "0.00000000"], ["96637.61000000", "0.00000000"], ["96637.43000000", "0.00000000"], ["96636.23000000", "0.00000000"], ["96635.83000000", "0.00000000"], ["96635.53000000", "0.00000000"], ["96634.36000000", "0.00000000"], ["96633.73000000", "0.00008000"], ["96633.55000000", "0.00000000"], ["96633.32000000", "0.00000000"], ["96632.52000000", "0.00000000"], ["96632.19000000", "0.00000000"], ["96632.03000000", "0.00000000"], ["96631.34000000", "0.62052000"], ["96629.95000000", "0.00000000"], ["96629.81000000", "0.74485000"], ["96629.05000000", "0.77566000"], ["96628.98000000", "0.00000000"], ["96628.97000000", "0.00000000"], ["96627.36000000", "0.00000000"], ["96626.82000000", "0.00000000"], ["96626.81000000", "0.21301000"], ["96625.70000000", "0.00000000"], ["96623.08000000", "0.83660000"], ["96622.51000000", "0.00206000"], ["96622.16000000", "0.00000000"], ["96622.10000000", "0.00000000"], ["96621.54000000", "0.00000000"], ["96619.21000000", "0.00000000"], ["96619.02000000", "0.00000000"], ["96615.90000000", "0.00000000"], ["96614.39000000", "0.00000000"], ["96612.48000000", "0.00000000"], ["96612.00000000", "0.00220000"], ["96611.94000000", "0.05000000"], ["96608.54000000", "0.00007000"], ["96607.48000000", "2.00000000"], ["96606.48000000", "0.00000000"], ["96604.48000000", "0.00000000"], ["96604.37000000", "0.00000000"], ["96601.76000000", "0.00000000"], ["96601.48000000", "0.00000000"], ["96600.72000000", "0.54000000"], ["96600.17000000", "0.00000000"], ["96599.01000000", "0.00000000"], ["96598.28000000", "0.00000000"], ["96597.68000000", "0.00000000"], ["96597.07000000", "0.00000000"], ["96596.03000000", "0.00000000"], ["96594.08000000", "0.00000000"], ["96590.68000000", "0.00000000"], ["96590.29000000", "0.02301000"], ["96586.98000000", "0.03785000"], ["96583.06000000", "0.00000000"], ["96579.40000000", "0.03693000"], ["96577.77000000", "0.00000000"], ["96554.89000000", "0.11139000"], ["96543.18000000", "0.16537000"], ["96528.76000000", "0.00000000"], ["96525.98000000", "0.00000000"], ["96524.02000000", "0.00000000"], ["96523.39000000", "0.01036000"], ["96387.20000000", "0.00000000"], ["96347.67000000", "0.03786000"], ["96341.08000000", "0.00000000"], ["95306.70000000", "0.00000000"], ["95223.27000000", "0.00133000"], ["95210.04000000", "0.00000000"], ["95113.38000000", "0.00000000"], ["95016.72000000", "0.00000000"], ["88933.10000000", "0.00012000"], ["87006.04000000", "0.00000000"], ["87006.00000000", "0.00000000"], ["87005.00000000", "0.00163000"], ["77338.71000000", "0.00050000"], ["70000.00000000", "183.65395000"], ["34802.42000000", "0.00306000"], ["33000.00000000", "2.70627000"], ["20002.00000000", "0.00100000"]], "a": [["96673.39000000", "5.58066000"], ["96673.40000000", "0.00408000"], ["96673.42000000", "0.00040000"], ["96673.70000000", "0.00024000"], ["96673.75000000", "0.00018000"], ["96673.76000000", "0.07937000"], ["96673.88000000", "0.11053000"], ["96673.89000000", "0.00006000"], ["96673.90000000", "0.04216000"], ["96673.91000000", "0.01892000"], ["96673.99000000", "0.00000000"], ["96674.00000000", "0.03802000"], ["96674.04000000", "0.68258000"], ["96675.03000000", "0.00000000"], ["96675.13000000", "0.41670000"], ["96675.84000000", "0.00000000"], ["96675.88000000", "0.01040000"], ["96675.89000000", "0.00000000"], ["96675.99000000", "0.00000000"], ["96676.40000000", "0.01714000"], ["96676.46000000", "0.00000000"], ["96676.49000000", "0.00000000"], ["96676.50000000", "0.00000000"], ["96676.79000000", "0.00414000"], ["96677.10000000", "0.00517000"], ["96677.47000000", "0.00000000"], ["96677.48000000", "0.21301000"], ["96677.60000000", "0.04140000"], ["96677.80000000", "0.02068000"], ["96677.99000000", "0.62048000"], ["96678.00000000", "0.03790000"], ["96678.17000000", "0.04000000"], ["96678.38000000", "0.00000000"], ["96679.20000000", "0.00000000"], ["96679.22000000", "0.00000000"], ["96679.47000000", "0.00000000"], ["96680.31000000", "0.00000000"], ["96680.72000000", "0.00000000"], ["96680.81000000", "0.06000000"], ["96680.98000000", "0.00000000"], ["96681.30000000", "0.00000000"], ["96682.07000000", "0.00000000"], ["96682.11000000", "0.00517000"], ["96683.40000000", "0.00000000"], ["96683.81000000", "0.00000000"], ["96684.00000000", "0.04340000"], ["96684.83000000", "0.00310000"], ["96685.96000000", "0.00000000"], ["96686.79000000", "0.21301000"], ["96686.89000000", "0.00000000"], ["96686.95000000", "0.02068000"], ["96686.96000000", "0.00000000"], ["96687.00000000", "0.54000000"], ["96687.11000000", "0.00000000"], ["96687.24000000", "0.00000000"], ["96687.51000000", "0.00000000"], ["96687.67000000", "0.00000000"], ["96688.67000000", "0.00000000"], ["96689.17000000", "0.03999000"], ["96689.38000000", "0.00000000"], ["96689.47000000", "0.00000000"], ["96689.77000000", "0.00000000"], ["96690.22000000", "0.00000000"], ["96690.49000000", "0.10080000"], ["96690.69000000", "0.00000000"], ["96690.96000000", "0.00000000"], ["96691.37000000", "0.00000000"], ["96691.89000000", "0.10288000"], ["96691.99000000", "0.00000000"], ["96692.19000000", "0.00000000"], ["96692.87000000", "0.00000000"], ["96693.34000000", "0.00000000"], ["96693.47000000", "0.00000000"], ["96693.87000000", "0.00000000"], ["96694.89000000", "1.00000000"], ["96696.17000000", "0.00000000"], ["96696.87000000", "0.00000000"], ["96696.97000000", "0.74433000"], ["96697.87000000", "0.00000000"], ["96698.31000000", "0.00000000"], ["96698.39000000", "0.00000000"], ["96698.43000000", "0.05196000"], ["96698.49000000", "0.00000000"], ["96699.57000000", "0.00000000"], ["96699.65000000", "0.03734000"], ["96699.68000000", "0.05196000"], ["96700.44000000", "0.00000000"], ["96701.82000000", "0.05196000"], ["96701.95000000", "0.00000000"], ["96702.40000000", "0.01481000"], ["96702.47000000", "0.00000000"], ["96703.13000000", "0.10394000"], ["96703.69000000", "0.00000000"], ["96703.91000000", "0.74428000"], ["96704.00000000", "0.00211000"], ["96704.46000000", "0.03641000"], ["96704.52000000", "0.05197000"], ["96705.04000000", "0.00000000"], ["96705.55000000", "0.00925000"], ["96705.56000000", "0.03105000"], ["96706.15000000", "0.00000000"], ["96706.21000000", "0.09838000"], ["96706.61000000", "0.00000000"], ["96708.06000000", "0.74424000"], ["96709.35000000", "0.00000000"], ["96710.14000000", "0.00000000"], ["96711.43000000", "0.00000000"], ["96711.62000000", "0.00000000"], ["96712.35000000", "0.00000000"], ["96713.29000000", "0.00103000"], ["96713.55000000", "0.00000000"], ["96714.35000000", "0.00000000"], ["96714.41000000", "0.00000000"], ["96715.58000000", "0.00000000"], ["96716.39000000", "2.00000000"], ["96716.40000000", "0.00000000"], ["96716.89000000", "0.07860000"], ["96719.31000000", "0.01551000"], ["96719.60000000", "0.00000000"], ["96719.70000000", "0.00000000"], ["96721.39000000", "0.61573000"], ["96721.40000000", "0.00000000"], ["96722.35000000", "0.00000000"], ["96723.39000000", "0.00000000"], ["96723.59000000", "0.00000000"], ["96724.14000000", "0.01034000"], ["96725.51000000", "0.00000000"], ["96725.65000000", "0.00000000"], ["96725.75000000", "0.00000000"], ["96725.94000000", "0.02832000"], ["96726.83000000", "0.00490000"], ["96729.13000000", "0.00000000"], ["96730.35000000", "0.00000000"], ["96730.91000000", "0.00000000"], ["96731.55000000", "0.00000000"], ["96733.05000000", "0.29793000"], ["96733.99000000", "0.00000000"], ["96734.61000000", "0.00000000"], ["96735.34000000", "0.00000000"], ["96735.67000000", "0.00000000"], ["96737.73000000", "0.00000000"], ["96739.02000000", "0.00000000"], ["96741.90000000", "0.00000000"], ["96742.38000000", "0.00000000"], ["96743.28000000", "0.00000000"], ["96743.47000000", "0.00000000"], ["96743.73000000", "0.00000000"], ["96748.58000000", "0.00000000"], ["96753.89000000", "0.00000000"], ["96754.78000000", "0.44179000"], ["96755.31000000", "0.00006000"], ["96756.74000000", "0.11139000"], ["96760.15000000", "0.00000000"], ["96760.66000000", "0.11141000"], ["96763.04000000", "0.00000000"], ["96764.25000000", "0.00000000"], ["96768.83000000", "0.00000000"], ["96773.38000000", "0.00000000"], ["96776.37000000", "0.00000000"], ["96778.97000000", "0.00000000"], ["96783.94000000", "0.00000000"], ["96787.59000000", "0.00000000"], ["96793.31000000", "0.00000000"], ["96793.73000000", "0.00000000"], ["96795.32000000", "0.00000000"], ["96798.36000000", "0.00000000"], ["96802.06000000", "0.00000000"], ["96803.21000000", "0.00000000"], ["96803.69000000", "0.00000000"], ["96803.70000000", "0.00000000"], ["96805.02000000", "0.00000000"], ["96806.05000000", "0.00000000"], ["96807.71000000", "0.03929000"], ["96808.26000000", "0.00000000"], ["96811.01000000", "0.00000000"], ["96811.68000000", "0.00000000"], ["96812.47000000", "0.00000000"], ["96812.68000000", "0.00000000"], ["96812.96000000", "0.00000000"], ["96813.04000000", "0.00000000"], ["96813.37000000", "0.00000000"], ["96813.56000000", "0.00000000"], ["96814.33000000", "0.00019000"], ["96815.64000000", "0.00000000"], ["96816.58000000", "0.00000000"], ["96817.82000000", "0.00000000"], ["96822.45000000", "0.00000000"], ["96827.68000000", "0.00000000"], ["96831.66000000", "0.00000000"], ["96837.27000000", "0.00000000"], ["96840.96000000", "0.00000000"], ["96846.04000000", "0.00008000"], ["96851.55000000", "0.00000000"], ["96855.82000000", "0.00000000"], ["96860.27000000", "0.00010000"], ["97372.80000000", "0.05175000"], ["97411.44000000", "0.00000000"], ["98123.50000000", "0.00000000"]]}
{"e": "depthUpdate", "E": 1746124985014, "s": "BTCUSDT", "b": [["96673.38000000", "3.45215000"], ["96673.37000000", "0.00102000"], ["96673.32000000", "0.00006000"], ["96672.96000000", "0.00000000"], ["96672.87000000", "0.00006000"], ["96672.86000000", "0.00006000"], ["96672.21000000", "0.00018000"], ["96672.20000000", "0.29375000"], ["96672.19000000", "0.23851000"], ["96671.64000000", "0.00000000"], ["96671.53000000", "0.00007000"], ["96671.44000000", "0.00044000"], ["96671.43000000", "0.00012000"], ["96671.42000000", "0.68254000"], ["96671.20000000", "0.00000000"], ["96671.11000000", "0.00000000"], ["96670.00000000", "0.00011000"], ["96669.92000000", "0.00000000"], ["96669.58000000", "0.00000000"], ["96669.57000000", "0.00000000"], ["96669.35000000", "0.00000000"], ["96669.10000000", "0.00006000"], ["96667.30000000", "0.00000000"], ["96667.29000000", "0.00000000"], ["96666.91000000", "0.26501000"], ["96666.90000000", "0.00000000"], ["96666.89000000", "0.00000000"], ["96666.88000000", "0.00000000"], ["96666.66000000", "0.06294000"], ["96666.47000000", "0.00000000"], ["96666.41000000", "0.04645000"], ["96666.25000000", "0.00000000"], ["96666.24000000", "0.00000000"], ["96666.00000000", "0.03796000"], ["96665.55000000", "0.19954000"], ["96665.52000000", "0.00000000"], ["96664.86000000", "0.00000000"], ["96664.80000000", "0.04146000"], ["96664.74000000", "0.00000000"], ["96664.00000000", "0.03790000"], ["96663.85000000", "0.00103000"], ["96663.16000000", "0.21301000"], ["96662.00000000", "0.03790000"], ["96661.93000000", "0.00008000"], ["96661.88000000", "0.00000000"], ["96661.26000000", "0.00000000"], ["96660.13000000", "0.14715000"], ["96657.88000000", "0.44618000"], ["96656.49000000", "0.00000000"], ["96655.50000000", "0.00560000"], ["96654.04000000", "0.00000000"], ["96654.01000000", "0.00517000"], ["96652.81000000", "0.55865000"], ["96651.91000000", "0.00000000"], ["96651.71000000", "0.00999000"], ["96649.77000000", "0.04800000"], ["96649.65000000", "0.62040000"], ["96649.37000000", "0.00000000"], ["96648.30000000", "0.02079000"], ["96648.23000000", "0.00000000"], ["96647.33000000", "0.45928000"], ["96646.86000000", "0.04800000"], ["96646.63000000", "0.00000000"], ["96646.56000000", "1.68968000"], ["96646.53000000", "0.00000000"], ["96645.76000000", "0.12439000"], ["96645.63000000", "0.00000000"], ["96645.61000000", "0.00000000"], ["96644.89000000", "0.04800000"], ["96644.66000000", "0.74473000"], ["96644.43000000", "0.00000000"], ["96644.37000000", "0.02824000"], ["96642.83000000", "0.00000000"], ["96641.73000000", "0.00000000"], ["96641.14000000", "0.00000000"], ["96640.67000000", "0.02300000"], ["96640.51000000", "0.00000000"], ["96640.50000000", "0.00000000"], ["96640.43000000", "1.00000000"], ["96640.10000000", "0.16713000"], ["96639.91000000", "0.00000000"], ["96639.39000000", "0.00000000"], ["96637.83000000", "0.00000000"], ["96637.34000000", "0.03999000"], ["96635.41000000", "0.00000000"], ["96634.36000000", "0.00000000"], ["96633.72000000", "1.04004000"], ["96633.71000000", "0.74482000"], ["96632.51000000", "0.00000000"], ["96631.34000000", "0.00000000"], ["96631.33000000", "0.00000000"], ["96629.95000000", "0.21301000"], ["96629.81000000", "0.00000000"], ["96623.26000000", "0.01034000"], ["96623.08000000", "0.83660000"], ["96620.23000000", "0.00000000"], ["96619.88000000", "0.00000000"], ["96619.68000000", "0.00000000"], ["96617.88000000", "0.00000000"], ["96617.83000000", "0.31026000"], ["96615.48000000", "0.00000000"], ["96612.28000000", "0.00000000"], ["96611.94000000", "0.00000000"], ["96611.92000000", "0.00520000"], ["96610.08000000", "0.00000000"], ["96609.22000000", "0.03785000"], ["96607.48000000", "2.00000000"], ["96606.44000000", "0.00000000"], ["96606.32000000", "0.03693000"], ["96605.40000000", "0.00000000"], ["96602.33000000", "0.00000000"], ["96602.28000000", "0.00000000"], ["96600.39000000", "0.00000000"], ["96590.29000000", "0.00000000"], ["96588.63000000", "0.00560000"], ["96586.98000000", "0.00000000"], ["96582.92000000", "0.04800000"], ["96580.02000000", "0.00000000"], ["96579.95000000", "0.00178000"], ["96579.40000000", "0.00000000"], ["96573.63000000", "0.00000000"], ["96571.18000000", "0.00000000"], ["96567.69000000", "0.03348000"], ["96562.69000000", "0.00000000"], ["96522.38000000", "2.69714000"], ["96444.63000000", "0.00000000"], ["96444.01000000", "0.00548000"], ["95223.27000000", "0.00033000"], ["94920.06000000", "0.00000000"], ["94823.40000000", "0.00000000"], ["94726.74000000", "0.00000000"], ["94630.08000000", "0.00000000"], ["88933.10000000", "0.00000000"], ["87006.04000000", "0.00000000"], ["87006.00000000", "0.00000000"], ["87005.00000000", "0.00163000"], ["77338.71000000", "0.00050000"], ["34802.42000000", "0.00324000"], ["33000.00000000", "2.70627000"], ["20002.00000000", "0.00000000"]], "a": [["96673.39000000", "6.40136000"], ["96673.76000000", "0.07937000"], ["96673.87000000", "0.00018000"], ["96673.88000000", "0.36393000"], ["96673.89000000", "0.00000000"], ["96673.90000000", "0.04228000"], ["96673.91000000", "0.70138000"], ["96674.00000000", "0.03796000"], ["96674.03000000", "0.00000000"], ["96674.04000000", "0.00006000"], ["96675.12000000", "0.00000000"], ["96675.45000000", "0.00103000"], ["96675.49000000", "0.00000000"], ["96676.00000000", "0.03996000"], ["96676.05000000", "0.00000000"], ["96676.20000000", "0.00724000"], ["96676.40000000", "0.01720000"], ["96676.77000000", "0.00999000"], ["96676.88000000", "0.00000000"], ["96677.10000000", "0.00000000"], ["96677.80000000", "0.00000000"], ["96677.99000000", "0.00000000"], ["96679.21000000", "0.70773000"], ["96679.28000000", "0.02000000"], ["96680.30000000", "0.10080000"], ["96681.21000000", "0.00000000"], ["96681.28000000", "0.00000000"], ["96681.55000000", "0.00000000"], ["96682.11000000", "0.00000000"], ["96683.20000000", "0.09600000"], ["96683.37000000", "0.00310000"], ["96684.08000000", "0.09120000"], ["96684.82000000", "0.00530000"], ["96684.83000000", "0.00000000"], ["96684.97000000", "0.00000000"], ["96685.10000000", "0.08160000"], ["96685.13000000", "0.07680000"], ["96685.35000000", "0.00000000"], ["96686.79000000", "0.00000000"], ["96686.94000000", "0.21301000"], ["96689.16000000", "0.00000000"], ["96689.21000000", "0.85052000"], ["96689.55000000", "0.00000000"], ["96690.49000000", "0.00000000"], ["96692.79000000", "0.62039000"], ["96693.39000000", "0.00000000"], ["96694.36000000", "0.00000000"], ["96694.42000000", "0.00000000"], ["96694.89000000", "0.00000000"], ["96695.34000000", "0.00000000"], ["96695.42000000", "0.00000000"], ["96695.67000000", "1.00000000"], ["96695.93000000", "0.00000000"], ["96696.45000000", "0.00000000"], ["96696.77000000", "0.00000000"], ["96696.97000000", "0.00000000"], ["96697.50000000", "0.00000000"], ["96698.37000000", "0.00000000"], ["96699.42000000", "0.74431000"], ["96699.57000000", "0.00000000"], ["96699.65000000", "0.00000000"], ["96700.57000000", "0.00890000"], ["96702.17000000", "0.00000000"], ["96704.46000000", "0.00000000"], ["96705.78000000", "0.00000000"], ["96709.34000000", "0.00000000"], ["96713.28000000", "0.00000000"], ["96713.72000000", "0.43067000"], ["96713.94000000", "0.74420000"], ["96714.92000000", "0.00000000"], ["96715.62000000", "0.02298000"], ["96716.39000000", "0.00000000"], ["96717.02000000", "0.03641000"], ["96717.95000000", "2.00000000"], ["96718.47000000", "0.00464000"], ["96719.36000000", "0.00103000"], ["96719.51000000", "0.00000000"], ["96720.15000000", "0.00000000"], ["96721.61000000", "0.00000000"], ["96723.35000000", "0.00000000"], ["96725.75000000", "0.00000000"], ["96725.82000000", "0.03734000"], ["96727.75000000", "0.00000000"], ["96729.04000000", "0.00103000"], ["96730.95000000", "0.00000000"], ["96738.71000000", "0.00103000"], ["96738.81000000", "0.00000000"], ["96741.90000000", "0.30700000"], ["96748.38000000", "0.00103000"], ["96752.12000000", "0.00000000"], ["96756.74000000", "0.00000000"], ["96760.66000000", "0.00000000"], ["96766.80000000", "0.00178000"], ["96766.85000000", "0.00000000"], ["96768.45000000", "0.00000000"], ["96768.79000000", "0.00000000"], ["96774.83000000", "0.04996000"], ["96776.48000000", "0.00357000"], ["96778.28000000", "0.00000000"], ["96779.74000000", "0.04996000"], ["96785.25000000", "0.11139000"], ["96787.97000000", "0.11141000"], ["96808.24000000", "0.00000000"], ["98123.50000000", "0.00100000"]]}
{"e": "depthUpdate", "E": 1746124986014, "s": "BTCUSDT", "b": [["96673.38000000", "3.45072000"], ["96673.37000000", "0.00120000"], ["96673.32000000", "0.00006000"], ["96673.00000000", "0.00013000"], ["96672.21000000", "0.00012000"], ["96671.42000000", "0.68254000"], ["96669.70000000", "0.00414000"], ["96669.69000000", "0.01886000"], ["96667.25000000", "0.21307000"], ["96666.91000000", "0.19426000"], ["96665.55000000", "0.19948000"], ["96665.35000000", "0.02747000"], ["96664.80000000", "0.04140000"], ["96654.02000000", "0.00999000"], ["96653.44000000", "0.24948000"], ["96653.02000000", "0.00000000"], ["96651.71000000", "0.00000000"], ["96647.33000000", "1.16701000"], ["96645.76000000", "0.00000000"], ["96637.83000000", "1.66495000"], ["96634.36000000", "0.21301000"], ["96628.09000000", "0.01551000"], ["96580.02000000", "0.04800000"], ["95800.01000000", "0.00266000"], ["95223.27000000", "0.00133000"], ["87006.04000000", "0.00000000"], ["87006.00000000", "0.00000000"], ["87005.00000000", "0.00163000"], ["77338.71000000", "0.00050000"], ["70000.00000000", "183.65395000"], ["42000.00000000", "3.70661000"], ["33000.00000000", "2.70627000"]], "a": [["96673.39000000", "6.36800000"], ["96676.77000000", "0.00000000"], ["96677.20000000", "0.00724000"], ["96677.95000000", "0.00999000"], ["96678.20000000", "0.00724000"], ["96679.20000000", "0.00724000"], ["96680.20000000", "0.00724000"], ["96681.20000000", "0.00724000"], ["96682.20000000", "0.00724000"], ["96683.20000000", "0.10324000"], ["96697.69000000", "1.65789000"], ["96704.67000000", "0.10080000"], ["96706.21000000", "0.00000000"], ["96707.56000000", "0.09600000"], ["96709.46000000", "0.08160000"], ["96711.29000000", "0.10055000"], ["96719.36000000", "0.00000000"], ["96729.04000000", "0.00000000"], ["96737.92000000", "0.02000000"], ["96738.71000000", "0.00000000"], ["96748.38000000", "0.00000000"], ["96766.86000000", "0.00000000"], ["96768.79000000", "0.00000000"], ["98123.50000000", "0.00000000"]]}
{"e": "depthUpdate", "E": 1746124987014, "s": "BTCUSDT", "b": [["96673.38000000", "5.41218000"], ["96673.37000000", "0.00114000"], ["96673.32000000", "0.00006000"], ["96673.24000000", "0.00018000"], ["96673.23000000", "0.02312000"], ["96673.00000000", "0.00013000"], ["96672.87000000", "0.00000000"], ["96672.86000000", "0.00000000"], ["96672.20000000", "0.28536000"], ["96672.19000000", "0.23857000"], ["96671.42000000", "0.68260000"], ["96671.20000000", "0.04152000"], ["96671.03000000", "0.00000000"], ["96670.48000000", "0.21313000"], ["96670.00000000", "0.00000000"], ["96669.69000000", "0.01886000"], ["96669.55000000", "0.00103000"], ["96668.00000000", "0.03796000"], ["96666.91000000", "0.24211000"], ["96666.67000000", "0.00000000"], ["96666.66000000", "0.06288000"], ["96666.41000000", "0.04639000"], ["96666.00000000", "0.43140000"], ["96665.55000000", "0.00000000"], ["96663.85000000", "0.00000000"], ["96662.94000000", "0.00000000"], ["96662.57000000", "0.00000000"], ["96662.21000000", "0.00999000"], ["96660.64000000", "0.00000000"], ["96660.15000000", "0.15817000"], ["96660.14000000", "0.00000000"], ["96660.13000000", "0.00000000"], ["96658.17000000", "0.00000000"], ["96657.88000000", "0.00000000"], ["96657.45000000", "1.37553000"], ["96655.21000000", "0.00464000"], ["96654.26000000", "1.68968000"], ["96654.19000000", "0.74466000"], ["96654.02000000", "0.00000000"], ["96652.81000000", "0.94983000"], ["96649.33000000", "0.74470000"], ["96648.85000000", "0.77566000"], ["96648.60000000", "0.03999000"], ["96648.28000000", "1.21301000"], ["96647.33000000", "1.09563000"], ["96647.10000000", "0.77566000"], ["96646.18000000", "0.00000000"], ["96644.38000000", "0.10146000"], ["96642.39000000", "0.83660000"], ["96641.76000000", "0.00000000"], ["96641.43000000", "0.00000000"], ["96640.43000000", "0.00000000"], ["96640.10000000", "0.06440000"], ["96638.46000000", "0.00000000"], ["96637.84000000", "0.00000000"], ["96637.34000000", "0.00000000"], ["96637.29000000", "0.07919000"], ["96636.10000000", "0.00000000"], ["96635.49000000", "0.00000000"], ["96635.28000000", "0.00000000"], ["96633.72000000", "0.00000000"], ["96633.71000000", "0.00000000"], ["96631.33000000", "0.56879000"], ["96629.17000000", "0.00000000"], ["96629.05000000", "0.00000000"], ["96623.18000000", "2.00000000"], ["96623.08000000", "0.00000000"], ["96622.79000000", "0.28507000"], ["96621.81000000", "0.03785000"], ["96618.98000000", "1.68968000"], ["96616.12000000", "0.03693000"], ["96614.94000000", "0.00000000"], ["96609.22000000", "0.00000000"], ["96608.17000000", "0.00000000"], ["96607.48000000", "0.00000000"], ["96606.32000000", "0.00000000"], ["96602.37000000", "0.00000000"], ["96597.80000000", "0.34047000"], ["96596.63000000", "0.64288000"], ["96586.66000000", "0.00000000"], ["96578.11000000", "0.11141000"], ["96543.18000000", "0.05396000"], ["96392.54000000", "0.00000000"], ["95223.27000000", "0.00033000"], ["87006.04000000", "0.00000000"], ["87006.00000000", "0.00000000"], ["87005.00000000", "0.00163000"], ["79000.00000000", "54.24644000"], ["77338.71000000", "0.00050000"], ["34802.42000000", "0.00342000"], ["33000.00000000", "2.70627000"]], "a": [["96673.39000000", "3.70636000"], ["96673.40000000", "0.00438000"], ["96673.75000000", "0.00006000"], ["96673.76000000", "0.00006000"], ["96673.87000000", "0.00006000"], ["96673.88000000", "0.00018000"], ["96673.89000000", "0.10700000"], ["96673.90000000", "0.04216000"], ["96673.91000000", "0.00000000"], ["96673.99000000", "0.00000000"], ["96674.00000000", "0.03802000"], ["96674.04000000", "0.00000000"], ["96675.13000000", "0.00000000"], ["96675.45000000", "0.00000000"], ["96675.84000000", "0.00006000"], ["96675.99000000", "0.00000000"], ["96676.00000000", "0.04002000"], ["96676.40000000", "0.01720000"], ["96676.79000000", "0.00000000"], ["96677.13000000", "0.00012000"], ["96677.14000000", "0.21307000"], ["96677.48000000", "0.00000000"], ["96677.60000000", "0.00000000"], ["96677.95000000", "0.00000000"], ["96678.00000000", "0.03796000"], ["96678.07000000", "0.00000000"], ["96678.08000000", "0.06446000"], ["96678.17000000", "0.04000000"], ["96679.21000000", "0.00000000"], ["96679.28000000", "0.02000000"], ["96679.59000000", "0.00000000"], ["96679.95000000", "0.07919000"], ["96680.14000000", "0.00000000"], ["96680.20000000", "0.00724000"], ["96680.21000000", "0.21301000"], ["96680.22000000", "0.31018000"], ["96680.73000000", "0.00000000"], ["96680.77000000", "0.68242000"], ["96680.81000000", "0.00000000"], ["96681.15000000", "0.00103000"], ["96681.40000000", "0.02294000"], ["96683.70000000", "0.18334000"], ["96684.20000000", "0.00724000"], ["96684.82000000", "0.00013000"], ["96685.20000000", "0.00724000"], ["96686.84000000", "0.00999000"], ["96686.94000000", "0.00000000"], ["96686.95000000", "0.00000000"], ["96689.16000000", "0.00000000"], ["96689.17000000", "0.00000000"], ["96689.21000000", "0.21301000"], ["96689.22000000", "0.41902000"], ["96689.32000000", "0.06000000"], ["96689.98000000", "0.00517000"], ["96690.27000000", "0.00000000"], ["96691.89000000", "0.00000000"], ["96692.54000000", "0.21301000"], ["96692.79000000", "0.00000000"], ["96693.18000000", "0.21301000"], ["96693.19000000", "0.00000000"], ["96693.20000000", "0.95742000"], ["96695.67000000", "0.00000000"], ["96696.17000000", "0.10312000"], ["96696.64000000", "0.83337000"], ["96697.38000000", "0.32654000"], ["96697.65000000", "0.03999000"], ["96697.69000000", "0.05171000"], ["96699.23000000", "0.00000000"], ["96699.42000000", "0.00000000"], ["96700.12000000", "0.00000000"], ["96700.69000000", "0.00000000"], ["96701.05000000", "0.77566000"], ["96702.22000000", "0.00000000"], ["96702.92000000", "0.00000000"], ["96703.91000000", "0.00000000"], ["96703.96000000", "1.00403000"], ["96704.48000000", "0.00000000"], ["96704.81000000", "0.00000000"], ["96705.48000000", "0.77566000"], ["96706.05000000", "0.00000000"], ["96706.35000000", "1.89415000"], ["96711.29000000", "0.00000000"], ["96712.75000000", "0.05000000"], ["96713.72000000", "0.60009000"], ["96715.78000000", "0.74418000"], ["96716.91000000", "0.07919000"], ["96717.02000000", "0.00000000"], ["96717.53000000", "0.00000000"], ["96717.95000000", "0.00000000"], ["96719.31000000", "0.00000000"], ["96719.80000000", "0.74415000"], ["96720.65000000", "0.10299000"], ["96721.74000000", "0.00000000"], ["96724.14000000", "0.00000000"], ["96725.82000000", "0.00000000"], ["96725.94000000", "0.00000000"], ["96726.75000000", "0.64202000"], ["96726.83000000", "0.00000000"], ["96726.85000000", "0.00000000"], ["96731.05000000", "0.00000000"], ["96731.66000000", "0.03641000"], ["96732.45000000", "0.00000000"], ["96734.53000000", "2.00000000"], ["96735.57000000", "0.00000000"], ["96736.23000000", "0.00000000"], ["96738.12000000", "0.02832000"], ["96738.71000000", "0.00000000"], ["96739.26000000", "0.03734000"], ["96741.90000000", "0.54786000"], ["96742.75000000", "0.41368000"], ["96743.92000000", "0.51710000"], ["96763.95000000", "0.00000000"], ["96785.61000000", "0.00000000"], ["96797.83000000", "0.00000000"], ["96802.47000000", "0.00738000"], ["96809.26000000", "0.00000000"], ["96812.47000000", "1.33332000"], ["96831.37000000", "0.00646000"], ["96869.32000000", "0.00593000"], ["97372.80000000", "0.00000000"], ["97411.44000000", "0.05175000"], ["97640.11000000", "0.00000000"], ["98123.50000000", "0.00100000"]]}
{"e": "depthUpdate", "E": 1746124988014, "s": "BTCUSDT", "b": [["96673.38000000", "5.43559000"], ["96673.00000000", "0.00024000"], ["96665.35000000", "0.00000000"], ["96662.65000000", "0.00422000"], ["96623.19000000", "0.89618000"], ["96622.50000000", "0.00000000"], ["96621.81000000", "0.00000000"], ["95937.91000000", "0.00009000"], ["95223.27000000", "0.00133000"], ["94948.43000000", "0.00009000"], ["93969.16000000", "0.00010000"], ["93000.00000000", "87.50123000"], ["91839.71000000", "0.00000000"], ["87006.04000000", "0.00000000"], ["87006.00000000", "0.00000000"], ["87005.00000000", "0.00163000"], ["79500.00000000", "20.12824000"], ["77338.71000000", "0.00050000"], ["75000.00000000", "153.32132000"], ["70000.00000000", "183.65395000"], ["42000.00000000", "3.70561000"], ["33000.00000000", "2.70627000"]], "a": [["96673.39000000", "5.13987000"], ["96673.40000000", "0.00444000"], ["96674.00000000", "0.03802000"], ["96675.45000000", "0.02712000"], ["96678.08000000", "0.06440000"], ["96683.69000000", "0.43249000"], ["96689.22000000", "0.00000000"], ["96692.38000000", "0.18243000"], ["96697.38000000", "0.00000000"], ["96700.00000000", "0.27937000"], ["96703.68000000", "0.74428000"], ["96716.91000000", "0.07950000"], ["96719.80000000", "0.00000000"], ["96721.39000000", "0.61676000"], ["96721.74000000", "0.00031000"], ["96731.07000000", "0.00103000"], ["96733.05000000", "0.86515000"], ["96733.24000000", "0.00560000"], ["96739.42000000", "0.00906000"], ["96740.74000000", "0.00103000"], ["96747.27000000", "0.00499000"], ["96749.38000000", "0.00560000"], ["96750.41000000", "0.00103000"], ["96759.49000000", "0.00499000"], ["96771.01000000", "0.00499000"], ["96772.99000000", "0.00868000"], ["96797.82000000", "0.00000000"], ["96803.77000000", "0.15924000"], ["96825.74000000", "0.00906000"], ["97947.89000000", "0.00009000"], ["98123.50000000", "0.00000000"], ["98968.63000000", "0.00009000"], ["100000.00000000", "184.43863000"]]}
