{"e": "depthUpdate", "E": 1746124989014, "s": "BTCUSDT", "b": [["96673.38000000", "5.42946000"], ["96673.00000000", "0.00013000"], ["96672.19000000", "0.23857000"], ["96672.12000000", "0.00000000"], ["96671.20000000", "0.04146000"], ["96670.48000000", "0.00000000"], ["96669.69000000", "0.01886000"], ["96668.65000000", "0.02047000"], ["96667.25000000", "0.21307000"], ["96666.91000000", "0.24211000"], ["96662.96000000", "0.00095000"], ["96662.21000000", "0.00000000"], ["96661.22000000", "0.00999000"], ["96634.36000000", "0.21301000"], ["96619.94000000", "0.05000000"], ["96616.12000000", "0.00000000"], ["96610.65000000", "0.03785000"], ["96604.86000000", "0.03693000"], ["96570.87000000", "0.01782000"], ["95223.27000000", "0.00133000"], ["94737.69000000", "0.00076000"], ["87006.04000000", "0.00000000"], ["87006.00000000", "0.00000000"], ["87005.00000000", "0.00163000"], ["79000.00000000", "54.24642000"], ["77338.71000000", "0.00050000"], ["34802.42000000", "0.00396000"], ["33000.00000000", "2.70627000"], ["20002.00000000", "0.00000000"]], "a": [["96673.39000000", "5.13861000"], ["96673.40000000", "0.00450000"], ["96674.00000000", "0.03802000"], ["96674.28000000", "0.00012000"], ["96674.29000000", "0.07925000"], ["96676.00000000", "0.03996000"], ["96677.14000000", "0.21307000"], ["96677.44000000", "0.02294000"], ["96677.60000000", "0.04140000"], ["96678.00000000", "0.03790000"], ["96678.09000000", "0.00012000"], ["96678.10000000", "0.95000000"], ["96678.11000000", "0.68243000"], ["96680.20000000", "1.69692000"], ["96680.22000000", "0.00000000"], ["96680.77000000", "0.00000000"], ["96685.87000000", "0.00999000"], ["96686.84000000", "0.00000000"], ["96723.96000000", "0.03734000"], ["96730.37000000", "0.00856000"], ["96739.26000000", "0.00000000"], ["96768.95000000", "0.00744000"], ["96778.56000000", "0.00461000"], ["96788.59000000", "0.00663000"], ["96797.30000000", "0.00663000"], ["96806.81000000", "0.00856000"], ["96845.50000000", "0.00569000"], ["96850.59000000", "0.00856000"], ["96861.35000000", "0.00856000"], ["96865.37000000", "0.00700000"], ["96874.17000000", "0.00663000"], ["98123.50000000", "0.00100000"]]}
{"e": "depthUpdate", "E": 1746124990014, "s": "BTCUSDT", "b": [["96673.38000000", "5.42643000"], ["96673.37000000", "0.00120000"], ["96673.00000000", "0.00024000"], ["96672.19000000", "0.23857000"], ["96672.12000000", "0.02823000"], ["96667.25000000", "0.21301000"], ["96662.96000000", "0.00000000"], ["96528.76000000", "2.69714000"], ["96522.38000000", "0.00000000"], ["96391.64000000", "0.00007000"], ["95223.27000000", "0.00033000"], ["88939.51000000", "0.00012000"], ["87006.04000000", "0.00000000"], ["87006.00000000", "0.00000000"], ["87005.00000000", "0.00163000"], ["77338.71000000", "0.00050000"], ["70000.00000000", "183.65395000"], ["33000.00000000", "2.70627000"]], "a": [["96673.39000000", "4.81599000"], ["96674.29000000", "0.07925000"], ["96675.45000000", "0.00000000"], ["96675.54000000", "0.02729000"], ["96677.44000000", "0.02294000"], ["96686.25000000", "0.00612000"], ["96691.92000000", "0.00461000"], ["96695.02000000", "0.00383000"], ["96704.74000000", "0.00686000"], ["96713.91000000", "0.00649000"], ["96715.75000000", "0.10154000"], ["96720.65000000", "0.00000000"], ["96811.00000000", "0.00612000"], ["98123.50000000", "0.00000000"]]}
{"e": "depthUpdate", "E": 1746124991014, "s": "BTCUSDT", "b": [["96673.38000000", "6.70968000"], ["96673.37000000", "0.00006000"], ["96673.23000000", "0.02312000"], ["96673.00000000", "0.00024000"], ["96672.23000000", "0.00012000"], ["96672.22000000", "0.45299000"], ["96672.21000000", "0.00000000"], ["96672.20000000", "0.18277000"], ["96672.19000000", "0.23851000"], ["96672.12000000", "0.02823000"], ["96671.43000000", "0.00000000"], ["96671.42000000", "0.00006000"], ["96671.20000000", "0.04146000"], ["96670.48000000", "0.21307000"], ["96669.55000000", "0.00000000"], ["96668.00000000", "0.03790000"], ["96666.00000000", "0.03790000"], ["96664.55000000", "0.00103000"], ["96662.65000000", "0.00000000"], ["96660.15000000", "0.54789000"], ["96658.41000000", "0.62035000"], ["96658.40000000", "0.78603000"], ["96655.94000000", "1.00000000"], ["96655.84000000", "0.00000000"], ["96653.74000000", "0.00000000"], ["96653.54000000", "0.00000000"], ["96649.74000000", "0.00000000"], ["96649.65000000", "0.00000000"], ["96648.28000000", "0.21301000"], ["96648.12000000", "0.00000000"], ["96642.26000000", "1.63306000"], ["96639.99000000", "0.00000000"], ["96638.50000000", "2.00000000"], ["96638.30000000", "0.00000000"], ["96638.12000000", "0.21301000"], ["96637.84000000", "0.00000000"], ["96637.83000000", "0.00000000"], ["96636.09000000", "0.01551000"], ["96634.10000000", "0.00000000"], ["96633.70000000", "0.00000000"], ["96633.05000000", "0.00206000"], ["96631.33000000", "0.47607000"], ["96631.26000000", "0.01034000"], ["96628.09000000", "0.00000000"], ["96626.66000000", "0.03785000"], ["96626.10000000", "0.00000000"], ["96623.26000000", "0.00000000"], ["96623.19000000", "0.29982000"], ["96623.18000000", "0.00000000"], ["96622.86000000", "0.00000000"], ["96622.51000000", "0.00000000"], ["96610.65000000", "0.00000000"], ["95600.01000000", "0.00313000"], ["95442.71000000", "0.04105000"], ["95223.27000000", "0.00133000"], ["88939.51000000", "0.00000000"], ["87006.04000000", "0.00000000"], ["87006.00000000", "0.00000000"], ["87005.00000000", "0.00163000"], ["79000.00000000", "54.24641000"], ["77338.71000000", "0.00050000"], ["60000.00000000", "80.85283000"], ["34802.42000000", "0.00414000"], ["33000.00000000", "2.70627000"]], "a": [["96673.39000000", "2.11815000"], ["96673.40000000", "0.00456000"], ["96673.88000000", "0.00018000"], ["96673.89000000", "0.05745000"], ["96673.90000000", "0.00006000"], ["96673.99000000", "0.00012000"], ["96674.00000000", "0.03802000"], ["96674.28000000", "0.00000000"], ["96674.29000000", "0.00000000"], ["96674.45000000", "0.00000000"], ["96675.54000000", "0.00000000"], ["96675.99000000", "0.00012000"], ["96676.15000000", "0.00103000"], ["96676.40000000", "0.01720000"], ["96676.91000000", "0.00000000"], ["96677.13000000", "0.00000000"], ["96677.14000000", "0.00000000"], ["96677.44000000", "0.00000000"], ["96677.60000000", "0.00000000"], ["96677.99000000", "0.00000000"], ["96678.00000000", "0.03796000"], ["96678.07000000", "0.00000000"], ["96678.08000000", "0.06446000"], ["96678.09000000", "0.00000000"], ["96678.10000000", "0.00000000"], ["96678.11000000", "0.00000000"], ["96678.17000000", "0.00000000"], ["96678.21000000", "0.02704000"], ["96679.28000000", "0.02006000"], ["96679.95000000", "0.07919000"], ["96680.20000000", "0.00724000"], ["96680.50000000", "0.00000000"], ["96680.87000000", "0.00000000"], ["96681.15000000", "0.00000000"], ["96681.40000000", "0.00000000"], ["96682.12000000", "0.62897000"], ["96682.49000000", "0.00000000"], ["96683.69000000", "0.00000000"], ["96684.17000000", "0.00427000"], ["96684.27000000", "0.00089000"], ["96684.28000000", "0.04000000"], ["96686.96000000", "0.00000000"], ["96687.82000000", "0.47801000"], ["96689.21000000", "0.00000000"], ["96689.98000000", "0.00000000"], ["96690.03000000", "0.00000000"], ["96693.17000000", "0.00516000"], ["96696.64000000", "0.21301000"], ["96699.54000000", "0.62034000"], ["96702.84000000", "1.60849000"], ["96703.68000000", "0.00000000"], ["96703.73000000", "0.00000000"], ["96703.96000000", "0.00403000"], ["96706.35000000", "0.21911000"], ["96707.46000000", "0.00000000"], ["96707.66000000", "0.00000000"], ["96708.06000000", "0.00000000"], ["96708.99000000", "0.00366000"], ["96709.76000000", "1.00000000"], ["96709.79000000", "0.74723000"], ["96715.62000000", "0.00000000"], ["96715.78000000", "0.00000000"], ["96716.91000000", "0.07919000"], ["96718.74000000", "0.00991000"], ["96719.08000000", "0.00000000"], ["96719.54000000", "0.74415000"], ["96720.32000000", "0.00000000"], ["96721.74000000", "0.00000000"], ["96723.21000000", "0.01551000"], ["96723.96000000", "0.00000000"], ["96725.54000000", "0.02298000"], ["96725.65000000", "0.00749000"], ["96728.04000000", "0.01034000"], ["96733.05000000", "0.29793000"], ["96734.53000000", "0.00000000"], ["96735.32000000", "0.03734000"], ["96741.53000000", "0.00000000"], ["96741.93000000", "0.00000000"], ["96743.67000000", "0.00369000"], ["96745.52000000", "1.02896000"], ["96746.13000000", "2.00000000"], ["96757.72000000", "0.00749000"], ["96782.24000000", "0.00902000"], ["96817.04000000", "0.00902000"], ["98123.50000000", "0.00100000"]]}
{"e": "depthUpdate", "E": 1746124992014, "s": "BTCUSDT", "b": [["96673.38000000", "6.66383000"], ["96673.23000000", "0.02306000"], ["96673.00000000", "0.00024000"], ["96672.24000000", "0.00012000"], ["96672.23000000", "0.31874000"], ["96672.22000000", "0.45299000"], ["96672.20000000", "0.00006000"], ["96666.91000000", "0.14246000"], ["96660.15000000", "0.47965000"], ["96656.34000000", "1.00000000"], ["96656.14000000", "0.00000000"], ["96655.94000000", "0.00000000"], ["96653.44000000", "0.00000000"], ["96650.59000000", "0.02300000"], ["96647.60000000", "0.00000000"], ["96647.08000000", "0.00000000"], ["96646.56000000", "1.68968000"], ["96642.59000000", "2.39725000"], ["96640.67000000", "0.00000000"], ["96639.30000000", "2.00000000"], ["96638.90000000", "0.00006000"], ["96638.50000000", "0.00000000"], ["96638.12000000", "0.00000000"], ["96633.92000000", "0.02000000"], ["96628.04000000", "0.04800000"], ["96621.82000000", "0.00000000"], ["96620.78000000", "0.00000000"], ["96619.74000000", "0.00000000"], ["96583.81000000", "0.00000000"], ["96577.93000000", "0.00000000"], ["96570.87000000", "0.00000000"], ["96565.90000000", "0.01617000"], ["96530.40000000", "0.00000000"], ["96450.70000000", "1.31358000"], ["96414.60000000", "0.00000000"], ["96305.80000000", "3.65114000"], ["95706.64000000", "0.00000000"], ["95442.71000000", "0.00000000"], ["95223.27000000", "0.00133000"], ["87006.04000000", "0.00000000"], ["87006.00000000", "0.00000000"], ["87005.00000000", "0.00163000"], ["77338.71000000", "0.00050000"], ["70000.00000000", "183.65395000"], ["60000.00000000", "80.85273000"], ["56621.23000000", "0.00000000"], ["34802.42000000", "0.00432000"], ["33000.00000000", "2.70627000"]], "a": [["96673.39000000", "2.30378000"], ["96673.40000000", "0.00468000"], ["96673.89000000", "0.09603000"], ["96674.00000000", "0.03802000"], ["96675.72000000", "0.00012000"], ["96675.73000000", "0.05958000"], ["96675.84000000", "0.00000000"], ["96675.99000000", "0.00000000"], ["96676.40000000", "0.01720000"], ["96677.21000000", "0.00006000"], ["96677.22000000", "0.21307000"], ["96677.38000000", "0.00000000"], ["96677.39000000", "0.06446000"], ["96678.00000000", "0.03796000"], ["96678.07000000", "0.00000000"], ["96678.08000000", "0.00000000"], ["96678.21000000", "0.02698000"], ["96679.28000000", "0.02000000"], ["96679.47000000", "0.00000000"], ["96679.48000000", "0.20751000"], ["96681.83000000", "0.00414000"], ["96682.38000000", "0.01880000"], ["96684.00000000", "0.04340000"], ["96684.17000000", "0.00007000"], ["96684.21000000", "0.68239000"], ["96684.89000000", "0.00999000"], ["96685.87000000", "0.00000000"], ["96687.39000000", "0.00000000"], ["96699.54000000", "0.00000000"], ["96702.78000000", "0.62032000"], ["96723.81000000", "0.74412000"], ["96725.54000000", "0.00000000"], ["96728.63000000", "0.01617000"], ["96728.68000000", "0.00000000"], ["96731.29000000", "0.02298000"], ["96745.52000000", "1.49177000"], ["96753.14000000", "0.00911000"], ["96763.66000000", "0.00363000"], ["96792.88000000", "0.04426000"], ["96820.79000000", "0.00725000"], ["96839.98000000", "0.00363000"], ["96854.94000000", "0.00695000"], ["98123.50000000", "0.00000000"]]}
{"e": "depthUpdate", "E": 1746124993014, "s": "BTCUSDT", "b": [["96673.38000000", "6.30731000"], ["96673.37000000", "0.00024000"], ["96673.00000000", "0.00024000"], ["96672.24000000", "0.00012000"], ["96672.23000000", "0.15513000"], ["96672.22000000", "0.00000000"], ["96672.20000000", "0.00018000"], ["96672.19000000", "0.23851000"], ["96672.12000000", "0.00000000"], ["96671.20000000", "0.04146000"], ["96670.48000000", "0.00000000"], ["96670.01000000", "0.00000000"], ["96669.69000000", "0.01886000"], ["96669.24000000", "0.21307000"], ["96668.65000000", "0.00000000"], ["96668.00000000", "0.03796000"], ["96667.26000000", "0.33024000"], ["96667.25000000", "0.00000000"], ["96666.91000000", "0.00000000"], ["96666.66000000", "0.06294000"], ["96666.41000000", "0.04639000"], ["96666.13000000", "0.21301000"], ["96666.00000000", "0.03790000"], ["96665.90000000", "0.52349000"], ["96662.58000000", "0.00000000"], ["96661.22000000", "0.00000000"], ["96660.25000000", "0.00999000"], ["96660.15000000", "0.18852000"], ["96659.25000000", "0.00000000"], ["96658.78000000", "0.00000000"], ["96658.41000000", "0.00000000"], ["96658.40000000", "0.04140000"], ["96657.80000000", "0.00516000"], ["96656.34000000", "0.00000000"], ["96656.18000000", "0.00000000"], ["96654.94000000", "0.62036000"], ["96654.01000000", "0.00000000"], ["96652.98000000", "0.00000000"], ["96651.08000000", "0.00000000"], ["96650.48000000", "1.00000000"], ["96648.85000000", "0.77566000"], ["96648.48000000", "0.00000000"], ["96647.96000000", "0.00000000"], ["96647.10000000", "0.00000000"], ["96644.13000000", "0.77566000"], ["96643.06000000", "0.74480000"], ["96642.59000000", "1.40221000"], ["96642.26000000", "0.00000000"], ["96641.84000000", "1.64524000"], ["96639.30000000", "0.00000000"], ["96638.98000000", "0.00000000"], ["96634.38000000", "0.21301000"], ["96634.37000000", "0.00000000"], ["96634.36000000", "0.00000000"], ["96632.58000000", "0.00000000"], ["96628.78000000", "0.00000000"], ["96627.58000000", "2.00000000"], ["96626.66000000", "0.00000000"], ["96623.58000000", "0.00103000"], ["96622.54000000", "0.00000000"], ["96612.60000000", "0.03785000"], ["96600.41000000", "0.00258000"], ["96600.01000000", "0.00000000"], ["96598.06000000", "0.00256000"], ["96598.05000000", "0.00000000"], ["96588.74000000", "0.00000000"], ["96565.90000000", "0.00000000"], ["96553.70000000", "0.00234000"], ["96553.69000000", "0.00000000"], ["96531.94000000", "0.00000000"], ["96530.80000000", "0.00000000"], ["96528.76000000", "0.00000000"], ["96525.97000000", "0.01617000"], ["96502.96000000", "0.00103000"], ["96502.95000000", "0.00000000"], ["96501.50000000", "0.00103000"], ["96501.49000000", "0.00000000"], ["96475.18000000", "0.00000000"], ["96456.88000000", "0.00185000"], ["96456.87000000", "0.00000000"], ["96391.64000000", "0.00000000"], ["95223.27000000", "0.00033000"], ["87006.04000000", "0.00000000"], ["87006.00000000", "0.00000000"], ["87005.00000000", "0.00163000"], ["77338.71000000", "0.00050000"], ["76500.00000000", "50.08595000"], ["34802.42000000", "0.00468000"], ["33000.00000000", "2.70627000"]], "a": [["96673.39000000", "3.73496000"], ["96673.40000000", "0.00474000"], ["96673.42000000", "0.00040000"], ["96673.47000000", "0.00018000"], ["96673.48000000", "0.05494000"], ["96673.70000000", "0.00024000"], ["96673.75000000", "0.00006000"], ["96673.76000000", "0.00006000"], ["96673.87000000", "0.00000000"], ["96673.88000000", "0.00012000"], ["96673.99000000", "0.00000000"], ["96674.00000000", "0.03802000"], ["96675.72000000", "0.00000000"], ["96675.73000000", "0.00000000"], ["96675.84000000", "0.00006000"], ["96677.21000000", "0.00012000"], ["96677.60000000", "0.00000000"], ["96678.92000000", "0.42951000"], ["96678.93000000", "0.00000000"], ["96679.48000000", "0.00062000"], ["96680.12000000", "0.00000000"], ["96680.89000000", "0.68241000"], ["96680.95000000", "0.02739000"], ["96684.09000000", "0.00091000"], ["96684.21000000", "0.00000000"], ["96684.27000000", "0.00000000"], ["96684.28000000", "0.00000000"], ["96686.72000000", "0.21301000"], ["96688.28000000", "0.04000000"], ["96692.38000000", "0.00000000"], ["96692.68000000", "0.12090000"], ["96701.05000000", "0.77566000"], ["96702.34000000", "0.00000000"], ["96702.51000000", "0.77566000"], ["96702.84000000", "0.00000000"], ["96703.57000000", "0.74428000"], ["96703.68000000", "1.60441000"], ["96704.34000000", "1.00000000"], ["96704.94000000", "0.00000000"], ["96705.48000000", "0.00000000"], ["96706.84000000", "0.00000000"], ["96709.76000000", "0.00000000"], ["96723.81000000", "0.00000000"], ["96728.63000000", "0.00000000"], ["96731.29000000", "0.02298000"], ["96735.29000000", "2.00000000"], ["96736.49000000", "0.00000000"], ["96740.29000000", "0.00000000"], ["96745.52000000", "1.02896000"], ["96746.13000000", "0.00000000"], ["96764.04000000", "0.01617000"], ["96835.96000000", "0.00713000"], ["98123.50000000", "0.00100000"]]}
{"e": "depthUpdate", "E": 1746124994014, "s": "BTCUSDT", "b": [["96673.38000000", "5.78812000"], ["96673.37000000", "0.00030000"], ["96672.19000000", "0.23851000"], ["96672.12000000", "0.02788000"], ["96671.20000000", "0.07251000"], ["96666.66000000", "0.06288000"], ["96660.15000000", "0.35799000"], ["96658.77000000", "0.00000000"], ["96658.20000000", "0.74463000"], ["96650.79000000", "0.00000000"], ["96650.48000000", "0.00000000"], ["96648.43000000", "1.00000000"], ["96643.06000000", "0.00006000"], ["96627.58000000", "0.00000000"], ["96623.48000000", "2.00000000"], ["96525.97000000", "0.00000000"], ["96471.81000000", "3.12000000"], ["96460.01000000", "0.00000000"], ["95803.32000000", "0.00032000"], ["95223.27000000", "0.00133000"], ["87006.04000000", "0.00000000"], ["87006.00000000", "0.00000000"], ["87005.00000000", "0.00163000"], ["77338.71000000", "0.00050000"], ["70000.00000000", "183.65395000"], ["62866.67000000", "0.00000000"], ["34802.42000000", "0.00486000"], ["33000.00000000", "2.70627000"], ["20002.00000000", "0.00000000"]], "a": [["96673.39000000", "4.29029000"], ["96677.22000000", "0.21307000"], ["96677.39000000", "0.00000000"], ["96678.21000000", "0.02704000"], ["96702.19000000", "1.35338000"], ["96704.34000000", "0.00000000"], ["96730.99000000", "2.00000000"], ["96735.28000000", "1.74713000"], ["96735.29000000", "0.00000000"], ["96737.36000000", "0.00000000"], ["96764.04000000", "0.00000000"], ["98123.50000000", "0.00000000"]]}
{"e": "depthUpdate", "E": 1746124995014, "s": "BTCUSDT", "b": [["96673.38000000", "5.76540000"], ["96664.39000000", "0.00000000"], ["96657.52000000", "0.42005000"], ["96649.03000000", "1.00000000"], ["96648.43000000", "0.00000000"], ["96647.39000000", "0.00000000"], ["96646.87000000", "0.00000000"], ["96645.30000000", "0.00000000"], ["96624.68000000", "2.51741000"], ["96623.49000000", "0.00000000"], ["96623.48000000", "0.00000000"], ["96623.19000000", "0.00000000"], ["96621.40000000", "0.00000000"], ["96620.36000000", "0.00000000"], ["96617.22000000", "0.00000000"], ["96522.38000000", "2.69714000"], ["96487.41000000", "0.00000000"], ["96480.04000000", "0.00020000"], ["96461.77000000", "6.53224000"], ["96449.15000000", "0.00000000"], ["95706.65000000", "0.00032000"], ["95609.97000000", "0.00016000"], ["95513.30000000", "0.00016000"], ["95416.63000000", "0.00016000"], ["95346.76000000", "0.00000000"], ["95223.27000000", "0.00133000"], ["87006.04000000", "0.00000000"], ["87006.00000000", "0.00000000"], ["87005.00000000", "0.00163000"], ["77338.71000000", "0.00050000"], ["76500.00000000", "50.08594000"], ["67703.00000000", "0.00000000"], ["34802.42000000", "0.00522000"], ["33000.00000000", "2.70627000"]], "a": [["96673.39000000", "3.21562000"], ["96676.40000000", "0.01720000"], ["96676.96000000", "0.06446000"], ["96678.21000000", "0.02698000"], ["96678.91000000", "0.00000000"], ["96684.09000000", "0.00000000"], ["96735.28000000", "1.14713000"], ["96873.39000000", "0.00000000"], ["96887.95000000", "6.37577000"], ["98123.50000000", "0.00100000"], ["99238.79000000", "0.00000000"]]}
{"e": "depthUpdate", "E": 1746124996014, "s": "BTCUSDT", "b": [["96673.38000000", "5.75769000"], ["96667.85000000", "0.00007000"], ["96649.11000000", "1.00000000"], ["96649.03000000", "0.00000000"], ["96647.39000000", "0.00000000"], ["96624.84000000", "2.00000000"], ["96624.68000000", "0.51741000"], ["96621.40000000", "0.00000000"], ["96381.06000000", "0.00000000"], ["95400.01000000", "0.00366000"], ["95346.37000000", "0.00144000"], ["95319.95000000", "0.00016000"], ["95223.28000000", "0.00022000"], ["95223.27000000", "0.00033000"], ["95126.61000000", "0.00232000"], ["95029.93000000", "0.00016000"], ["94737.69000000", "0.00006000"], ["94588.76000000", "0.00000000"], ["88939.51000000", "0.00000000"], ["87006.04000000", "0.00000000"], ["87006.00000000", "0.00000000"], ["87005.00000000", "0.00163000"], ["77338.71000000", "0.00050000"], ["70000.00000000", "183.65395000"], ["42000.00000000", "3.70661000"], ["34802.42000000", "0.00540000"], ["33000.00000000", "2.70627000"]], "a": [["96673.39000000", "3.20747000"], ["96673.70000000", "0.00006000"], ["96684.08000000", "0.09212000"], ["96740.03000000", "0.00761000"], ["96830.41000000", "0.00934000"], ["98000.00000000", "141.05414000"], ["98123.50000000", "0.00000000"], ["98449.79000000", "0.00000000"], ["99238.40000000", "0.00142000"]]}
{"e": "depthUpdate", "E": 1746124997014, "s": "BTCUSDT", "b": [["96673.38000000", "5.83025000"], ["96669.80000000", "0.00103000"], ["96667.26000000", "0.33841000"], ["96664.55000000", "0.00000000"], ["96660.15000000", "0.28409000"], ["96658.21000000", "0.00516000"], ["96657.80000000", "0.00000000"], ["96649.11000000", "0.00000000"], ["96648.61000000", "1.00000000"], ["96646.75000000", "0.00000000"], ["96646.26000000", "0.06440000"], ["96640.10000000", "0.00000000"], ["96624.84000000", "0.00000000"], ["96623.84000000", "2.00000000"], ["96622.80000000", "0.29921000"], ["96620.12000000", "0.00000000"], ["96553.70000000", "0.00000000"], ["96553.69000000", "0.00206000"], ["96528.76000000", "2.69714000"], ["96527.14000000", "0.01780000"], ["96522.38000000", "0.00000000"], ["96456.88000000", "0.00000000"], ["96456.87000000", "0.00213000"], ["95706.64000000", "0.00000000"], ["95223.27000000", "0.00133000"], ["94933.26000000", "0.00016000"], ["94836.59000000", "0.00016000"], ["94739.91000000", "0.00016000"], ["94643.24000000", "0.00016000"], ["94588.37000000", "0.00098000"], ["87006.04000000", "0.00000000"], ["87006.00000000", "0.00000000"], ["87005.00000000", "0.00163000"], ["77338.71000000", "0.00050000"], ["76500.00000000", "50.08600000"], ["71477.00000000", "0.00000000"], ["33000.00000000", "2.70627000"]], "a": [["96673.39000000", "3.35730000"], ["96676.15000000", "0.00000000"], ["96678.98000000", "0.68243000"], ["96680.89000000", "0.00000000"], ["96681.40000000", "0.00103000"], ["96684.04000000", "0.00000000"], ["96684.08000000", "0.09120000"], ["96686.72000000", "0.00000000"], ["96687.39000000", "0.21301000"], ["96689.31000000", "0.00000000"], ["96689.98000000", "0.00516000"], ["96693.17000000", "0.00000000"], ["96701.38000000", "0.00558000"], ["96702.19000000", "0.35338000"], ["96702.67000000", "1.00000000"], ["96704.15000000", "0.00000000"], ["96730.98000000", "0.98081000"], ["96730.99000000", "0.00000000"], ["96731.95000000", "2.00000000"], ["96733.05000000", "0.00000000"], ["96734.91000000", "0.00000000"], ["96766.78000000", "0.00431000"], ["96786.42000000", "0.00940000"], ["96825.05000000", "0.00558000"], ["98123.50000000", "0.00100000"], ["98449.40000000", "0.00096000"]]}
{"e": "depthUpdate", "E": 1746124998014, "s": "BTCUSDT", "b": [["96673.38000000", "6.49458000"], ["96673.37000000", "0.00006000"], ["96672.23000000", "0.30776000"], ["96672.12000000", "0.02788000"], ["96671.52000000", "0.00012000"], ["96671.51000000", "0.44898000"], ["96671.20000000", "0.07251000"], ["96669.71000000", "0.02123000"], ["96668.00000000", "0.03790000"], ["96667.26000000", "0.14324000"], ["96665.90000000", "0.00000000"], ["96655.12000000", "1.00000000"], ["96655.03000000", "0.00000000"], ["96653.53000000", "0.00000000"], ["96651.83000000", "0.00000000"], ["96650.83000000", "0.00000000"], ["96650.23000000", "0.00000000"], ["96648.61000000", "0.00000000"], ["96647.81000000", "0.00000000"], ["96647.29000000", "0.00000000"], ["96647.18000000", "0.00000000"], ["96646.25000000", "0.00000000"], ["96638.60000000", "0.00000000"], ["96638.46000000", "0.00000000"], ["96636.86000000", "2.00000000"], ["96636.68000000", "0.77566000"], ["96635.12000000", "0.00206000"], ["96633.68000000", "0.00000000"], ["96633.05000000", "0.00000000"], ["96630.28000000", "0.00000000"], ["96629.08000000", "0.03785000"], ["96628.28000000", "0.00000000"], ["96627.08000000", "0.00000000"], ["96623.85000000", "0.20897000"], ["96623.84000000", "0.00000000"], ["96622.80000000", "0.00000000"], ["96622.24000000", "0.00000000"], ["96621.20000000", "0.00000000"], ["96620.98000000", "0.00000000"], ["96619.12000000", "0.00000000"], ["96612.60000000", "0.00000000"], ["96478.89000000", "0.00540000"], ["96470.96000000", "0.00000000"], ["95223.27000000", "0.00133000"], ["87006.04000000", "0.00000000"], ["87006.00000000", "0.00000000"], ["87005.00000000", "0.00163000"], ["77338.71000000", "0.00050000"], ["75251.00000000", "0.00000000"], ["70000.00000000", "183.65395000"], ["42000.00000000", "3.70561000"], ["34802.42000000", "0.00576000"], ["33000.00000000", "2.70627000"]], "a": [["96673.39000000", "2.49109000"], ["96673.40000000", "0.00486000"], ["96673.47000000", "0.00006000"], ["96673.48000000", "0.00006000"], ["96673.89000000", "0.10920000"], ["96673.99000000", "0.00012000"], ["96674.00000000", "0.03796000"], ["96674.86000000", "0.00012000"], ["96674.87000000", "0.04491000"], ["96675.99000000", "0.00000000"], ["96676.40000000", "0.01720000"], ["96676.96000000", "0.00000000"], ["96676.99000000", "0.00006000"], ["96677.00000000", "0.21307000"], ["96677.21000000", "0.00000000"], ["96677.22000000", "0.00000000"], ["96677.44000000", "0.00000000"], ["96677.45000000", "0.06446000"], ["96678.21000000", "0.02698000"], ["96678.91000000", "0.00000000"], ["96678.92000000", "0.40044000"], ["96678.98000000", "0.00000000"], ["96679.28000000", "0.02000000"], ["96680.64000000", "0.68242000"], ["96680.84000000", "0.00000000"], ["96681.83000000", "0.00000000"], ["96682.38000000", "0.00000000"], ["96682.83000000", "0.00000000"], ["96684.05000000", "0.00092000"], ["96684.60000000", "0.02294000"], ["96687.39000000", "0.21301000"], ["96689.98000000", "0.00000000"], ["96690.39000000", "0.00000000"], ["96691.28000000", "0.00516000"], ["96702.40000000", "0.00000000"], ["96702.67000000", "0.00000000"], ["96704.55000000", "0.00000000"], ["96707.25000000", "0.00000000"], ["96708.75000000", "1.00000000"], ["96730.98000000", "0.00000000"], ["96731.95000000", "0.00000000"], ["96733.31000000", "0.00603000"], ["96735.28000000", "1.14713000"], ["96735.71000000", "0.00000000"], ["96741.11000000", "0.00000000"], ["96744.11000000", "2.00000000"], ["96863.63000000", "0.00426000"], ["96870.75000000", "0.00492000"], ["96874.88000000", "0.00460000"], ["98123.50000000", "0.00000000"]]}
{"e": "depthUpdate", "E": 1746124999014, "s": "BTCUSDT", "b": [["96673.38000000", "4.69851000"], ["96673.37000000", "0.00030000"], ["96673.23000000", "0.02306000"], ["96672.24000000", "0.00000000"], ["96672.23000000", "0.00000000"], ["96672.12000000", "0.02788000"], ["96671.52000000", "0.00000000"], ["96671.51000000", "0.00000000"], ["96669.25000000", "0.00012000"], ["96668.00000000", "0.03796000"], ["96667.26000000", "0.20720000"], ["96666.46000000", "0.04000000"], ["96666.01000000", "0.00000000"], ["96665.15000000", "0.00000000"], ["96664.44000000", "0.05172000"], ["96662.02000000", "0.57431000"], ["96662.01000000", "0.62032000"], ["96660.26000000", "0.00000000"], ["96660.15000000", "0.04800000"], ["96658.57000000", "0.00516000"], ["96658.21000000", "0.00000000"], ["96657.25000000", "0.04800000"], ["96655.12000000", "0.00000000"], ["96654.94000000", "0.00000000"], ["96654.87000000", "0.00000000"], ["96649.77000000", "0.00000000"], ["96649.72000000", "0.00000000"], ["96648.22000000", "0.00000000"], ["96647.70000000", "0.00000000"], ["96646.86000000", "0.00000000"], ["96646.66000000", "0.00000000"], ["96646.26000000", "0.00000000"], ["96645.09000000", "1.00000000"], ["96642.68000000", "0.00000000"], ["96639.21000000", "0.00206000"], ["96638.46000000", "0.00000000"], ["96636.86000000", "0.00000000"], ["96635.12000000", "0.00000000"], ["96626.06000000", "0.00000000"], ["96623.85000000", "0.32262000"], ["96623.49000000", "0.03693000"], ["96623.06000000", "0.00000000"], ["96622.02000000", "0.00000000"], ["96619.94000000", "0.05000000"], ["96616.80000000", "2.00000000"], ["96604.86000000", "0.00000000"], ["96580.02000000", "0.00000000"], ["96524.50000000", "0.10350000"], ["96515.22000000", "0.00000000"], ["96381.00000000", "0.00000000"], ["95223.27000000", "0.00033000"], ["87006.04000000", "0.00000000"], ["87006.00000000", "0.00000000"], ["87005.00000000", "0.00163000"], ["77338.71000000", "0.00050000"], ["76500.00000000", "50.08592000"], ["35046.00000000", "0.00036000"], ["35042.86000000", "0.00270000"], ["35042.12000000", "0.00198000"], ["35041.98000000", "0.00126000"], ["35040.96000000", "0.00216000"], ["35039.52000000", "0.00090000"], ["35036.19000000", "0.00126000"], ["35007.67000000", "0.00234000"], ["35006.88000000", "0.00090000"], ["34996.71000000", "0.00324000"], ["34921.16000000", "0.00054000"], ["34915.47000000", "0.00090000"], ["34911.10000000", "0.00144000"], ["34909.92000000", "0.00072000"], ["34901.28000000", "0.00036000"], ["34898.41000000", "0.00054000"], ["34876.80000000", "0.00000000"], ["34802.42000000", "0.00594000"], ["34779.20000000", "0.00054000"], ["34770.31000000", "0.00000000"], ["33000.00000000", "2.70627000"], ["20002.00000000", "0.00000000"]], "a": [["96673.39000000", "6.07313000"], ["96673.40000000", "0.00492000"], ["96673.48000000", "0.00006000"], ["96673.70000000", "0.00006000"], ["96673.75000000", "0.00000000"], ["96673.76000000", "0.00012000"], ["96673.77000000", "0.07931000"], ["96673.88000000", "0.00000000"], ["96673.89000000", "0.00000000"], ["96673.90000000", "0.00012000"], ["96673.99000000", "0.00012000"], ["96674.00000000", "0.03796000"], ["96674.85000000", "0.00012000"], ["96674.86000000", "0.09749000"], ["96675.99000000", "0.00000000"], ["96676.40000000", "0.01720000"], ["96676.99000000", "0.00000000"], ["96677.00000000", "0.00000000"], ["96677.24000000", "0.00006000"], ["96677.25000000", "0.21307000"], ["96677.45000000", "0.06446000"], ["96677.60000000", "0.04140000"], ["96678.00000000", "0.03790000"], ["96678.21000000", "0.02698000"], ["96678.91000000", "0.00000000"], ["96678.92000000", "0.22510000"], ["96679.28000000", "0.00000000"], ["96679.82000000", "0.00000000"], ["96680.26000000", "0.00000000"], ["96680.30000000", "0.00000000"], ["96680.64000000", "0.00000000"], ["96680.95000000", "0.00000000"], ["96682.52000000", "0.00000000"], ["96683.20000000", "0.00724000"], ["96683.98000000", "0.00000000"], ["96684.08000000", "0.00000000"], ["96684.17000000", "0.00000000"], ["96684.46000000", "0.00421000"], ["96684.60000000", "0.00000000"], ["96684.87000000", "0.00096000"], ["96685.10000000", "0.00000000"], ["96685.13000000", "0.00000000"], ["96686.64000000", "0.03327000"], ["96686.99000000", "0.21301000"], ["96687.39000000", "0.00000000"], ["96689.33000000", "0.00000000"], ["96690.16000000", "0.21301000"], ["96690.17000000", "0.10080000"], ["96691.28000000", "0.00000000"], ["96692.68000000", "0.00000000"], ["96692.71000000", "0.00000000"], ["96692.72000000", "0.00051000"], ["96693.07000000", "0.09600000"], ["96694.70000000", "0.00516000"], ["96695.62000000", "0.00932000"], ["96698.00000000", "1.10000000"], ["96698.08000000", "0.00000000"], ["96699.43000000", "0.74431000"], ["96701.94000000", "1.00000000"], ["96702.78000000", "0.00000000"], ["96703.44000000", "0.00000000"], ["96703.96000000", "0.00000000"], ["96704.67000000", "0.00000000"], ["96706.71000000", "0.62030000"], ["96707.24000000", "0.00000000"], ["96707.56000000", "0.00000000"], ["96708.11000000", "0.00000000"], ["96708.75000000", "0.00000000"], ["96711.78000000", "0.00000000"], ["96717.74000000", "0.00000000"], ["96719.54000000", "0.00000000"], ["96721.71000000", "0.00000000"], ["96726.10000000", "0.00000000"], ["96730.49000000", "2.00000000"], ["96731.04000000", "0.00000000"], ["96733.49000000", "0.00000000"], ["96735.83000000", "0.00000000"], ["96741.09000000", "0.00000000"], ["96741.64000000", "0.00000000"], ["96744.11000000", "0.00000000"], ["96746.85000000", "0.00000000"], ["96748.18000000", "0.00830000"], ["96751.61000000", "0.00000000"], ["96756.23000000", "0.00000000"], ["96760.50000000", "0.00000000"], ["96763.95000000", "0.10080000"], ["96765.21000000", "0.00000000"], ["96766.85000000", "0.00000000"], ["96770.54000000", "0.00000000"], ["96772.83000000", "0.00547000"], ["96776.44000000", "0.00521000"], ["96776.67000000", "0.00000000"], ["96780.14000000", "0.00000000"], ["96785.22000000", "0.00000000"], ["96788.82000000", "0.00000000"], ["96794.76000000", "0.00000000"], ["96795.87000000", "0.00521000"], ["96799.17000000", "0.00006000"], ["96802.69000000", "0.00523000"], ["96804.12000000", "0.00000000"], ["96806.52000000", "0.00830000"], ["96808.54000000", "0.00000000"], ["96813.74000000", "0.00000000"], ["96818.11000000", "0.00000000"], ["96824.96000000", "0.00008000"], ["96829.46000000", "0.00000000"], ["96833.66000000", "0.00000000"], ["96837.40000000", "0.00000000"], ["96843.42000000", "0.00000000"], ["96848.15000000", "0.00000000"], ["96850.77000000", "0.00456000"], ["96853.34000000", "0.00000000"], ["96858.33000000", "0.00000000"], ["96861.86000000", "0.00000000"], ["96867.33000000", "0.00000000"], ["97000.00000000", "8.15376000"], ["98123.50000000", "0.00100000"]]}
{"e": "depthUpdate", "E": 1746125000014, "s": "BTCUSDT", "b": [["96673.38000000", "6.02090000"], ["96673.37000000", "0.00006000"], ["96673.23000000", "0.02306000"], ["96673.00000000", "0.00013000"], ["96672.21000000", "0.00012000"], ["96672.20000000", "0.19259000"], ["96669.25000000", "0.00000000"], ["96667.26000000", "0.31688000"], ["96665.96000000", "0.00560000"], ["96662.82000000", "0.39242000"], ["96662.76000000", "0.00000000"], ["96662.32000000", "0.39637000"], ["96662.31000000", "0.00000000"], ["96662.02000000", "0.00000000"], ["96662.01000000", "0.00000000"], ["96658.57000000", "0.00516000"], ["96655.82000000", "0.00000000"], ["96655.50000000", "0.00000000"], ["96655.22000000", "0.04800000"], ["96654.94000000", "0.62036000"], ["96654.22000000", "1.00000000"], ["96652.62000000", "0.00000000"], ["96650.92000000", "0.00000000"], ["96648.22000000", "0.00000000"], ["96647.80000000", "0.74471000"], ["96647.33000000", "1.32848000"], ["96647.23000000", "0.06440000"], ["96646.66000000", "0.00000000"], ["96645.09000000", "0.00000000"], ["96644.89000000", "0.00000000"], ["96644.66000000", "0.00000000"], ["96639.21000000", "0.00000000"], ["96638.26000000", "0.00000000"], ["96635.12000000", "0.00206000"], ["96635.06000000", "2.00000000"], ["96634.38000000", "0.00000000"], ["96634.36000000", "0.21301000"], ["96631.86000000", "0.00000000"], ["96629.08000000", "0.00000000"], ["96628.46000000", "0.00000000"], ["96623.49000000", "0.00000000"], ["96623.06000000", "0.00000000"], ["96619.94000000", "0.05000000"], ["96616.80000000", "0.00000000"], ["96613.65000000", "0.03785000"], ["96606.98000000", "0.03693000"], ["96595.37000000", "0.00000000"], ["96580.03000000", "0.04800000"], ["96579.95000000", "0.00178000"], ["96567.69000000", "0.03348000"], ["96400.00000000", "1.61363000"], ["96399.00000000", "0.00053000"], ["95796.41000000", "0.00008000"], ["95223.27000000", "0.00133000"], ["92000.00000000", "58.28637000"], ["91839.71000000", "0.00010000"], ["87006.04000000", "0.00000000"], ["87006.00000000", "0.00000000"], ["87005.00000000", "0.00163000"], ["77338.71000000", "0.00050000"], ["70000.00000000", "183.65395000"], ["35052.21000000", "0.00270000"], ["35042.12000000", "0.00180000"], ["35038.94000000", "0.00198000"], ["35038.55000000", "0.00270000"], ["35037.30000000", "0.00180000"], ["35036.19000000", "0.00108000"], ["35029.12000000", "0.00360000"], ["34999.19000000", "0.00234000"], ["34998.11000000", "0.00270000"], ["34995.96000000", "0.00108000"], ["34977.74000000", "0.00198000"], ["34956.00000000", "0.00324000"], ["34949.00000000", "0.00108000"], ["34948.80000000", "0.00216000"], ["34922.57000000", "0.00108000"], ["34921.16000000", "0.00036000"], ["34909.92000000", "0.00054000"], ["34905.71000000", "0.00090000"], ["34802.42000000", "0.00612000"], ["33000.00000000", "2.70627000"]], "a": [["96673.39000000", "2.93349000"], ["96673.40000000", "0.00498000"], ["96673.48000000", "0.00006000"], ["96673.70000000", "0.00000000"], ["96673.76000000", "0.00006000"], ["96673.77000000", "0.00006000"], ["96673.90000000", "0.00012000"], ["96674.86000000", "0.09761000"], ["96676.00000000", "0.03996000"], ["96676.33000000", "0.00000000"], ["96677.45000000", "0.06446000"], ["96677.60000000", "0.00000000"], ["96678.00000000", "0.03796000"], ["96678.92000000", "0.66383000"], ["96680.10000000", "0.68242000"], ["96681.49000000", "1.68968000"], ["96681.85000000", "0.00000000"], ["96682.11000000", "0.00000000"], ["96682.12000000", "0.45434000"], ["96683.86000000", "0.00000000"], ["96684.05000000", "0.00000000"], ["96684.34000000", "0.00090000"], ["96684.46000000", "0.00000000"], ["96684.87000000", "0.00000000"], ["96686.99000000", "0.00000000"], ["96689.20000000", "0.02000000"], ["96689.55000000", "0.00759000"], ["96694.04000000", "0.09120000"], ["96695.01000000", "0.08160000"], ["96695.06000000", "0.07680000"], ["96697.04000000", "0.00000000"], ["96699.43000000", "0.00000000"], ["96700.25000000", "0.62034000"], ["96701.94000000", "0.00000000"], ["96702.40000000", "0.00032000"], ["96703.50000000", "0.00000000"], ["96704.64000000", "0.00000000"], ["96705.04000000", "0.00525000"], ["96706.34000000", "0.00000000"], ["96706.71000000", "0.00000000"], ["96707.94000000", "1.00000000"], ["96709.46000000", "0.00000000"], ["96709.54000000", "0.00000000"], ["96714.35000000", "0.10080000"], ["96714.86000000", "0.74419000"], ["96717.26000000", "1.78568000"], ["96719.20000000", "0.00985000"], ["96728.25000000", "0.00980000"], ["96730.48000000", "0.00000000"], ["96730.49000000", "0.00000000"], ["96733.61000000", "0.00000000"], ["96735.89000000", "0.00000000"], ["96739.29000000", "0.00000000"], ["96742.49000000", "2.00000000"], ["96743.05000000", "0.00985000"], ["96745.69000000", "0.00000000"], ["96762.10000000", "0.00000000"], ["96766.80000000", "0.00000000"], ["96766.85000000", "0.00000000"], ["96767.82000000", "0.00000000"], ["96768.78000000", "0.00000000"], ["96772.61000000", "0.00178000"], ["96776.48000000", "0.00000000"], ["96782.28000000", "0.54357000"], ["96785.06000000", "0.00000000"], ["96791.69000000", "0.00936000"], ["96812.47000000", "1.33332000"], ["96812.49000000", "0.00936000"], ["96840.34000000", "0.00927000"], ["96845.12000000", "0.00496000"], ["96859.27000000", "0.00606000"], ["98123.50000000", "0.00000000"]]}
